Workbook

Sheet Leyenda
C2: LEYENDA
C3: GASTOS | D3: CONCEPTOS
C4: Salario | D4: serán los gastos de salario en los que se incurre en el día
C5: Renta | D5: alquiler del espacio se registrará el día que se ejecute el gasto
C6: Compras | D6: compra de mercancias para la venta
C7: Electricidad | D7: monto de la factura pagada
C8: Gas | D8: monto de la factura pagada
C9: Transporte | D9: servicios de transportación de mercancía, mensajeria y servicios de taxi que sean a cuenta del negocio
C10: Pantry | D10: gastos de café, agua, jugos u otros
C11: Comunicaciones | D11: gastos de internet, recargas del móvil asociadas al funcionamiento del negocio, nauta, etc.
C12: Publicidad | D12: gastos asociados a la publicidad y promoción del negocio, modelos, trabajo en redes u otros asociados
C13: Insumos de Limpieza | D13: material e insumos de limpieza asociados al funcionamiento del negocio
C14: Mantenimiento | D14: gastos de mantenimiento y reparacion del local, reposición de luces, pintura, gastos de plomería ect.
... C17: Otros servicios comprados | D17: pagos de otros servicios, por ejemplo: combustible, asesorías, trabajos profesionales

Sheet Ventas
C2: VENTAS
B3: Dia | C3: Turno | D3: TRANSFERENCIAS CUP | E3: TRANSFERENCIAS ZELLE | F3: EURO | G3: USD | H3: EFECTIVO | I3: CUENTA FISCAL | J3: TOTAL | K3: TOTAL USD
B4: 1 | D4: =+'Dia 1'!C4 -> 0 | E4: =+'Dia 1'!D4 -> 0 | F4: =+'Dia 1'!E4 -> 0 | G4: =+'Dia 1'!F4 -> 169 | H4: =+'Dia 1'!G4 -> 0 | I4: =+'Dia 1'!H4 -> 0 | J4: =+'Dia 1'!I4 -> 86190 | K4: =+'Dia 1'!J4 -> 169 | L4: =J4*0.042 -> 3619.98
B5: 2 | D5: =+'Dia 2'!C4 -> 0 | E5: =+'Dia 2'!D4 -> 0 | F5: =+'Dia 2'!E4 -> 0 | G5: =+'Dia 2'!F4 -> 0 | H5: =+'Dia 2'!G4 -> 0 | I5: =+'Dia 2'!H4 -> 0 | J5: =+'Dia 2'!I4 -> 0 | K5: =+'Dia 2'!J4 -> 0 | L5: =J5*0.042 -> 0
B6: 3 | D6: =+'Dia 3'!C4 -> 135130 | E6: =+'Dia 3'!D4 -> 0 | F6: =+'Dia 3'!E4 -> 0 | G6: =+'Dia 3'!F4 -> 574 | H6: =+'Dia 3'!G4 -> 0 | I6: =+'Dia 3'!H4 -> 50000 | J6: =+'Dia 3'!I4 -> 477870 | K6: =+'Dia 3'!J4 -> 937 | L6: =J6*0.042 -> 20070.54
B7: 4 | D7: =+'Dia 4'!C4 -> 0 | E7: =+'Dia 4'!D4 -> 0 | F7: =+'Dia 4'!E4 -> 0 | G7: =+'Dia 4'!F4 -> 110 | H7: =+'Dia 4'!G4 -> 0 | I7: =+'Dia 4'!H4 -> 0 | J7: =+'Dia 4'!I4 -> 56100 | K7: =+'Dia 4'!J4 -> 110 | L7: =J7*0.042 -> 2356.2
B8: 5 | D8: =+'Dia 5'!C4 -> 10000 | E8: =+'Dia 5'!D4 -> 0 | F8: =+'Dia 5'!E4 -> 0 | G8: =+'Dia 5'!F4 -> 36 | H8: =+'Dia 5'!G4 -> 0 | I8: =+'Dia 5'!H4 -> 15500 | J8: =+'Dia 5'!I4 -> 43860 | K8: =+'Dia 5'!J4 -> 86 | L8: =J8*0.042 -> 1842.12
B9: 6 | D9: =+'Dia 6'!C4 -> 0 | E9: =+'Dia 6'!D4 -> 74 | F9: =+'Dia 6'!E4 -> 0 | G9: =+'Dia 6'!F4 -> 65 | H9: =+'Dia 6'!G4 -> 0 | I9: =+'Dia 6'!H4 -> 0 | J9: =+'Dia 6'!I4 -> 70890 | K9: =+'Dia 6'!J4 -> 139 | L9: =J9*0.042 -> 2977.38
B10: 7 | D10: =+'Dia 7'!C4 -> 20000 | E10: =+'Dia 7'!D4 -> 0 | F10: =+'Dia 7'!E4 -> 0 | G10: =+'Dia 7'!F4 -> 405 | H10: =+'Dia 7'!G4 -> 25500 | I10: =+'Dia 7'!H4 -> 5500 | J10: =+'Dia 7'!I4 -> 257550 | K10: =+'Dia 7'!J4 -> 505 | L10: =J10*0.042 -> 10817.1
B11: 8 | D11: =+'Dia 8'!C4 -> 0 | E11: =+'Dia 8'!D4 -> 0 | F11: =+'Dia 8'!E4 -> 0 | G11: =+'Dia 8'!F4 -> 184 | H11: =+'Dia 8'!G4 -> 122200 | I11: =+'Dia 8'!H4 -> 1100 | J11: =+'Dia 8'!I4 -> 217140 | K11: =+'Dia 8'!J4 -> 425.76471 | L11: =J11*0.042 -> 9119.88
B12: 9 | D12: =+'Dia 9'!C4 -> 0 | E12: =+'Dia 9'!D4 -> 0 | F12: =+'Dia 9'!E4 -> 0 | G12: =+'Dia 9'!F4 -> 60 | H12: =+'Dia 9'!G4 -> 12750 | I12: =+'Dia 9'!H4 -> 0 | J12: =+'Dia 9'!I4 -> 43350 | K12: =+'Dia 9'!J4 -> 85 | L12: =J12*0.042 -> 1820.7
B13: 10 | D13: =+'Dia 10'!C4 -> 0 | E13: =+'Dia 10'!D4 -> 0 | F13: =+'Dia 10'!E4 -> 0 | G13: =+'Dia 10'!F4 -> 158 | H13: =+'Dia 10'!G4 -> 0 | I13: =+'Dia 10'!H4 -> 0 | J13: =+'Dia 10'!I4 -> 80580 | K13: =+'Dia 10'!J4 -> 158 | L13: =J13*0.042 -> 3384.36
B14: 11 | D14: =+'Dia 11'!C4 -> 0 | E14: =+'Dia 11'!D4 -> 0 | F14: =+'Dia 11'!E4 -> 0 | G14: =+'Dia 11'!F4 -> 973 | H14: =+'Dia 11'!G4 -> 0 | I14: =+'Dia 11'!H4 -> 0 | J14: =+'Dia 11'!I4 -> 496230 | K14: =+'Dia 11'!J4 -> 973 | L14: =J14*0.042 -> 20841.66
B15: 12 | D15: =+'Dia 12'!C4 -> 0 | E15: =+'Dia 12'!D4 -> 0 | F15: =+'Dia 12'!E4 -> 0 | G15: =+'Dia 12'!F4 -> 35 | H15: =+'Dia 12'!G4 -> 0 | I15: =+'Dia 12'!H4 -> 0 | J15: =+'Dia 12'!I4 -> 17850 | K15: =+'Dia 12'!J4 -> 35 | L15: =J15*0.042 -> 749.7
B16: 13 | D16: =+'Dia 13'!C4 -> 0 | E16: =+'Dia 13'!D4 -> 0 | F16: =+'Dia 13'!E4 -> 0 | G16: =+'Dia 13'!F4 -> 80 | H16: =+'Dia 13'!G4 -> 25500 | I16: =+'Dia 13'!H4 -> 0 | J16: =+'Dia 13'!I4 -> 66300 | K16: =+'Dia 13'!J4 -> 130 | L16: =J16*0.042 -> 2784.6
B17: 14 | D17: =+'Dia 14'!C4 -> 0 | E17: =+'Dia 14'!D4 -> 0 | F17: =+'Dia 14'!E4 -> 0 | G17: =+'Dia 14'!F4 -> 682 | H17: =+'Dia 14'!G4 -> 92160 | I17: =+'Dia 14'!H4 -> 0 | J17: =+'Dia 14'!I4 -> 441344 | K17: =+'Dia 14'!J4 -> 862 | L17: =J17*0.042 -> 18536.448
B18: 15 | D18: =+'Dia 15'!C4 -> 0 | E18: =+'Dia 15'!D4 -> 0 | F18: =+'Dia 15'!E4 -> 0 | G18: =+'Dia 15'!F4 -> 60 | H18: =+'Dia 15'!G4 -> 0 | I18: =+'Dia 15'!H4 -> 0 | J18: =+'Dia 15'!I4 -> 30600 | K18: =+'Dia 15'!J4 -> 60 | L18: =J18*0.042 -> 1285.2
B19: 16 | D19: =+'Dia 16'!C4 -> 7965 | E19: =+'Dia 16'!D4 -> 0 | F19: =+'Dia 16'!E4 -> 0 | G19: =+'Dia 16'!F4 -> 577 | H19: =+'Dia 16'!G4 -> 7700 | I19: =+'Dia 16'!H4 -> 10000 | J19: =+'Dia 16'!I4 -> 319935 | K19: =+'Dia 16'!J4 -> 627.32353 | L19: =J19*0.042 -> 13437.27
B20: 17 | D20: =+'Dia 17'!C4 -> 0 | E20: =+'Dia 17'!D4 -> 0 | F20: =+'Dia 17'!E4 -> 0 | G20: =+'Dia 17'!F4 -> 280 | H20: =+'Dia 17'!G4 -> 0 | I20: =+'Dia 17'!H4 -> 0 | J20: =+'Dia 17'!I4 -> 143920 | K20: =+'Dia 17'!J4 -> 280 | L20: =J20*0.042 -> 6044.64
B21: 18 | D21: =+'Dia 18'!C4 -> 0 | E21: =+'Dia 18'!D4 -> 0 | F21: =+'Dia 18'!E4 -> 50 | G21: =+'Dia 18'!F4 -> 195 | H21: =+'Dia 18'!G4 -> 1050 | I21: =+'Dia 18'!H4 -> 0 | J21: =+'Dia 18'!I4 -> 126980 | K21: =+'Dia 18'!J4 -> 247.0428 | L21: =J21*0.042 -> 5333.16
B22: 19 | D22: =+'Dia 19'!C4 -> 20720 | E22: =+'Dia 19'!D4 -> 0 | F22: =+'Dia 19'!E4 -> 0 | G22: =+'Dia 19'!F4 -> 55 | H22: =+'Dia 19'!G4 -> 12800 | I22: =+'Dia 19'!H4 -> 10000 | J22: =+'Dia 19'!I4 -> 71680 | K22: =+'Dia 19'!J4 -> 140 | L22: =J22*0.042 -> 3010.56
B23: 20 | D23: =+'Dia 20'!C4 -> 0 | E23: =+'Dia 20'!D4 -> 0 | F23: =+'Dia 20'!E4 -> 0 | G23: =+'Dia 20'!F4 -> 165 | H23: =+'Dia 20'!G4 -> 0 | I23: =+'Dia 20'!H4 -> 0 | J23: =+'Dia 20'!I4 -> 84480 | K23: =+'Dia 20'!J4 -> 165 | L23: =J23*0.042 -> 3548.16
B24: 21 | D24: =+'Dia 21'!C4 -> 0 | E24: =+'Dia 21'!D4 -> 0 | F24: =+'Dia 21'!E4 -> 0 | G24: =+'Dia 21'!F4 -> 170 | H24: =+'Dia 21'!G4 -> 16250 | I24: =+'Dia 21'!H4 -> 0 | J24: =+'Dia 21'!I4 -> 103800 | K24: =+'Dia 21'!J4 -> 201.5534 | L24: =J24*0.042 -> 4359.6
B25: 22 | D25: =+'Dia 22'!C4 -> 0 | E25: =+'Dia 22'!D4 -> 0 | F25: =+'Dia 22'!E4 -> 0 | G25: =+'Dia 22'!F4 -> 95 | H25: =+'Dia 22'!G4 -> 0 | I25: =+'Dia 22'!H4 -> 0 | J25: =+'Dia 22'!I4 -> 48925 | K25: =+'Dia 22'!J4 -> 95 | L25: =J25*0.042 -> 2054.85
B26: 23 | D26: =+'Dia 23'!C4 -> 0 | E26: =+'Dia 23'!D4 -> 0 | F26: =+'Dia 23'!E4 -> 0 | G26: =+'Dia 23'!F4 -> 0 | H26: =+'Dia 23'!G4 -> 18050 | I26: =+'Dia 23'!H4 -> 0 | J26: =+'Dia 23'!I4 -> 18050 | K26: =+'Dia 23'!J4 -> 35.048544 | L26: =J26*0.042 -> 758.1
B27: 24 | D27: =+'Dia 24'!C4 -> 0 | E27: =+'Dia 24'!D4 -> 0 | F27: =+'Dia 24'!E4 -> 0 | G27: =+'Dia 24'!F4 -> 457 | H27: =+'Dia 24'!G4 -> 0 | I27: =+'Dia 24'!H4 -> 0 | J27: =+'Dia 24'!I4 -> 235355 | K27: =+'Dia 24'!J4 -> 457 | L27: =J27*0.042 -> 9884.91
B28: 25 | D28: =+'Dia 25'!C4 -> 0 | E28: =+'Dia 25'!D4 -> 0 | F28: =+'Dia 25'!E4 -> 0 | G28: =+'Dia 25'!F4 -> 85 | H28: =+'Dia 25'!G4 -> 0 | I28: =+'Dia 25'!H4 -> 0 | J28: =+'Dia 25'!I4 -> 43775 | K28: =+'Dia 25'!J4 -> 85 | L28: =J28*0.042 -> 1838.55
B29: 26 | D29: =+'Dia 26'!C4 -> 0 | E29: =+'Dia 26'!D4 -> 0 | F29: =+'Dia 26'!E4 -> 0 | G29: =+'Dia 26'!F4 -> 141 | H29: =+'Dia 26'!G4 -> 37600 | I29: =+'Dia 26'!H4 -> 0 | J29: =+'Dia 26'!I4 -> 110215 | K29: =+'Dia 26'!J4 -> 214.00971 | L29: =J29*0.042 -> 4629.03
B30: 27 | D30: =+'Dia 27'!C4 -> 0 | E30: =+'Dia 27'!D4 -> 0 | F30: =+'Dia 27'!E4 -> 0 | G30: =+'Dia 27'!F4 -> 30 | H30: =+'Dia 27'!G4 -> 0 | I30: =+'Dia 27'!H4 -> 0 | J30: =+'Dia 27'!I4 -> 15450 | K30: =+'Dia 27'!J4 -> 30 | L30: =J30*0.042 -> 648.9
B31: 28 | D31: =+'Dia 28'!C4 -> 0 | E31: =+'Dia 28'!D4 -> 0 | F31: =+'Dia 28'!E4 -> 0 | G31: =+'Dia 28'!F4 -> 85 | H31: =+'Dia 28'!G4 -> 0 | I31: =+'Dia 28'!H4 -> 0 | J31: =+'Dia 28'!I4 -> 43775 | K31: =+'Dia 28'!J4 -> 85 | L31: =J31*0.042 -> 1838.55
B32: 29 | D32: =+'Dia 29'!C4 -> 0 | E32: =+'Dia 29'!D4 -> 0 | F32: =+'Dia 29'!E4 -> 0 | G32: =+'Dia 29'!F4 -> 127.17 | H32: =+'Dia 29'!G4 -> 28500 | I32: =+'Dia 29'!H4 -> 0 | J32: =+'Dia 29'!I4 -> 93992.55 | K32: =+'Dia 29'!J4 -> 182.50981 | L32: =J32*0.042 -> 3947.6871
B33: 30 | D33: =+'Dia 30'!C4 -> 0 | E33: =+'Dia 30'!D4 -> 0 | F33: =+'Dia 30'!E4 -> 0 | G33: =+'Dia 30'!F4 -> 100 | H33: =+'Dia 30'!G4 -> 0 | I33: =+'Dia 30'!H4 -> 0 | J33: =+'Dia 30'!I4 -> 51500 | K33: =+'Dia 30'!J4 -> 100 | L33: =J33*0.042 -> 2163
B34: 31 | D34: =+'Dia 31'!C4 -> 0 | E34: =+'Dia 31'!D4 -> 0 | F34: =+'Dia 31'!E4 -> 0 | G34: =+'Dia 31'!F4 -> 465 | H34: =+'Dia 31'!G4 -> 22148 | I34: =+'Dia 31'!H4 -> 0 | J34: =+'Dia 31'!I4 -> 261623 | K34: =+'Dia 31'!J4 -> 508.00583 | L34: =J34*0.042 -> 10988.166
B35: TOTAL | D35: =+SUM(D4:D34) -> 193815 | E35: =+SUM(E4:E34) -> 74 | F35: =+SUM(F4:F34) -> 50 | G35: =+SUM(G4:G34) -> 6618.17 | H35: =+SUM(H4:H34) -> 422208 | I35: =+SUM(I4:I34) -> 92100 | J35: =+SUM(J4:J34) -> 4159309.5 | K35: =+SUM(K4:K34) -> 8127.2583 | M35: =19700*435 -> 8569500
C37: Promedio diario | D37: =+D35/31 -> 6252.0968 | E37: =+E35/31 -> 2.3870968 | F37: =+F35/31 -> 1.6129032 | G37: =+G35/31 -> 213.48935 | H37: =+H35/31 -> 13619.613 | I37: =+I35/31 -> 2970.9677 | J37: =+J35/31 -> 134171.28 | K37: =+K35/31 -> 262.16962
D38: TRANSFERENCIAS CUP | E38: TRANSFERENCIAS MLC | F38: EURO | G38: USD | H38: EFECTIVO | I38: CUENTA FISCAL | J38: TOTAL | K38: TOTAL USD

Sheet Salario
C5: Dia1 | D5: Día 2 | E5: Dia3 | F5: Dia4 | G5: Dia5 | H5: Dia6 | I5: Dia7 | J5: Dia8 | K5: Dia9 | L5: Dia10 | M5: Dia11 | N5: Dia12 | O5: Dia13 | P5: Dia14 | Q5: Dia15 | R5: Dia16 | S5: Dia17 | T5: Dia18 | U5: Dia19 | V5: Dia20 | W5: Dia21 | X5: Dia22 | Y5: Dia23 | Z5: Dia24 | AA5: Dia25 | AB5: Dia26 | AC5: Dia27 | AD5: Dia28 | AE5: Dia29 | AF5: Dia30 | AG5: Dia31 | AH5: TOTAL MES
B6: Jacqueline | C6: =+'Dia 1'!C34 -> 0 | D6: =+'Dia 2'!C34 -> 0 | E6: =+'Dia 3'!C34 -> 0 | F6: =+'Dia 4'!C34 -> 2000 | G6: =+'Dia 5'!C34 -> 2000 | H6: =+'Dia 6'!C34 -> 2000 | I6: =+'Dia 7'!C34 -> 0 | J6: =+'Dia 8'!C34 -> 0 | K6: =+'Dia 9'!C34 -> 0 | L6: =+'Dia 10'!C34 -> 2000 | M6: =+'Dia 11'!C34 -> 2000 | N6: =+'Dia 12'!C34 -> 2000 | O6: =+'Dia 13'!C34 -> 0 | P6: =+'Dia 14'!C34 -> 0 | Q6: =+'Dia 15'!C34 -> 0 | R6: =+'Dia 16'!C34 -> 2000 | S6: =+'Dia 17'!C34 -> 2000 | T6: =+'Dia 18'!C34 -> 2000 | U6: =+'Dia 19'!C34 -> 0 | V6: =+'Dia 20'!C34 -> 0 | W6: =+'Dia 21'!C34 -> 0 | X6: =+'Dia 22'!C34 -> 2000 | Y6: =+'Dia 23'!C34 -> 2000 | Z6: =+'Dia 24'!C34 -> 2000 | AA6: =+'Dia 25'!C34 -> 2000 | AB6: =+'Dia 26'!C34 -> 0 | AC6: =+'Dia 27'!C34 -> 0 | AD6: =+'Dia 28'!C34 -> 2000 | AE6: =+'Dia 29'!C34 -> 2000 | AF6: =+'Dia 30'!C34 -> 2000 | AG6: =+'Dia 31'!C34 -> 0 | AH6: =SUM(C6:AG6) -> 32000
B7: Yeni | C7: =+'Dia 1'!C35 -> 2000 | D7: =+'Dia 2'!C35 -> 0 | E7: =+'Dia 3'!C35 -> 0 | F7: =+'Dia 4'!C35 -> 0 | G7: =+'Dia 5'!C35 -> 0 | H7: =+'Dia 6'!C35 -> 0 | I7: =+'Dia 7'!C35 -> 2000 | J7: =+'Dia 8'!C35 -> 0 | K7: =+'Dia 9'!C35 -> 2000 | L7: =+'Dia 10'!C35 -> 0 | M7: =+'Dia 11'!C35 -> 0 | N7: =+'Dia 12'!C35 -> 0 | O7: =+'Dia 13'!C35 -> 2000 | P7: =+'Dia 14'!C35 -> 2000 | Q7: =+'Dia 15'!C35 -> 2000 | R7: =+'Dia 16'!C35 -> 0 | S7: =+'Dia 17'!C35 -> 0 | T7: =+'Dia 18'!C35 -> 0 | U7: =+'Dia 19'!C35 -> 2000 | V7: =+'Dia 20'!C35 -> 2000 | W7: =+'Dia 21'!C35 -> 2000 | X7: =+'Dia 22'!C35 -> 0 | Y7: =+'Dia 23'!C35 -> 0 | Z7: =+'Dia 24'!C35 -> 0 | AA7: =+'Dia 25'!C35 -> 0 | AB7: =+'Dia 26'!C35 -> 2000 | AC7: =+'Dia 27'!C35 -> 2000 | AD7: =+'Dia 28'!C35 -> 0 | AE7: =+'Dia 29'!C35 -> 0 | AF7: =+'Dia 30'!C35 -> 0 | AG7: =+'Dia 31'!C35 -> 2000 | AH7: =SUM(C7:AG7) -> 24000
B8: Daniela | C8: =+'Dia 1'!C36 -> 0 | D8: =+'Dia 2'!C36 -> 0 | E8: =+'Dia 3'!C36 -> 0 | F8: =+'Dia 4'!C36 -> 0 | G8: =+'Dia 5'!C36 -> 0 | H8: =+'Dia 6'!C36 -> 0 | I8: =+'Dia 7'!C36 -> 0 | J8: =+'Dia 8'!C36 -> 0 | K8: =+'Dia 9'!C36 -> 0 | L8: =+'Dia 10'!C36 -> 0 | M8: =+'Dia 11'!C36 -> 0 | N8: =+'Dia 12'!C36 -> 0 | O8: =+'Dia 13'!C36 -> 0 | P8: =+'Dia 14'!C36 -> 0 | Q8: =+'Dia 15'!C36 -> 0 | R8: =+'Dia 16'!C36 -> 0 | S8: =+'Dia 17'!C36 -> 0 | T8: =+'Dia 18'!C36 -> 0 | U8: =+'Dia 19'!C36 -> 0 | V8: =+'Dia 20'!C36 -> 0 | W8: =+'Dia 21'!C36 -> 0 | X8: =+'Dia 22'!C36 -> 0 | Y8: =+'Dia 23'!C36 -> 0 | Z8: =+'Dia 24'!C36 -> 0 | AA8: =+'Dia 25'!C36 -> 0 | AB8: =+'Dia 26'!C36 -> 0 | AC8: =+'Dia 27'!C36 -> 0 | AD8: =+'Dia 28'!C36 -> 0 | AE8: =+'Dia 29'!C36 -> 0 | AF8: =+'Dia 30'!C36 -> 0 | AG8: =+'Dia 31'!C36 -> 0 | AH8: =SUM(C8:AG8) -> 0
B9: Lisandra | C9: =+'Dia 1'!C37 -> 2000 | D9: =+'Dia 2'!C37 -> 2000 | E9: =+'Dia 3'!C37 -> 2000 | F9: =+'Dia 4'!C37 -> 2000 | G9: =+'Dia 5'!C37 -> 0 | H9: =+'Dia 6'!C37 -> 0 | I9: =+'Dia 7'!C37 -> 2000 | J9: =+'Dia 8'!C37 -> 2000 | K9: =+'Dia 9'!C37 -> 2000 | L9: =+'Dia 10'!C37 -> 0 | M9: =+'Dia 11'!C37 -> 0 | N9: =+'Dia 12'!C37 -> 0 | O9: =+'Dia 13'!C37 -> 2000 | P9: =+'Dia 14'!C37 -> 2000 | Q9: =+'Dia 15'!C37 -> 0 | R9: =+'Dia 16'!C37 -> 2000 | S9: =+'Dia 17'!C37 -> 0 | T9: =+'Dia 18'!C37 -> 0 | U9: =+'Dia 19'!C37 -> 2000 | V9: =+'Dia 20'!C37 -> 2000 | W9: =+'Dia 21'!C37 -> 2000 | X9: =+'Dia 22'!C37 -> 0 | Y9: =+'Dia 23'!C37 -> 0 | Z9: =+'Dia 24'!C37 -> 0 | AA9: =+'Dia 25'!C37 -> 0 | AB9: =+'Dia 26'!C37 -> 2000 | AC9: =+'Dia 27'!C37 -> 2000 | AD9: =+'Dia 28'!C37 -> 0 | AE9: =+'Dia 29'!C37 -> 0 | AF9: =+'Dia 30'!C37 -> 0 | AG9: =+'Dia 31'!C37 -> 0 | AH9: =SUM(C9:AG9) -> 30000
B10: Aileen | C10: =+'Dia 1'!C38 -> 0 | D10: =+'Dia 2'!C38 -> 2000 | E10: =+'Dia 3'!C38 -> 2000 | F10: =+'Dia 4'!C38 -> 0 | G10: =+'Dia 5'!C38 -> 2000 | H10: =+'Dia 6'!C38 -> 2000 | I10: =+'Dia 7'!C38 -> 0 | J10: =+'Dia 8'!C38 -> 2000 | K10: =+'Dia 9'!C38 -> 0 | L10: =+'Dia 10'!C38 -> 2000 | M10: =+'Dia 11'!C38 -> 2000 | N10: =+'Dia 12'!C38 -> 2000 | O10: =+'Dia 13'!C38 -> 0 | P10: =+'Dia 14'!C38 -> 0 | Q10: =+'Dia 15'!C38 -> 2000 | R10: =+'Dia 16'!C38 -> 0 | S10: =+'Dia 17'!C38 -> 2000 | T10: =+'Dia 18'!C38 -> 2000 | U10: =+'Dia 19'!C38 -> 0 | V10: =+'Dia 20'!C38 -> 0 | W10: =+'Dia 21'!C38 -> 0 | X10: =+'Dia 22'!C38 -> 2000 | Y10: =+'Dia 23'!C38 -> 2000 | Z10: =+'Dia 24'!C38 -> 2000 | AA10: =+'Dia 25'!C38 -> 2000 | AB10: =+'Dia 26'!C38 -> 0 | AC10: =+'Dia 27'!C38 -> 0 | AD10: =+'Dia 28'!C38 -> 2000 | AE10: =+'Dia 29'!C38 -> 2000 | AF10: =+'Dia 30'!C38 -> 2000 | AG10: =+'Dia 31'!C38 -> 2000 | AH10: =SUM(C10:AG10) -> 38000
B11: Laura | C11: =+'Dia 1'!C39 -> 0 | D11: =+'Dia 2'!C39 -> 0 | E11: =+'Dia 3'!C39 -> 0 | F11: =+'Dia 4'!C39 -> 0 | G11: =+'Dia 5'!C39 -> 0 | H11: =+'Dia 6'!C39 -> 0 | I11: =+'Dia 7'!C39 -> 0 | J11: =+'Dia 8'!C39 -> 0 | K11: =+'Dia 9'!C39 -> 0 | L11: =+'Dia 10'!C39 -> 0 | M11: =+'Dia 11'!C39 -> 0 | N11: =+'Dia 12'!C39 -> 0 | O11: =+'Dia 13'!C39 -> 0 | P11: =+'Dia 14'!C39 -> 0 | Q11: =+'Dia 15'!C39 -> 0 | R11: =+'Dia 16'!C39 -> 0 | S11: =+'Dia 17'!C39 -> 0 | T11: =+'Dia 18'!C39 -> 0 | U11: =+'Dia 19'!C39 -> 0 | V11: =+'Dia 20'!C39 -> 0 | W11: =+'Dia 21'!C39 -> 0 | X11: =+'Dia 22'!C39 -> 0 | Y11: =+'Dia 23'!C39 -> 0 | Z11: =+'Dia 24'!C39 -> 0 | AA11: =+'Dia 25'!C39 -> 0 | AB11: =+'Dia 26'!C39 -> 0 | AC11: =+'Dia 27'!C39 -> 0 | AD11: =+'Dia 28'!C39 -> 0 | AE11: =+'Dia 29'!C39 -> 0 | AF11: =+'Dia 30'!C39 -> 0 | AG11: =+'Dia 31'!C39 -> 0 | AH11: =SUM(C11:AG11) -> 0
B12: Vanessa | C12: =+'Dia 1'!C40 -> 0 | D12: =+'Dia 2'!C40 -> 0 | E12: =+'Dia 3'!C40 -> 0 | F12: =+'Dia 4'!C40 -> 0 | G12: =+'Dia 5'!C40 -> 0 | H12: =+'Dia 6'!C40 -> 0 | I12: =+'Dia 7'!C40 -> 0 | J12: =+'Dia 8'!C40 -> 0 | K12: =+'Dia 9'!C40 -> 0 | L12: =+'Dia 10'!C40 -> 0 | M12: =+'Dia 11'!C40 -> 0 | N12: =+'Dia 12'!C40 -> 0 | O12: =+'Dia 13'!C40 -> 0 | P12: =+'Dia 14'!C40 -> 0 | Q12: =+'Dia 15'!C40 -> 0 | R12: =+'Dia 16'!C40 -> 0 | S12: =+'Dia 17'!C40 -> 0 | T12: =+'Dia 18'!C40 -> 0 | U12: =+'Dia 19'!C40 -> 0 | V12: =+'Dia 20'!C40 -> 0 | W12: =+'Dia 21'!C40 -> 0 | X12: =+'Dia 22'!C40 -> 0 | Y12: =+'Dia 23'!C40 -> 0 | Z12: =+'Dia 24'!C40 -> 0 | AA12: =+'Dia 25'!C40 -> 0 | AB12: =+'Dia 26'!C40 -> 0 | AC12: =+'Dia 27'!C40 -> 0 | AD12: =+'Dia 28'!C40 -> 0 | AE12: =+'Dia 29'!C40 -> 0 | AF12: =+'Dia 30'!C40 -> 0 | AG12: =+'Dia 31'!C40 -> 0 | AH12: =SUM(C12:AG12) -> 0
B13: Magaly | C13: =+'Dia 1'!C41 -> 0 | D13: =+'Dia 2'!C41 -> 0 | E13: =+'Dia 3'!C41 -> 0 | F13: =+'Dia 4'!C41 -> 0 | G13: =+'Dia 5'!C41 -> 0 | H13: =+'Dia 6'!C41 -> 0 | I13: =+'Dia 7'!C41 -> 0 | J13: =+'Dia 8'!C41 -> 0 | K13: =+'Dia 9'!C41 -> 0 | L13: =+'Dia 10'!C41 -> 0 | M13: =+'Dia 11'!C41 -> 0 | N13: =+'Dia 12'!C41 -> 0 | O13: =+'Dia 13'!C41 -> 0 | P13: =+'Dia 14'!C41 -> 0 | Q13: =+'Dia 15'!C41 -> 0 | R13: =+'Dia 16'!C41 -> 0 | S13: =+'Dia 17'!C41 -> 0 | T13: =+'Dia 18'!C41 -> 0 | U13: =+'Dia 19'!C41 -> 0 | V13: =+'Dia 20'!C41 -> 0 | W13: =+'Dia 21'!C41 -> 0 | X13: =+'Dia 22'!C41 -> 0 | Y13: =+'Dia 23'!C41 -> 0 | Z13: =+'Dia 24'!C41 -> 0 | AA13: =+'Dia 25'!C41 -> 0 | AB13: =+'Dia 26'!C41 -> 0 | AC13: =+'Dia 27'!C41 -> 0 | AD13: =+'Dia 28'!C41 -> 0 | AE13: =+'Dia 29'!C41 -> 0 | AF13: =+'Dia 30'!C41 -> 0 | AG13: =+'Dia 31'!C41 -> 0 | AH13: =SUM(C13:AG13) -> 0
C14: =+'Dia 1'!C42 -> 0 | D14: =+'Dia 2'!C42 -> 0 | E14: =+'Dia 3'!C42 -> 0 | F14: =+'Dia 4'!C42 -> 0 | G14: =+'Dia 5'!C42 -> 0 | H14: =+'Dia 6'!C42 -> 0 | I14: =+'Dia 7'!C42 -> 0 | J14: =+'Dia 8'!C42 -> 0 | K14: =+'Dia 9'!C42 -> 0 | L14: =+'Dia 10'!C42 -> 0 | M14: =+'Dia 11'!C42 -> 0 | N14: =+'Dia 12'!C42 -> 0 | O14: =+'Dia 13'!C42 -> 0 | P14: =+'Dia 14'!C42 -> 0 | Q14: =+'Dia 15'!C42 -> 0 | R14: =+'Dia 16'!C42 -> 0 | S14: =+'Dia 17'!C42 -> 0 | T14: =+'Dia 18'!C42 -> 0 | U14: =+'Dia 19'!C42 -> 0 | V14: =+'Dia 20'!C42 -> 0 | W14: =+'Dia 21'!C42 -> 0 | X14: =+'Dia 22'!C42 -> 0 | Y14: =+'Dia 23'!C42 -> 0 | Z14: =+'Dia 24'!C42 -> 0 | AA14: =+'Dia 25'!C42 -> 0 | AB14: =+'Dia 26'!C42 -> 0 | AC14: =+'Dia 27'!C42 -> 0 | AD14: =+'Dia 28'!C42 -> 0 | AE14: =+'Dia 29'!C42 -> 0 | AF14: =+'Dia 30'!C42 -> 0 | AG14: =+'Dia 31'!C42 -> 0 | AH14: =SUM(C14:AG14) -> 0
C15: =SUM(C6:C14) -> 4000 | D15: =SUM(D6:D14) -> 4000 | E15: =SUM(E6:E14) -> 4000 | F15: =SUM(F6:F14) -> 4000 | G15: =SUM(G6:G14) -> 4000 | H15: =SUM(H6:H14) -> 4000 | I15: =SUM(I6:I14) -> 4000 | J15: =SUM(J6:J14) -> 4000 | ... AG15: =SUM(AG6:AG14) -> 4000 | AH15: =SUM(C15:AG15) -> 124000
B17: 0.02 | C17: ='Dia 1'!D43 -> 4 | D17: ='Dia 2'!D43 -> 0 | E17: =+'Dia 3'!D43 -> 19 | F17: =+'Dia 4'!D43 -> 3 | G17: =+'Dia 5'!D43 -> 2 | H17: =+'Dia 6'!D43 -> 3 | I17: =+'Dia 7'!D43 -> 10 | J17: =+'Dia 8'!D43 -> 8.1 | K17: =+'Dia 9'!D43 -> 2 | L17: =+'Dia 10'!D43 -> 4 | M17: =+'Dia 11'!D43 -> 20 | N17: =+'Dia 12'!D43 -> 1 | O17: =+'Dia 13'!D43 -> 3 | P17: =+'Dia 14'!D43 -> 18 | Q17: =+'Dia 15'!D43 -> 2 | R17: =+'Dia 16'!D43 -> 13 | S17: =+'Dia 17'!D43 -> 6 | T17: =+'Dia 18'!D43 -> 5 | U17: =+'Dia 19'!D43 -> 3 | V17: =+'Dia 20'!D43 -> 4 | W17: =+'Dia 21'!D43 -> 5 | X17: =+'Dia 22'!D43 -> 2 | Y17: =+'Dia 23'!D43 -> 1 | Z17: =+'Dia 25'!D43 -> 2 | AA17: =+'Dia 25'!D43 -> 2 | AB17: =+'Dia 26'!D43 -> 5 | AC17: =+'Dia 27'!D43 -> 1 | AD17: =+'Dia 28'!D43 -> 2 | AE17: =+'Dia 29'!D43 -> 4 | AF17: =+'Dia 30'!D43 -> 2 | AG17: =+'Dia 31'!D43 -> 10 | AH17: =SUM(C17:AG17) -> 166.1

Sheet Dia 1
B1: Día: 1
D2: 510 | E2: 510 | F2: 510
B3: VENTAS | C3: TRANSFERENCIAS CUP | D3: TRANSFERENCIAS ZELLE | E3: EURO | F3: USD | G3: EFECTIVO | H3: TRANSFERENCIA A CUENTA FISCAL (4660) | I3: TOTAL | J3: TOTAL USD
C4: =H9+H10 -> 0 | D4: 0 | E4: 0 | F4: 169 | G4: 0 | H4: 0 | I4: =+C4+E5+F5+G4+H4+D5 -> 86190 | J4: =+I4/F2 -> 169
D5: =+D4*D2 -> 0 | E5: =+E4*E2 -> 0 | F5: =+F4*F2 -> 86190
B7: Ventas
B8: Ventas Brutas | C8: =+I4 -> 86190 | G8: Transferencias CUP
B9: Gastos | C9: CUP | D9: USD | G9: 2236
B10: Salario | C10: =+C48 -> 4000 | D10: =+D48 -> 11.843137 | G10: 4910
B11: Renta
B12: Compras
B13: Perfumes Juank
B14: H&M
B15: Otros
B16: Electricidad
B17: Gas
B18: Pantry
B19: Comunicaciones | C19: 324 | D19: =C19/D2 -> 0.63529412
B20: Publicidad | C20: =C21+C22+C23 -> 0 | D20: =D21+D22+D23 -> 0
B21: Pago de colaboración modelos
B22: Comunity manager
B23: Creador de contenido
B24: Insumos de Limpieza
B25: Mantenimiento
B26: Insumos para la tienda
B27: Transporte
B28: Servicios contables
B29: Otros servicios comprados
B30: Total de Gastos | C30: =SUM(C10:C29) -> 4324 | D30: =SUM(D10:D20)+D24+D25+D26+D27+D28+D29 -> 12.478431
B33: Salario | C33: CUP | D33: USD
B34: Jacqueline
B35: Yeni | C35: 2000 | D35: =C35/F2 -> 3.9215686
B36: Daniela
B37: Lisandra | C37: 2000 | D37: =C37/F2 -> 3.9215686
B38: Aileen
B39: Laura
B40: Vanessa
B41: Magaly
B43: 0.02 | D43: =ROUNDUP(J4*0.02,0) -> 4
B48: Total | C48: =SUM(C34:C47) -> 4000 | D48: =SUM(D34:D47) -> 11.843137

Sheet Dia 2
B1: Día:2
D2: 510 | E2: 510 | F2: 510
B3: VENTAS | C3: TRANSFERENCIAS CUP | D3: TRANSFERENCIAS ZELLE | E3: EURO | F3: USD | G3: EFECTIVO | H3: TRANSFERENCIA A CUENTA FISCAL (4660) | I3: TOTAL | J3: TOTAL USD
C4: 0 | D4: 0 | E4: 0 | F4: 0 | G4: 0 | H4: 0 | I4: =+C4+E5+F5+G4+H4+D5 -> 0 | J4: =+I4/F2 -> 0
D5: =+D4*D2 -> 0 | E5: =+E4*E2 -> 0 | F5: =+F4*F2 -> 0
B7: Ventas
B8: Ventas Brutas | C8: =+I4 -> 0 | G8: Transferencias CUP
B9: Gastos | C9: CUP | D9: USD | G9: 2236
B10: Salario | C10: =+C48 -> 4000 | D10: =+D48 -> 27.843137 | G10: 4910
B11: Renta
B12: Compras
B13: Perfumes Juank
B14: H&M
B15: Otros
B16: Electricidad
B17: Gas
B18: Pantry
B19: Comunicaciones
B20: Publicidad | C20: =C21+C22+C23 -> 0 | D20: =D21+D22+D23 -> 0
B21: Pago de colaboración modelos
B22: Comunity manager
B23: Creador de contenido
B24: Insumos de Limpieza
B25: Mantenimiento | D25: 60 | E25: pintura cuarto hombre
B26: Insumos para la tienda
B27: Transporte
B28: Servicios contables
B29: Otros servicios comprados
B30: Total de Gastos | C30: =SUM(C10:C29) -> 4000 | D30: =SUM(D10:D20)+D24+D25+D26+D27+D28+D29 -> 87.843137
B33: Salario | C33: CUP | D33: USD
B34: Jacqueline | D34: =C34/$F$2 -> 0
B35: Yeni
B36: Daniela
B37: Lisandra | C37: 2000 | D37: =C37/$F$2 -> 3.9215686
B38: Aileen | C38: 2000 | D38: =C38/$F$2 -> 3.9215686
B39: Laura | D39: 20
B40: Vanessa
B41: Magaly
B43: 0.02 | D43: =ROUNDUP(J4*0.02,0) -> 0
B48: Total | C48: =SUM(C34:C47) -> 4000 | D48: =SUM(D34:D47) -> 27.843137

Sheet Dia 3
B1: Día:3
D2: 510 | E2: 510 | F2: 510
B3: VENTAS | C3: TRANSFERENCIAS CUP | D3: TRANSFERENCIAS ZELLE | E3: EURO | F3: USD | G3: EFECTIVO CUP | H3: TRANSFERENCIA A CUENTA FISCAL (4660) | I3: TOTAL | J3: TOTAL USD
C4: =H9+H10 -> 135130 | D4: 0 | E4: 0 | F4: 574 | G4: 0 | H4: 50000 | I4: =+C4+E5+F5+G4+H4+D5 -> 477870 | J4: =+I4/F2 -> 937
D5: =+D4*D2 -> 0 | E5: =+E4*E2 -> 0 | F5: =+F4*F2 -> 292740
B7: Ventas
B8: Ventas Brutas | C8: =+I4 -> 477870 | G8: Transferencias CUP
B9: Gastos | C9: CUP | D9: USD | G9: 2236 | H9: 50000
B10: Salario | C10: =+C48 -> 4000 | D10: =+D48 -> 26.843137 | G10: 4910 | H10: 85130
B11: Renta
B12: Compras
B13: Perfumes Juank
B14: H&M
B15: Otros
B16: Electricidad
B17: Gas
B18: Pantry
B19: Comunicaciones
B20: Publicidad | C20: =C21+C22+C23 -> 0 | D20: =D21+D22+D23 -> 100
B21: Pago de colaboración modelos
B22: Comunity manager | D22: 100
B23: Creador de contenido
B24: Insumos de Limpieza
B25: Mantenimiento | C25: 2000 | D25: =20+C25/510 -> 23.921569 | E25: 20 albañil
B26: Insumos para la tienda
B27: Transporte
B28: Servicios contables
B29: Otros servicios comprados
B30: Total de Gastos | C30: =SUM(C10:C29) -> 6000 | D30: =SUM(D10:D20)+D24+D25+D26+D27+D28+D29 -> 150.76471
B33: Salario | C33: CUP | D33: USD
B34: Jacqueline | D34: =C34/$F$2 -> 0
B35: Yeni
B36: Daniela
B37: Lisandra | C37: 2000 | D37: =C37/$F$2 -> 3.9215686
B38: Aileen | C38: 2000 | D38: =C38/$F$2 -> 3.9215686
B39: Laura
B40: Vanessa
B41: Magaly
B43: 0.02 | D43: =ROUNDUP(J4*0.02,0) -> 19
B48: Total | C48: =SUM(C34:C47) -> 4000 | D48: =SUM(D34:D47) -> 26.843137

Sheet Dia 4
B1: Día: 4
D2: 510 | E2: 510 | F2: 510
B3: VENTAS | C3: TRANSFERENCIAS CUP | D3: TRANSFERENCIAS ZELLE | E3: EURO | F3: USD | G3: EFECTIVO CUP | H3: TRANSFERENCIA A CUENTA FISCAL (4660) | I3: TOTAL | J3: TOTAL USD
C4: =H9+H10 -> 0 | D4: 0 | E4: 0 | F4: 110 | G4: 0 | H4: 0 | I4: =+C4+E5+F5+G4+H4+D5 -> 56100 | J4: =+I4/F2 -> 110
D5: =+D4*D2 -> 0 | E5: =+E4*E2 -> 0 | F5: =+F4*F2 -> 56100
B7: Ventas
B8: Ventas Brutas | C8: =+I4 -> 56100 | G8: Transferencias CUP
B9: Gastos | C9: CUP | D9: USD | G9: 2236
B10: Salario | C10: =+C48 -> 4000 | D10: =+D48 -> 10.843137 | G10: 4910
B11: Renta
B12: Compras
B13: Perfumes Juank
B14: H&M
B15: Otros
B16: Electricidad
B17: Gas
B18: Pantry
B19: Comunicaciones
B20: Publicidad | C20: =C21+C22+C23 -> 0 | D20: =D21+D22+D23 -> 0
B21: Pago de colaboración modelos
B22: Comunity manager
B23: Creador de contenido
B24: Insumos de Limpieza
B25: Mantenimiento
B26: Insumos para la tienda
B27: Transporte
B28: Servicios contables
B29: Otros servicios comprados
B30: Total de Gastos | C30: =SUM(C10:C29) -> 4000 | D30: =SUM(D10:D20)+D24+D25+D26+D27+D28+D29 -> 10.843137
B33: Salario | C33: CUP | D33: USD
B34: Jacqueline | C34: 2000 | D34: =C34/$F$2 -> 3.9215686
B35: Yeni
B36: Daniela
B37: Lisandra | C37: 2000 | D37: =C37/$F$2 -> 3.9215686
B38: Aileen | D38: =C38/$F$2 -> 0
B39: Laura | D39: =C39/$F$2 -> 0
B40: Vanessa
B41: Magaly
B43: 0.02 | D43: =ROUNDUP(J4*0.02,0) -> 3
B48: Total | C48: =SUM(C34:C47) -> 4000 | D48: =SUM(D34:D47) -> 10.843137

Sheet Dia 5
B1: Día: 5
D2: 510 | E2: 510 | F2: 510
B3: VENTAS | C3: TRANSFERENCIAS CUP | D3: TRANSFERENCIAS ZELLE | E3: EURO | F3: USD | G3: EFECTIVO | H3: TRANSFERENCIA A CUENTA FISCAL (4660) | I3: TOTAL | J3: TOTAL USD
C4: =H9+H10 -> 10000 | D4: 0 | E4: 0 | F4: 36 | G4: 0 | H4: 15500 | I4: =+C4+E5+F5+G4+H4+D5 -> 43860 | J4: =+I4/F2 -> 86
D5: =+D4*D2 -> 0 | E5: =+E4*E2 -> 0 | F5: =+F4*F2 -> 18360
B7: Ventas
B8: Ventas Brutas | C8: =+I4 -> 43860 | G8: Transferencias CUP
B9: Gastos | C9: CUP | D9: USD | G9: 2236 | H9: 10000
B10: Salario | C10: =+C48 -> 4000 | D10: =+D48 -> 9.8431373 | G10: 4910
B11: Renta
B12: Compras
B13: Perfumes Juank
B14: H&M
B15: Otros
B16: Electricidad
B17: Gas
B18: Pantry
B19: Comunicaciones
B20: Publicidad | C20: =C21+C22+C23 -> 0 | D20: =D21+D22+D23 -> 0
B21: Pago de colaboración modelos
B22: Comunity manager
B23: Creador de contenido
B24: Insumos de Limpieza
B25: Mantenimiento
B26: Insumos para la tienda
B27: Transporte
B28: Servicios contables
B29: Otros servicios comprados
B30: Total de Gastos | C30: =SUM(C10:C29) -> 4000 | D30: =SUM(D10:D20)+D24+D25+D26+D27+D28+D29 -> 9.8431373
B33: Salario | C33: CUP | D33: USD
B34: Jacqueline | C34: 2000 | D34: =C34/$F$2 -> 3.9215686
B35: Yeni
B36: Daniela
B37: Lisandra | D37: =C37/$F$2 -> 0
B38: Aileen | C38: 2000 | D38: =C38/$F$2 -> 3.9215686
B39: Laura | D39: =C39/$F$2 -> 0
B40: Vanessa
B41: Magaly
B43: 0.02 | D43: =ROUNDUP(J4*0.02,0) -> 2
B48: Total | C48: =SUM(C34:C47) -> 4000 | D48: =SUM(D34:D47) -> 9.8431373

Sheet Dia 6
B1: Día: 6
D2: 510 | E2: 510 | F2: 510
B3: VENTAS | C3: TRANSFERENCIAS CUP | D3: TRANSFERENCIAS ZELLE | E3: EURO | F3: USD | G3: EFECTIVO CUP | H3: TRANSFERENCIA A CUENTA FISCAL (4660) | I3: TOTAL | J3: TOTAL USD
C4: =H9+H10 -> 0 | D4: 74 | E4: 0 | F4: 65 | G4: 0 | H4: 0 | I4: =+C4+E5+F5+G4+H4+D5 -> 70890 | J4: =+I4/F2 -> 139
D5: =+D4*D2 -> 37740 | E5: =+E4*E2 -> 0 | F5: =+F4*F2 -> 33150
B7: Ventas
B8: Ventas Brutas | C8: =+I4 -> 70890 | G8: Transferencias CUP
B9: Gastos | C9: CUP | D9: USD | G9: 2236
B10: Salario | C10: =+C48 -> 4000 | D10: =+D48 -> 30.843137 | G10: 4910
B11: Renta | C11: 20000 | D11: =60+C11/E2 -> 99.215686 | E11: 60 usd +20 mil transf
B12: Compras
B13: Perfumes Juank
B14: H&M
B15: Otros
B16: Electricidad
B17: Gas
B18: Pantry
B19: Comunicaciones
B20: Publicidad | C20: =C21+C22+C23 -> 0 | D20: =D21+D22+D23 -> 0
B21: Pago de colaboración modelos
B22: Comunity manager
B23: Creador de contenido
B24: Insumos de Limpieza
B25: Mantenimiento
B26: Insumos para la tienda
B27: Transporte
B28: Servicios contables
B29: Otros servicios comprados
B30: Total de Gastos | C30: =SUM(C10:C29) -> 24000 | D30: =SUM(D10:D20)+D24+D25+D26+D27+D28+D29 -> 130.05882
B33: Salario | C33: CUP | D33: USD
B34: Jacqueline | C34: 2000 | D34: =C34/$F$2 -> 3.9215686
B35: Yeni
B36: Daniela
B37: Lisandra | D37: =C37/$F$2 -> 0
B38: Aileen | C38: 2000 | D38: =C38/$F$2 -> 3.9215686
B39: Laura | D39: 20
B40: Vanessa
B41: Magaly
B43: 0.02 | D43: =ROUNDUP(J4*0.02,0) -> 3
B48: Total | C48: =SUM(C34:C47) -> 4000 | D48: =SUM(D34:D47) -> 30.843137

Sheet Dia 7
B1: Día: 7
D2: 510 | E2: 510 | F2: 510
B3: VENTAS | C3: TRANSFERENCIAS CUP | D3: TRANSFERENCIAS ZELLE | E3: EURO | F3: USD | G3: EFECTIVO | H3: TRANSFERENCIA A CUENTA FISCAL (4660) | I3: TOTAL | J3: TOTAL USD
C4: =H9+H10 -> 20000 | D4: 0 | E4: 0 | F4: =296+99+10 -> 405 | G4: =19800+4000+1700 -> 25500 | H4: 5500 | I4: =+C4+E5+F5+G4+H4+D5 -> 257550 | J4: =+I4/F2 -> 505
D5: =+D4*D2 -> 0 | E5: =+E4*E2 -> 0 | F5: =+F4*F2 -> 206550
B7: Ventas
B8: Ventas Brutas | C8: =+I4 -> 257550 | G8: Transferencias CUP
B9: Gastos | C9: CUP | D9: USD | G9: 2236 | H9: 10000
B10: Salario | C10: =+C48 -> 4000 | D10: =+D48 -> 17.843137 | G10: 4910 | H10: 10000
B11: Renta
B12: Compras
B13: Perfumes Juank | D13: 99
B14: H&M
B15: Otros
B16: Electricidad
B17: Gas
B18: Pantry
B19: Comunicaciones
B20: Publicidad | C20: =C21+C22+C23 -> 0 | D20: =D21+D22+D23 -> 0
B21: Pago de colaboración modelos
B22: Comunity manager
B23: Creador de contenido
B24: Insumos de Limpieza
B25: Mantenimiento
B26: Insumos para la tienda
B27: Transporte | C27: 1700 | D27: =C27/F2 -> 3.3333333 | E27: Mensajería
B28: Servicios contables
B29: Otros servicios comprados
B30: Total de Gastos | C30: =SUM(C10:C29) -> 5700 | D30: =SUM(D10:D20)+D24+D25+D26+D27+D28+D29 -> 120.17647
B33: Salario | C33: CUP | D33: USD
B34: Jacqueline | D34: =C34/$F$2 -> 0
B35: Yeni | C35: 2000 | D35: =C35/510 -> 3.9215686
B36: Daniela
B37: Lisandra | C37: 2000 | D37: =C37/$F$2 -> 3.9215686
B38: Aileen | D38: =C38/$F$2 -> 0
B39: Laura | D39: =C39/$F$2 -> 0
B40: Vanessa
B41: Magaly
B43: 0.02 | D43: =ROUND(J4*0.02,0) -> 10
B48: Total | C48: =SUM(C34:C47) -> 4000 | D48: =SUM(D34:D47) -> 17.843137

Sheet Dia 8
B1: Día: 8
D2: 510 | E2: 510 | F2: 510
B3: VENTAS | C3: TRANSFERENCIAS CUP | D3: TRANSFERENCIAS ZELLE | E3: EURO | F3: USD | G3: EFECTIVO | H3: TRANSFERENCIA A CUENTA FISCAL (4660) | I3: TOTAL | J3: TOTAL USD
C4: =H9+H10 -> 0 | D4: 0 | E4: 0 | F4: =175+9 -> 184 | G4: =50060+4000+68140 -> 122200 | H4: 1100 | I4: =+C4+E5+F5+G4+H4+D5 -> 217140 | J4: =+I4/F2 -> 425.76471
D5: =+D4*D2 -> 0 | E5: =+E4*E2 -> 0 | F5: =+F4*F2 -> 93840
B7: Ventas
B8: Ventas Brutas | C8: =+I4 -> 217140 | G8: Transferencias CUP | H8: =68140/510 -> 133.60784
B9: Gastos | C9: CUP | D9: USD | G9: 2236
B10: Salario | C10: =+C48 -> 4000 | D10: =+D48 -> 15.943137 | G10: 4910
B11: Renta
B12: Compras
B13: Perfumes Juank
B14: H&M
B15: Otros
B16: Electricidad
B17: Gas
B18: Pantry
B19: Comunicaciones
B20: Publicidad | C20: =C21+C22+C23 -> 0 | D20: =D21+D22+D23 -> 0
B21: Pago de colaboración modelos
B22: Comunity manager
B23: Creador de contenido
B24: Insumos de Limpieza
B25: Mantenimiento
B26: Insumos para la tienda
B27: Transporte
B28: Servicios contables
B29: Otros servicios comprados
B30: Total de Gastos | C30: =SUM(C10:C29) -> 4000 | D30: =SUM(D10:D20)+D24+D25+D26+D27+D28+D29 -> 15.943137
B33: Salario | C33: CUP | D33: USD
B34: Jacqueline | D34: =C34/$F$2 -> 0
B35: Yeni
B36: Daniela
B37: Lisandra | C37: 2000 | D37: =C37/$F$2 -> 3.9215686
B38: Aileen | C38: 2000 | D38: =C38/$F$2 -> 3.9215686
B39: Laura | D39: =C39/$F$2 -> 0
B40: Vanessa
B41: Magaly
B43: 0.02 | D43: =405*0.02 -> 8.1
B48: Total | C48: =SUM(C34:C47) -> 4000 | D48: =SUM(D34:D47) -> 15.943137

Sheet Dia 9
B1: Día: 9
D2: 510 | E2: 510 | F2: 510
B3: VENTAS | C3: TRANSFERENCIAS CUP | D3: TRANSFERENCIAS ZELLE | E3: EURO | F3: USD | G3: EFECTIVO CUP | H3: TRANSFERENCIA A CUENTA FISCAL (4660) | I3: TOTAL | J3: TOTAL USD
C4: =H9+H10 -> 0 | D4: 0 | E4: 0 | F4: 60 | G4: 12750 | H4: 0 | I4: =+C4+E5+F5+G4+H4+D5 -> 43350 | J4: =+I4/F2 -> 85
D5: =+D4*D2 -> 0 | E5: =+E4*E2 -> 0 | F5: =+F4*F2 -> 30600
B7: Ventas
B8: Ventas Brutas | C8: =+I4 -> 43350 | G8: Transferencias CUP
B9: Gastos | C9: CUP | D9: USD | G9: 2236
B10: Salario | C10: =+C48 -> 4000 | D10: =+D48 -> 9.8431373 | G10: 4910
B11: Renta
B12: Compras
B13: Perfumes Juank
B14: H&M
B15: Otros
B16: Electricidad
B17: Gas
B18: Pantry
B19: Comunicaciones
B20: Publicidad | C20: =C21+C22+C23 -> 0 | D20: =D21+D22+D23 -> 0
B21: Pago de colaboración modelos
B22: Comunity manager
B23: Creador de contenido
B24: Insumos de Limpieza
B25: Mantenimiento
B26: Insumos para la tienda
B27: Transporte | C27: 500 | D27: =C27/F2 -> 0.98039216 | E27: Mensajería
B28: Servicios contables
B29: Otros servicios comprados
B30: Total de Gastos | C30: =SUM(C10:C29) -> 4500 | D30: =SUM(D10:D20)+D24+D25+D26+D27+D28+D29 -> 10.823529
B33: Salario | C33: CUP | D33: USD
B34: Jacqueline | D34: =C34/$F$2 -> 0
B35: Yeni | C35: 2000 | D35: =C35/$F$2 -> 3.9215686
B36: Daniela
B37: Lisandra | C37: 2000 | D37: =C37/$F$2 -> 3.9215686
B38: Aileen | D38: =C38/$F$2 -> 0
B39: Laura | D39: =C39/$F$2 -> 0
B40: Vanessa
B41: Magaly
B43: 0.02 | D43: =ROUNDUP(J4*0.02,0) -> 2
B48: Total | C48: =SUM(C34:C47) -> 4000 | D48: =SUM(D34:D47) -> 9.8431373

Sheet Dia 10
B1: Día: 10
D2: 510 | E2: 510 | F2: 510
B3: VENTAS | C3: TRANSFERENCIAS CUP | D3: TRANSFERENCIAS ZELLE | E3: EURO | F3: USD | G3: EFECTIVO | H3: TRANSFERENCIA A CUENTA FISCAL (4660) | I3: TOTAL | J3: TOTAL USD
C4: =H9+H10 -> 0 | D4: 0 | E4: 0 | F4: 158 | G4: 0 | H4: 0 | I4: =+C4+E5+F5+G4+H4+D5 -> 80580 | J4: =+I4/F2 -> 158
D5: =+D4*D2 -> 0 | E5: =+E4*E2 -> 0 | F5: =+F4*F2 -> 80580
B7: Ventas
B8: Ventas Brutas | C8: 158 | G8: Transferencias CUP
B9: Gastos | C9: CUP | D9: USD | G9: 2236
B10: Salario | C10: 4000 | D10: =+D48 -> 11.843137 | G10: 4910
B11: Renta
B12: Compras
B13: Perfumes Juank
B14: H&M
B15: Otros
B16: Electricidad
B17: Gas
B18: Pantry
B19: Comunicaciones
B20: Publicidad | C20: =C21+C22+C23 -> 0 | D20: =D21+D22+D23 -> 0
B21: Pago de colaboración modelos
B22: Comunity manager
B23: Creador de contenido
B24: Insumos de Limpieza
B25: Mantenimiento
B26: Insumos para la tienda
B27: Transporte
B28: Servicios contables
B29: Otros servicios comprados
B30: Total de Gastos | C30: =SUM(C10:C29) -> 4000 | D30: =SUM(D10:D20)+D24+D25+D26+D27+D28+D29 -> 11.843137
B33: Salario | C33: CUP | D33: USD
B34: Jacqueline | C34: 2000 | D34: =C34/$F$2 -> 3.9215686
B35: Yeni
B36: Daniela
B37: Lisandra | D37: =C37/$F$2 -> 0
B38: Aileen | C38: 2000 | D38: =C38/$F$2 -> 3.9215686
B39: Laura | D39: =C39/$F$2 -> 0
B40: Vanessa
B41: Magaly
B43: 0.02 | D43: =ROUNDUP(J4*0.02,0) -> 4
B48: Total | C48: =SUM(C34:C47) -> 4000 | D48: =SUM(D34:D47) -> 11.843137

Sheet Dia 11
B1: Día: 11
D2: 510 | E2: 510 | F2: 510
B3: VENTAS | C3: TRANSFERENCIAS CUP | D3: TRANSFERENCIAS ZELLE | E3: EURO | F3: USD | G3: EFECTIVO | H3: TRANSFERENCIA A CUENTA FISCAL (4660) | I3: TOTAL | J3: TOTAL USD
C4: =H9+H10 -> 0 | D4: 0 | E4: 0 | F4: =903+20+50 -> 973 | G4: 0 | H4: 0 | I4: =+C4+E5+F5+G4+H4+D5 -> 496230 | J4: =+I4/F2 -> 973
D5: =+D4*D2 -> 0 | E5: =+E4*E2 -> 0 | F5: =+F4*F2 -> 496230
B7: Ventas
B8: Ventas Brutas | C8: =+I4 -> 496230 | G8: Transferencias CUP
B9: Gastos | C9: CUP | D9: USD | G9: 2236
B10: Salario | C10: =+C48 -> 4000 | D10: =+D48 -> 27.843137 | G10: 4910
B11: Renta
B12: Compras
B13: Perfumes Juank
B14: H&M
B15: Otros
B16: Electricidad | C16: 260.64 | D16: =C16/D2 -> 0.51105882
B17: Gas
B18: Pantry
B19: Comunicaciones | C19: 20.7 | D19: =C19/D2 -> 0.040588235
B20: Publicidad | C20: =C21+C22+C23 -> 0 | D20: =D21+D22+D23 -> 0
B21: Pago de colaboración modelos
B22: Comunity manager
B23: Creador de contenido
B24: Insumos de Limpieza
B25: Mantenimiento
B26: Insumos para la tienda | D26: 50 | E26: 200 Bolsas
B27: Transporte | C27: 900 | D27: =C27/F2 -> 1.7647059 | E27: Mensajería bolsas
B28: Servicios contables
B29: Otros servicios comprados
B30: Total de Gastos | C30: =SUM(C10:C29) -> 5181.34 | D30: =SUM(D10:D20)+D24+D25+D26+D27+D28+D29 -> 80.15949
B33: Salario | C33: CUP | D33: USD
B34: Jacqueline | C34: 2000 | D34: =C34/$F$2 -> 3.9215686
B35: Yeni
B36: Daniela
B37: Lisandra | D37: =C37/$F$2 -> 0
B38: Aileen | C38: 2000 | D38: =C38/$F$2 -> 3.9215686
B39: Laura | D39: =C39/$F$2 -> 0
B40: Vanessa
B41: Magaly
B43: 0.02 | D43: =ROUNDUP(J4*0.02,0) -> 20
B48: Total | C48: =SUM(C34:C47) -> 4000 | D48: =SUM(D34:D47) -> 27.843137
...

Sheet Dia 12
B1: Día: 12
D2: 510 | E2: 510 | F2: 510
B3: VENTAS | C3: TRANSFERENCIAS CUP | D3: TRANSFERENCIAS ZELLE | E3: EURO | F3: USD | G3: EFECTIVO | H3: TRANSFERENCIA A CUENTA FISCAL (4660) | I3: TOTAL | J3: TOTAL USD
C4: =H9+H10 -> 0 | D4: 0 | E4: 0 | F4: 35 | G4: 0 | H4: 0 | I4: =+C4+E5+F5+G4+H4+D5 -> 17850 | J4: =+I4/F2 -> 35
D5: =+D4*D2 -> 0 | E5: =+E4*E2 -> 0 | F5: =+F4*F2 -> 17850
B7: Ventas
B8: Ventas Brutas | C8: =+I4 -> 17850 | G8: Transferencias CUP
B9: Gastos | C9: CUP | D9: USD | G9: 2236
B10: Salario | C10: =+C48 -> 4000 | D10: =+D48 -> 8.8431373 | G10: 4910
B11: Renta
B12: Compras
B13: Perfumes Juank
B14: H&M
B15: Otros
B16: Electricidad
B17: Gas
B18: Pantry
B19: Comunicaciones
B20: Publicidad | C20: =C21+C22+C23 -> 0 | D20: =D21+D22+D23 -> 0
B21: Pago de colaboración modelos
B22: Comunity manager
B23: Creador de contenido
B24: Insumos de Limpieza
B25: Mantenimiento
B26: Insumos para la tienda
B27: Transporte
B28: Servicios contables
B29: Otros servicios comprados
B30: Total de Gastos | C30: =SUM(C10:C29) -> 4000 | D30: =SUM(D10:D20)+D24+D25+D26+D27+D28+D29 -> 8.8431373
B33: Salario | C33: CUP | D33: USD
B34: Jacqueline | C34: 2000 | D34: =C34/$F$2 -> 3.9215686
B35: Yeni | D35: =C35/F2 -> 0
B36: Daniela
B37: Lisandra | D37: =C37/$F$2 -> 0
B38: Aileen | C38: 2000 | D38: =C38/$F$2 -> 3.9215686
B39: Laura | D39: =C39/$F$2 -> 0
B40: Vanessa
B41: Magaly
B43: 0.02 | D43: =ROUNDUP(J4*0.02,0) -> 1
B48: Total | C48: =SUM(C34:C47) -> 4000 | D48: =SUM(D34:D47) -> 8.8431373

Sheet Dia 13
B1: Día: 13
D2: 510 | E2: 510 | F2: 510
B3: VENTAS | C3: TRANSFERENCIAS CUP | D3: TRANSFERENCIAS ZELLE | E3: EURO | F3: USD | G3: EFECTIVO | H3: TRANSFERENCIA A CUENTA FISCAL (4660) | I3: TOTAL | J3: TOTAL USD
C4: =H9+H10 -> 0 | D4: 0 | E4: 0 | F4: 80 | G4: 25500 | H4: 0 | I4: =+C4+E5+F5+G4+H4+D5 -> 66300 | J4: =+I4/F2 -> 130
D5: =+D4*D2 -> 0 | E5: =+E4*E2 -> 0 | F5: =+F4*F2 -> 40800
B7: Ventas
B8: Ventas Brutas | C8: =+I4 -> 66300 | G8: Transferencias CUP
B9: Gastos | C9: CUP | D9: USD | G9: 2236
B10: Salario | C10: =+C48 -> 4000 | D10: =+D48 -> 10.843137 | G10: 4910
B11: Renta
B12: Compras
B13: Perfumes Juank
B14: H&M
B15: Otros
B16: Electricidad
B17: Gas
B18: Pantry
B19: Comunicaciones
B20: Publicidad | C20: =C21+C22+C23 -> 0 | D20: =D21+D22+D23 -> 0
B21: Pago de colaboración modelos
B22: Comunity manager
B23: Creador de contenido
B24: Insumos de Limpieza
B25: Mantenimiento
B26: Insumos para la tienda
B27: Transporte
B28: Servicios contables
B29: Otros servicios comprados
B30: Total de Gastos | C30: =SUM(C10:C29) -> 4000 | D30: =SUM(D10:D20)+D24+D25+D26+D27+D28+D29 -> 10.843137
B33: Salario | C33: CUP | D33: USD
B34: Jacqueline | D34: =C34/$F$2 -> 0
B35: Yeni | C35: 2000 | D35: =C35/F2 -> 3.9215686
B36: Daniela
B37: Lisandra | C37: 2000 | D37: =C37/$F$2 -> 3.9215686
B38: Aileen | D38: =C38/$F$2 -> 0
B39: Laura | D39: =C39/$F$2 -> 0
B40: Vanessa
B41: Magaly
B43: 0.02 | D43: =ROUNDUP(J4*0.02,0) -> 3
B48: Total | C48: =SUM(C34:C47) -> 4000 | D48: =SUM(D34:D47) -> 10.843137

Sheet Dia 14
B1: Día: 14
D2: 512 | E2: 512 | F2: 512
B3: VENTAS | C3: TRANSFERENCIAS CUP | D3: TRANSFERENCIAS ZELLE | E3: EURO | F3: USD | G3: EFECTIVO CUP | H3: TRANSFERENCIA A CUENTA FISCAL (4660) | I3: TOTAL | J3: TOTAL USD
C4: =H9+H10 -> 0 | D4: 0 | E4: 0 | F4: =528+154 -> 682 | G4: 92160 | H4: 0 | I4: =+C4+E5+F5+G4+H4+D5 -> 441344 | J4: =+I4/F2 -> 862
D5: =+D4*D2 -> 0 | E5: =+E4*E2 -> 0 | F5: =+F4*F2 -> 349184
B7: Ventas
B8: Ventas Brutas | C8: =+I4 -> 441344 | G8: Transferencias CUP
B9: Gastos | C9: CUP | D9: USD | G9: 2236
B10: Salario | C10: =+C48 -> 4000 | D10: =+D48 -> 25.8125 | G10: 4910
B11: Renta
B12: Compras
B13: Perfumes Juank | D13: 114
B14: H&M
B15: Otros
B16: Electricidad
B17: Gas
B18: Pantry
B19: Comunicaciones
B20: Publicidad | C20: =C21+C22+C23 -> 0 | D20: =D21+D22+D23 -> 40
B21: Pago de colaboración modelos | D21: 40 | E21: Fotos
B22: Comunity manager
B23: Creador de contenido
B24: Insumos de Limpieza
B25: Mantenimiento
B26: Insumos para la tienda
B27: Transporte
B28: Servicios contables
B29: Otros servicios comprados
B30: Total de Gastos | C30: =SUM(C10:C29) -> 4000 | D30: =SUM(D10:D20)+D24+D25+D26+D27+D28+D29 -> 179.8125
B33: Salario | C33: CUP | D33: USD
B34: Jacqueline | D34: =C34/$F$2 -> 0
B35: Yeni | C35: 2000 | D35: =C35/$F$2 -> 3.90625
B36: Daniela
B37: Lisandra | C37: 2000 | D37: =C37/$F$2 -> 3.90625
B38: Aileen | D38: =C38/$F$2 -> 0
B39: Laura | D39: =C39/$F$2 -> 0
B40: Vanessa
B41: Magaly
B43: 0.02 | D43: =ROUNDUP(J4*0.02,0) -> 18
B48: Total | C48: =SUM(C34:C47) -> 4000 | D48: =SUM(D34:D47) -> 25.8125

Sheet Dia 15
B1: Día: 15
D2: 510 | E2: 510 | F2: 510
B3: VENTAS | C3: TRANSFERENCIAS CUP | D3: TRANSFERENCIAS ZELLE | E3: EURO | F3: USD | G3: EFECTIVO | H3: TRANSFERENCIA A CUENTA FISCAL (4660) | I3: TOTAL | J3: TOTAL USD
C4: =H9+H10 -> 0 | D4: 0 | E4: 0 | F4: 60 | G4: 0 | H4: 0 | I4: =+C4+E5+F5+G4+H4+D5 -> 30600 | J4: =+I4/F2 -> 60
D5: =+D4*D2 -> 0 | E5: =+E4*E2 -> 0 | F5: =+F4*F2 -> 30600
B7: Ventas
B8: Ventas Brutas | C8: =+I4 -> 30600 | G8: Transferencias CUP
B9: Gastos | C9: CUP | D9: USD | G9: 2236
B10: Salario | C10: =+C48 -> 4000 | D10: =+D48 -> 9.8431373 | G10: 4910
B11: Renta
B12: Compras
B13: Perfumes Juank
B14: H&M
B15: Otros
B16: Electricidad
B17: Gas
B18: Pantry
B19: Comunicaciones
B20: Publicidad | C20: =C21+C22+C23 -> 0 | D20: =D21+D22+D23 -> 0
B21: Pago de colaboración modelos
B22: Comunity manager
B23: Creador de contenido
B24: Insumos de Limpieza
B25: Mantenimiento
B26: Insumos para la tienda
B27: Transporte
B28: Servicios contables
B29: Otros servicios comprados
B30: Total de Gastos | C30: =SUM(C10:C29) -> 4000 | D30: =SUM(D10:D20)+D24+D25+D26+D27+D28+D29 -> 9.8431373
B33: Salario | C33: CUP | D33: USD
B34: Jacqueline | D34: =C34/$F$2 -> 0
B35: Yeni | C35: 2000 | D35: =C35/$F$2 -> 3.9215686
B36: Daniela
B37: Lisandra | D37: =C37/$F$2 -> 0
B38: Aileen | C38: 2000 | D38: =C38/$F$2 -> 3.9215686
B39: Laura | D39: =C39/$F$2 -> 0
B40: Vanessa
B41: Magaly
B43: 0.02 | D43: =ROUNDUP(J4*0.02,0) -> 2
B48: Total | C48: =SUM(C34:C47) -> 4000 | D48: =SUM(D34:D47) -> 9.8431373

Sheet Dia 16
B1: Día: 16
D2: 510 | E2: 510 | F2: 510
B3: VENTAS | C3: TRANSFERENCIAS CUP | D3: TRANSFERENCIAS ZELLE | E3: EURO | F3: USD | G3: EFECTIVO CUP | H3: TRANSFERENCIA A CUENTA FISCAL (4660) | I3: TOTAL | J3: TOTAL USD
C4: =H9+H10 -> 7965 | D4: 0 | E4: 0 | F4: =557+20 -> 577 | G4: 7700 | H4: 10000 | I4: =+C4+E5+F5+G4+H4+D5 -> 319935 | J4: =+I4/F2 -> 627.32353
D5: =+D4*D2 -> 0 | E5: =+E4*E2 -> 0 | F5: =+F4*F2 -> 294270
B7: Ventas
B8: Ventas Brutas | C8: =+I4 -> 319935 | G8: Transferencias CUP
B9: Gastos | C9: CUP | D9: USD | G9: 2236
B10: Salario | C10: =+C48 -> 4000 | D10: =+D48 -> 40.843137 | G10: 4910 | H10: 7965
B11: Renta
B12: Compras
B13: Perfumes Juank
B14: H&M
B15: Otros
B16: Electricidad
B17: Gas
B18: Pantry
B19: Comunicaciones
B20: Publicidad | C20: =C21+C22+C23 -> 0 | D20: =D21+D22+D23 -> 0
B21: Pago de colaboración modelos
B22: Comunity manager
B23: Creador de contenido
B24: Insumos de Limpieza
B25: Mantenimiento
B26: Insumos para la tienda
B27: Transporte
B28: Servicios contables
B29: Otros servicios comprados
B30: Total de Gastos | C30: =SUM(C10:C29) -> 4000 | D30: =SUM(D10:D20)+D24+D25+D26+D27+D28+D29 -> 40.843137
B33: Salario | C33: CUP | D33: USD
B34: Jacqueline | C34: 2000 | D34: =C34/$F$2 -> 3.9215686
B35: Yeni
B36: Daniela
B37: Lisandra | C37: 2000 | D37: =C37/$F$2 -> 3.9215686
B38: Aileen | D38: =C38/$F$2 -> 0
B39: Laura | D39: 20
B40: Vanessa
B41: Magaly
B43: 0.02 | D43: =ROUNDUP(J4*0.02,0) -> 13
B48: Total | C48: =SUM(C34:C47) -> 4000 | D48: =SUM(D34:D47) -> 40.843137

Sheet Dia 17
B1: Día: 17
D2: 514 | E2: 514 | F2: 514
B3: VENTAS | C3: TRANSFERENCIAS CUP | D3: TRANSFERENCIAS ZELLE | E3: EURO | F3: USD | G3: EFECTIVO | H3: TRANSFERENCIA A CUENTA FISCAL (4660) | I3: TOTAL | J3: TOTAL USD
C4: =H9+H10 -> 0 | D4: 0 | E4: 0 | F4: 280 | G4: 0 | H4: 0 | I4: =+C4+E5+F5+G4+H4+D5 -> 143920 | J4: =+I4/F2 -> 280
D5: =+D4*D2 -> 0 | E5: =+E4*E2 -> 0 | F5: =+F4*F2 -> 143920
B7: Ventas
B8: Ventas Brutas | C8: =+I4 -> 143920 | G8: Transferencias CUP
B9: Gastos | C9: CUP | D9: USD | G9: 2236
B10: Salario | C10: =+C48 -> 4000 | D10: =+D48 -> 13.782101 | G10: 4910
B11: Renta
B12: Compras
B13: Perfumes Juank
B14: H&M
B15: Otros
B16: Electricidad
B17: Gas
B18: Pantry
B19: Comunicaciones
B20: Publicidad | C20: =C21+C22+C23 -> 0 | D20: =D21+D22+D23 -> 0
B21: Pago de colaboración modelos
B22: Comunity manager
B23: Creador de contenido
B24: Insumos de Limpieza
B25: Mantenimiento
B26: Insumos para la tienda | C26: 3000 | E26: (base teléfono)
B27: Transporte
B28: Servicios contables
B29: Otros servicios comprados
B30: Total de Gastos | C30: =SUM(C10:C28) -> 7000 | D30: =SUM(D10:D20)+D24+D25+D26+D27+D28+D29 -> 13.782101
B33: Salario | C33: CUP | D33: USD
B34: Jacqueline | C34: 2000 | D34: =C34/$F$2 -> 3.8910506
B35: Yeni
B36: Daniela
B37: Lisandra | D37: =C37/$F$2 -> 0
B38: Aileen | C38: 2000 | D38: =C38/$F$2 -> 3.8910506
B39: Laura | D39: =C39/$F$2 -> 0
B40: Vanessa
B41: Magaly
B43: 0.02 | D43: =ROUNDUP(J4*0.02,0) -> 6
B48: Total | C48: =SUM(C34:C47) -> 4000 | D48: =SUM(D34:D47) -> 13.782101

Sheet Dia 18
B1: Día: 18
D2: 514 | E2: 514 | F2: 514
B3: VENTAS | C3: TRANSFERENCIAS CUP | D3: TRANSFERENCIAS ZELLE | E3: EURO | F3: USD | G3: EFECTIVO | H3: TRANSFERENCIA A CUENTA FISCAL (4660) | I3: TOTAL | J3: TOTAL USD
C4: =H9+H10 -> 0 | D4: 0 | E4: 50 | F4: =240+5-50 -> 195 | G4: 1050 | H4: 0 | I4: =+C4+E5+F5+G4+H4+D5 -> 126980 | J4: =+I4/F2 -> 247.0428
D5: =+D4*D2 -> 0 | E5: =+E4*E2 -> 25700 | F5: =+F4*F2 -> 100230
B7: Ventas
B8: Ventas Brutas | C8: =+I4 -> 126980 | G8: Transferencias CUP
B9: Gastos | C9: CUP | D9: USD | G9: 2236
B10: Salario | C10: =+C48 -> 4000 | D10: =+D48 -> 12.782101 | G10: 4910
B11: Renta
B12: Compras
B13: Perfumes Juank
B14: H&M
B15: Otros
B16: Electricidad
B17: Gas
B18: Pantry
B19: Comunicaciones
B20: Publicidad | C20: =C21+C22+C23 -> 0 | D20: =D21+D22+D23 -> 0
B21: Pago de colaboración modelos
B22: Comunity manager
B23: Creador de contenido
B24: Insumos de Limpieza
B25: Mantenimiento
B26: Insumos para la tienda
B27: Transporte
B28: Servicios contables
B29: Otros servicios comprados
B30: Total de Gastos | C30: =SUM(C10:C29) -> 4000 | D30: =SUM(D10:D20)+D24+D25+D26+D27+D28+D29 -> 12.782101
B33: Salario | C33: CUP | D33: USD
B34: Jacqueline | C34: 2000 | D34: =C34/$F$2 -> 3.8910506
B35: Yeni
B36: Daniela
B37: Lisandra | D37: =C37/$F$2 -> 0
B38: Aileen | C38: 2000 | D38: =C38/$F$2 -> 3.8910506
B39: Laura | D39: =C39/$F$2 -> 0
B40: Vanessa
B41: Magaly
B43: 0.02 | D43: =ROUNDUP(J4*0.02,0) -> 5
B48: Total | C48: =SUM(C34:C47) -> 4000 | D48: =SUM(D34:D47) -> 12.782101

Sheet Dia 19
B1: Día: 19
D2: 512 | E2: 512 | F2: 512
B3: VENTAS | C3: TRANSFERENCIAS CUP | D3: TRANSFERENCIAS ZELLE | E3: EURO | F3: USD | G3: EFECTIVO | H3: TRANSFERENCIA A CUENTA FISCAL (4660) | I3: TOTAL | J3: TOTAL USD
C4: =H9+H10 -> 20720 | D4: 0 | E4: 0 | F4: 55 | G4: 12800 | H4: 10000 | I4: =+C4+E5+F5+G4+H4+D5 -> 71680 | J4: =+I4/F2 -> 140
D5: =+D4*D2 -> 0 | E5: =+E4*E2 -> 0 | F5: =+F4*F2 -> 28160
B7: Ventas
B8: Ventas Brutas | C8: =+I4 -> 71680 | G8: Transferencias CUP
B9: Gastos | C9: CUP | D9: USD | G9: 2236 | H9: 10720
B10: Salario | C10: =+C48 -> 4000 | D10: =+D48 -> 10.8125 | G10: 4910 | H10: 10000
B11: Renta
B12: Compras
B13: Perfumes Juank
B14: H&M
B15: Otros
B16: Electricidad
B17: Gas
B18: Pantry
B19: Comunicaciones
B20: Publicidad | C20: =C21+C22+C23 -> 0 | D20: =D21+D22+D23 -> 0
B21: Pago de colaboración modelos
B22: Comunity manager
B23: Creador de contenido
B24: Insumos de Limpieza
B25: Mantenimiento
B26: Insumos para la tienda
B27: Transporte
B28: Servicios contables
B29: Otros servicios comprados
B30: Total de Gastos | C30: =SUM(C10:C29) -> 4000 | D30: =SUM(D10:D20)+D24+D25+D26+D27+D28+D29 -> 10.8125
B33: Salario | C33: CUP | D33: USD
B34: Jacqueline | D34: =C34/$F$2 -> 0
B35: Yeni | C35: 2000 | D35: =C35/$F$2 -> 3.90625
B36: Daniela
B37: Lisandra | C37: 2000 | D37: =C37/$F$2 -> 3.90625
B38: Aileen | D38: =C38/$F$2 -> 0
B39: Laura | D39: =C39/$F$2 -> 0
B40: Vanessa
B41: Magaly
B43: 0.02 | D43: =ROUNDUP(J4*0.02,0) -> 3
B48: Total | C48: =SUM(C34:C47) -> 4000 | D48: =SUM(D34:D47) -> 10.8125

Sheet Dia 20
B1: Día: 4
D2: 512 | E2: 512 | F2: 512
B3: VENTAS | C3: TRANSFERENCIAS CUP | D3: TRANSFERENCIAS ZELLE | E3: EURO | F3: USD | G3: EFECTIVO | H3: TRANSFERENCIA A CUENTA FISCAL (4660) | I3: TOTAL | J3: TOTAL USD
C4: =H9+H10 -> 0 | D4: 0 | E4: 0 | F4: 165 | G4: 0 | H4: 0 | I4: =+C4+E5+F5+G4+H4+D5 -> 84480 | J4: =+I4/F2 -> 165
D5: =+D4*D2 -> 0 | E5: =+E4*E2 -> 0 | F5: =+F4*F2 -> 84480
B7: Ventas
B8: Ventas Brutas | C8: =+I4 -> 84480 | G8: Transferencias CUP
B9: Gastos | C9: CUP | D9: USD | G9: 2236
B10: Salario | C10: =+C48 -> 4000 | D10: =+D48 -> 11.8125 | G10: 4910
B11: Renta
B12: Compras
B13: Perfumes Juank
B14: H&M
B15: Otros
B16: Electricidad
B17: Gas
B18: Pantry
B19: Comunicaciones
B20: Publicidad | C20: =C21+C22+C23 -> 0 | D20: =D21+D22+D23 -> 0
B21: Pago de colaboración modelos
B22: Comunity manager
B23: Creador de contenido
B24: Insumos de Limpieza
B25: Mantenimiento
B26: Insumos para la tienda
B27: Transporte
B28: Servicios contables
B29: Otros servicios comprados
B30: Total de Gastos | C30: =SUM(C10:C29) -> 4000 | D30: =SUM(D10:D20)+D24+D25+D26+D27+D28+D29 -> 11.8125
B33: Salario | C33: CUP | D33: USD
B34: Jacqueline | D34: =C34/$F$2 -> 0
B35: Yeni | C35: 2000 | D35: =C35/$F$2 -> 3.90625
B36: Daniela
B37: Lisandra | C37: 2000 | D37: =C37/$F$2 -> 3.90625
B38: Aileen | D38: =C38/$F$2 -> 0
B39: Laura | D39: =C39/$F$2 -> 0
B40: Vanessa
B41: Magaly
B43: 0.02 | D43: =ROUNDUP(J4*0.02,0) -> 4
B48: Total | C48: =SUM(C34:C47) -> 4000 | D48: =SUM(D34:D47) -> 11.8125

Sheet Dia 21
B1: Día: 21
D2: 515 | E2: 515 | F2: 515
B3: VENTAS | C3: TRANSFERENCIAS CUP | D3: TRANSFERENCIAS ZELLE | E3: EURO | F3: USD | G3: EFECTIVO | H3: TRANSFERENCIA A CUENTA FISCAL (4660) | I3: TOTAL | J3: TOTAL USD
C4: =H9+H10 -> 0 | D4: 0 | E4: 0 | F4: 170 | G4: 16250 | H4: 0 | I4: =+C4+E5+F5+G4+H4+D5 -> 103800 | J4: =+I4/F2 -> 201.5534
D5: =+D4*D2 -> 0 | E5: =+E4*E2 -> 0 | F5: =+F4*F2 -> 87550
B7: Ventas
B8: Ventas Brutas | C8: =+I4 -> 103800 | G8: Transferencias CUP
B9: Gastos | C9: CUP | D9: USD | G9: 2236
B10: Salario | C10: =+C48 -> 4000 | D10: =+D48 -> 12.76699 | G10: 4910
B11: Renta
B12: Compras
B13: Perfumes Juank | F13: =(4000/515) -> 7.7669903
B14: H&M
B15: Otros
B16: Electricidad
B17: Gas
B18: Pantry
B19: Comunicaciones
B20: Publicidad | C20: =C21+C22+C23 -> 0 | D20: =D21+D22+D23 -> 0
B21: Pago de colaboración modelos
B22: Comunity manager
B23: Creador de contenido
B24: Insumos de Limpieza
B25: Mantenimiento
B26: Insumos para la tienda
B27: Transporte
B28: Servicios contables
B29: Otros servicios comprados
B30: Total de Gastos | C30: =SUM(C10:C29) -> 4000 | D30: =SUM(D10:D20)+D24+D25+D26+D27+D28+D29 -> 12.76699
B33: Salario | C33: CUP | D33: USD
B34: Jacqueline | D34: =C34/$F$2 -> 0
B35: Yeni | C35: 2000 | D35: =C35/$F$2 -> 3.8834951
B36: Daniela
B37: Lisandra | C37: 2000 | D37: =C37/$F$2 -> 3.8834951
B38: Aileen | D38: =C38/$F$2 -> 0
B39: Laura | D39: =C39/$F$2 -> 0
B40: Vanessa
B41: Magaly
B43: 0.02 | D43: =ROUNDUP(J4*0.02,0) -> 5
B48: Total | C48: =SUM(C34:C47) -> 4000 | D48: =SUM(D34:D47) -> 12.76699

Sheet Dia 22
B1: Día: 22
D2: 515 | E2: 515 | F2: 515
B3: VENTAS | C3: TRANSFERENCIAS CUP | D3: TRANSFERENCIAS ZELLE | E3: EURO | F3: USD | G3: EFECTIVO | H3: TRANSFERENCIA A CUENTA FISCAL (4660) | I3: TOTAL | J3: TOTAL USD
C4: =H9+H10 -> 0 | D4: 0 | E4: 0 | F4: 95 | G4: 0 | H4: 0 | I4: =+C4+E5+F5+G4+H4+D5 -> 48925 | J4: =+I4/F2 -> 95
D5: =+D4*D2 -> 0 | E5: =+E4*E2 -> 0 | F5: =+F4*F2 -> 48925
B7: Ventas
B8: Ventas Brutas | C8: =+I4 -> 48925 | G8: Transferencias CUP
B9: Gastos | C9: CUP | D9: USD | G9: 2236
B10: Salario | D10: =+D48 -> 9.7669903 | G10: 4910
B11: Renta
B12: Compras
B13: Perfumes Juank
B14: H&M
B15: Otros
B16: Electricidad
B17: Gas
B18: Pantry
B19: Comunicaciones
B20: Publicidad | C20: =C21+C22+C23 -> 0 | D20: =D21+D22+D23 -> 0
B21: Pago de colaboración modelos
B22: Comunity manager
B23: Creador de contenido
B24: Insumos de Limpieza
B25: Mantenimiento
B26: Insumos para la tienda
B27: Transporte
B28: Servicios contables
B29: Otros servicios comprados
B30: Total de Gastos | C30: =SUM(C10:C29) -> 0 | D30: =SUM(D10:D20)+D24+D25+D26+D27+D28+D29 -> 9.7669903
B33: Salario | C33: CUP | D33: USD
B34: Jacqueline | C34: 2000 | D34: =C34/$F$2 -> 3.8834951
B35: Yeni
B36: Daniela
B37: Lisandra | D37: =C37/$F$2 -> 0
B38: Aileen | C38: 2000 | D38: =C38/$F$2 -> 3.8834951
B39: Laura | D39: =C39/$F$2 -> 0
B40: Vanessa
B41: Magaly
B43: 0.02 | D43: =ROUNDUP(J4*0.02,0) -> 2
B48: Total | C48: =SUM(C34:C47) -> 4000 | D48: =SUM(D34:D47) -> 9.7669903

Sheet Dia 23
B1: Día: 23
D2: 515 | E2: 515 | F2: 515
B3: VENTAS | C3: TRANSFERENCIAS CUP | D3: TRANSFERENCIAS ZELLE | E3: EURO | F3: USD | G3: EFECTIVO | H3: TRANSFERENCIA A CUENTA FISCAL (4660) | I3: TOTAL | J3: TOTAL USD
C4: =H9+H10 -> 0 | D4: 0 | E4: 0 | F4: 0 | G4: =13550+4000+500 -> 18050 | H4: 0 | I4: =+C4+E5+F5+G4+H4+D5 -> 18050 | J4: =+I4/F2 -> 35.048544
D5: =+D4*D2 -> 0 | E5: =+E4*E2 -> 0 | F5: =+F4*F2 -> 0
B7: Ventas
B8: Ventas Brutas | C8: =+I4 -> 18050 | G8: Transferencias CUP
B9: Gastos | C9: CUP | D9: USD | G9: 2236
B10: Salario | C10: =+C48 -> 4000 | D10: =+D48 -> 8.7669903 | G10: 4910
B11: Renta
B12: Compras
B13: Perfumes Juank
B14: H&M
B15: Otros
B16: Electricidad
B17: Gas
B18: Pantry
B19: Comunicaciones
B20: Publicidad | C20: =C21+C22+C23 -> 0 | D20: =D21+D22+D23 -> 0
B21: Pago de colaboración modelos
B22: Comunity manager
B23: Creador de contenido
B24: Insumos de Limpieza
B25: Mantenimiento
B26: Insumos para la tienda
B27: Transporte
B28: Servicios contables
B29: Otros servicios comprados
B30: Total de Gastos | C30: =SUM(C10:C29) -> 4000 | D30: =SUM(D10:D20)+D24+D25+D26+D27+D28+D29 -> 8.7669903
B33: Salario | C33: CUP | D33: USD
B34: Jacqueline | C34: 2000 | D34: =C34/$F$2 -> 3.8834951
B35: Yeni
B36: Daniela
B37: Lisandra | D37: =C37/$F$2 -> 0
B38: Aileen | C38: 2000 | D38: =C38/$F$2 -> 3.8834951
B39: Laura | D39: =C39/$F$2 -> 0
B40: Vanessa
B41: Magaly
B43: 0.02 | D43: =ROUNDUP(J4*0.02,0) -> 1
B48: Total | C48: =SUM(C34:C47) -> 4000 | D48: =SUM(D34:D47) -> 8.7669903

Sheet Dia 24
B1: Día: 24
D2: 515 | E2: 515 | F2: 515
B3: VENTAS | C3: TRANSFERENCIAS CUP | D3: TRANSFERENCIAS ZELLE | E3: EURO | F3: USD | G3: EFECTIVO | H3: TRANSFERENCIA A CUENTA FISCAL (4660) | I3: TOTAL | J3: TOTAL USD
C4: =H9+H10 -> 0 | D4: 0 | E4: 0 | F4: 457 | G4: 0 | H4: 0 | I4: =+C4+E5+F5+G4+H4+D5 -> 235355 | J4: =+I4/F2 -> 457
D5: =+D4*D2 -> 0 | E5: =+E4*E2 -> 0 | F5: =+F4*F2 -> 235355
B7: Ventas
B8: Ventas Brutas | C8: =+I4 -> 235355 | G8: Transferencias CUP
B9: Gastos | C9: CUP | D9: USD | G9: 2236
B10: Salario | C10: =+C48 -> 4000 | D10: =+D48 -> 17.76699 | G10: 4910
B11: Renta
B12: Compras
B13: Perfumes Juank
B14: H&M
B15: Otros
B16: Electricidad
B17: Gas
B18: Pantry
B19: Comunicaciones
B20: Publicidad | C20: =C21+C22+C23 -> 0 | D20: =D21+D22+D23 -> 0
B21: Pago de colaboración modelos
B22: Comunity manager
B23: Creador de contenido
B24: Insumos de Limpieza
B25: Mantenimiento
B26: Insumos para la tienda
B27: Transporte
B28: Servicios contables
B29: Otros servicios comprados
B30: Total de Gastos | C30: =SUM(C10:C29) -> 4000 | D30: =SUM(D10:D20)+D24+D25+D26+D27+D28+D29 -> 17.76699
B33: Salario | C33: CUP | D33: USD
B34: Jacqueline | C34: 2000 | D34: =C34/$F$2 -> 3.8834951
B35: Yeni
B36: Daniela
B37: Lisandra | D37: =C37/$F$2 -> 0
B38: Aileen | C38: 2000 | D38: =C38/$F$2 -> 3.8834951
B39: Laura | D39: =C39/$F$2 -> 0
B40: Vanessa
B41: Magaly
B43: 0.02 | D43: =ROUNDUP(J4*0.02,0) -> 10
B48: Total | C48: =SUM(C34:C47) -> 4000 | D48: =SUM(D34:D47) -> 17.76699

Sheet Dia 25
B1: Día: 25
D2: 515 | E2: 515 | F2: 515
B3: VENTAS | C3: TRANSFERENCIAS CUP | D3: TRANSFERENCIAS ZELLE | E3: EURO | F3: USD | G3: EFECTIVO | H3: TRANSFERENCIA A CUENTA FISCAL (4660) | I3: TOTAL | J3: TOTAL USD
C4: =H9+H10 -> 0 | D4: 0 | E4: 0 | F4: 85 | G4: 0 | H4: 0 | I4: =+C4+E5+F5+G4+H4+D5 -> 43775 | J4: =+I4/F2 -> 85
D5: =+D4*D2 -> 0 | E5: =+E4*E2 -> 0 | F5: =+F4*F2 -> 43775
B7: Ventas
B8: Ventas Brutas | C8: =+I4 -> 43775 | G8: Transferencias CUP
B9: Gastos | C9: CUP | D9: USD | G9: 2236
B10: Salario | C10: =+C48 -> 4000 | D10: =+D48 -> 9.7669903 | G10: 4910
B11: Renta
B12: Compras
B13: Perfumes Juank
B14: H&M
B15: Otros
B16: Electricidad
B17: Gas
B18: Pantry
B19: Comunicaciones
B20: Publicidad | C20: =C21+C22+C23 -> 0 | D20: =D21+D22+D23 -> 0
B21: Pago de colaboración modelos
B22: Comunity manager
B23: Creador de contenido
B24: Insumos de Limpieza
B25: Mantenimiento
B26: Insumos para la tienda
B27: Transporte
B28: Servicios contables
B29: Otros servicios comprados
B30: Total de Gastos | C30: =SUM(C10:C29) -> 4000 | D30: =SUM(D10:D20)+D24+D25+D26+D27+D28+D29 -> 9.7669903
B33: Salario | C33: CUP | D33: USD
B34: Jacqueline | C34: 2000 | D34: =C34/$F$2 -> 3.8834951
B35: Yeni
B36: Daniela
B37: Lisandra | D37: =C37/$F$2 -> 0
B38: Aileen | C38: 2000 | D38: =C38/$F$2 -> 3.8834951
B39: Laura | D39: =C39/$F$2 -> 0
B40: Vanessa
B41: Magaly
B43: 0.02 | D43: =ROUNDUP(J4*0.02,0) -> 2
B48: Total | C48: =SUM(C34:C47) -> 4000 | D48: =SUM(D34:D47) -> 9.7669903

Sheet Dia 26
B1: Día: 26
D2: 515 | E2: 515 | F2: 515
B3: VENTAS | C3: TRANSFERENCIAS CUP | D3: TRANSFERENCIAS ZELLE | E3: EURO | F3: USD | G3: EFECTIVO | H3: TRANSFERENCIA A CUENTA FISCAL (4660) | I3: TOTAL | J3: TOTAL USD
C4: =H9+H10 -> 0 | D4: 0 | E4: 0 | F4: 141 | G4: 37600 | H4: 0 | I4: =+C4+E5+F5+G4+H4+D5 -> 110215 | J4: =+I4/F2 -> 214.00971
D5: =+D4*D2 -> 0 | E5: =+E4*E2 -> 0 | F5: =+F4*F2 -> 72615
B7: Ventas
B8: Ventas Brutas | C8: =+I4 -> 110215 | G8: Transferencias CUP
B9: Gastos | C9: CUP | D9: USD | G9: 2236 | J9: =J4-5 -> 209.00971
B10: Salario | C10: =+C48 -> 4000 | D10: =+D48 -> 12.76699 | G10: 4910
B11: Renta
B12: Compras
B13: Perfumes Juank
B14: H&M
B15: Otros
B16: Electricidad
B17: Gas | J17: =33100/F2 -> 64.271845
B18: Pantry
B19: Comunicaciones
B20: Publicidad | C20: =C21+C22+C23 -> 0 | D20: =D21+D22+D23 -> 0
B21: Pago de colaboración modelos
B22: Comunity manager
B23: Creador de contenido
B24: Insumos de Limpieza | J24: =141-5 -> 136
B25: Mantenimiento
B26: Insumos para la tienda
B27: Transporte
B28: Servicios contables
B29: Otros servicios comprados
B30: Total de Gastos | C30: =SUM(C10:C29) -> 4000 | D30: =SUM(D10:D20)+D24+D25+D26+D27+D28+D29 -> 12.76699
B33: Salario | C33: CUP | D33: USD
B34: Jacqueline | D34: =C34/$F$2 -> 0
B35: Yeni | C35: 2000 | D35: =C35/F2 -> 3.8834951
B36: Daniela
B37: Lisandra | C37: 2000 | D37: =C37/$F$2 -> 3.8834951
B38: Aileen | D38: =C38/$F$2 -> 0
B39: Laura | D39: =C39/$F$2 -> 0
B40: Vanessa
B41: Magaly
B43: 0.02 | D43: =ROUNDUP(J4*0.02,0) -> 5
B48: Total | C48: =SUM(C34:C47) -> 4000 | D48: =SUM(D34:D47) -> 12.76699

Sheet Dia 27
B1: Día: 27
D2: 515 | E2: 515 | F2: 515
B3: VENTAS | C3: TRANSFERENCIAS CUP | D3: TRANSFERENCIAS ZELLE | E3: EURO | F3: USD | G3: EFECTIVO | H3: TRANSFERENCIA A CUENTA FISCAL (4660) | I3: TOTAL | J3: TOTAL USD
C4: =H9+H10 -> 0 | D4: 0 | E4: 0 | F4: 30 | G4: 0 | H4: 0 | I4: =+C4+E5+F5+G4+H4+D5 -> 15450 | J4: =+I4/F2 -> 30
D5: =+D4*D2 -> 0 | E5: =+E4*E2 -> 0 | F5: =+F4*F2 -> 15450
B7: Ventas
B8: Ventas Brutas | C8: =+I4 -> 15450 | G8: Transferencias CUP
B9: Gastos | C9: CUP | D9: USD | G9: 2236
B10: Salario | C10: =+C48 -> 4000 | D10: =+D48 -> 8.7669903 | G10: 4910
B11: Renta
B12: Compras
B13: Perfumes Juank
B14: H&M
B15: Otros
B16: Electricidad
B17: Gas
B18: Pantry
B19: Comunicaciones
B20: Publicidad | C20: =C21+C22+C23 -> 0 | D20: =D21+D22+D23 -> 0
B21: Pago de colaboración modelos
B22: Comunity manager
