Workbook

Sheet Ventas
C2: VENTAS | D2: TRANSFERENCIAS CUP
B3: Dia | C3: Turno | D3: 2236 | E3: 4910 | F3: 4660 | G3: TRANSFERENCIAS ZELLE | H3: EURO | I3: USD | J3: CUP | K3: TOTAL | L3: TOTAL USD
B4: 1 | D4: ='DÍA 1'!C4 -> 0 | E4: ='DÍA 1'!D4 -> 0 | F4: ='DÍA 1'!E4 -> 0 | G4: ='DÍA 1'!F4 -> 0 | H4: ='DÍA 1'!G4 -> 0 | I4: ='DÍA 1'!H4 -> 768 | J4: ='DÍA 1'!I4 -> 0 | K4: ='DÍA 1'!J4 -> 395520 | L4: ='DÍA 1'!K4 -> 768
B5: 2 | D5: ='DÍA 2'!C4 -> 23925 | E5: ='DÍA 2'!D4 -> 25000 | F5: ='DÍA 2'!E4 -> 0 | G5: ='DÍA 2'!F4 -> 0 | H5: ='DÍA 2'!G4 -> 5 | I5: ='DÍA 2'!H4 -> 283 | J5: ='DÍA 2'!I4 -> 0 | K5: ='DÍA 2'!J4 -> 197245 | L5: ='DÍA 2'!K4 -> 383
B6: 3 | D6: ='DÍA 3'!C4 -> 0 | E6: ='DÍA 3'!D4 -> 0 | F6: ='DÍA 3'!E4 -> 0 | G6: ='DÍA 3'!F4 -> 0 | H6: ='DÍA 3'!G4 -> 0 | I6: ='DÍA 3'!H4 -> 697 | J6: ='DÍA 3'!I4 -> 15510 | K6: ='DÍA 3'!J4 -> 375859 | L6: ='DÍA 3'!K4 -> 727
B7: 4 | D7: ='DÍA 4'!C4 -> 0 | E7: ='DÍA 4'!D4 -> 0 | F7: ='DÍA 4'!E4 -> 0 | G7: ='DÍA 4'!F4 -> 0 | H7: ='DÍA 4'!G4 -> 0 | I7: ='DÍA 4'!H4 -> 205 | J7: ='DÍA 4'!I4 -> 0 | K7: ='DÍA 4'!J4 -> 106190 | L7: ='DÍA 4'!K4 -> 205
B8: 5 | D8: ='DÍA 5'!C4 -> 0 | E8: ='DÍA 5'!D4 -> 0 | F8: ='DÍA 5'!E4 -> 0 | G8: ='DÍA 5'!F4 -> 0 | H8: ='DÍA 5'!G4 -> 0 | I8: ='DÍA 5'!H4 -> 593 | J8: ='DÍA 5'!I4 -> 0 | K8: ='DÍA 5'!J4 -> 307174 | L8: ='DÍA 5'!K4 -> 593
B9: 6 | D9: ='DÍA 6'!C4 -> 0 | E9: ='DÍA 6'!D4 -> 0 | F9: ='DÍA 6'!E4 -> 0 | G9: ='DÍA 6'!F4 -> 0 | H9: ='DÍA 6'!G4 -> 0 | I9: ='DÍA 6'!H4 -> 90 | J9: ='DÍA 6'!I4 -> 0 | K9: ='DÍA 6'!J4 -> 46620 | L9: ='DÍA 6'!K4 -> 90
B10: 7 | D10: ='DÍA 7'!C4 -> 0 | E10: ='DÍA 7'!D4 -> 0 | F10: ='DÍA 7'!E4 -> 0 | G10: ='DÍA 7'!F4 -> 0 | H10: ='DÍA 7'!G4 -> 0 | I10: ='DÍA 7'!H4 -> 45 | J10: ='DÍA 7'!I4 -> 1040 | K10: ='DÍA 7'!J4 -> 24440 | L10: ='DÍA 7'!K4 -> 47
B11: 8 | D11: ='DÍA 8'!C4 -> 0 | E11: ='DÍA 8'!D4 -> 0 | F11: ='DÍA 8'!E4 -> 0 | G11: ='DÍA 8'!F4 -> 0 | H11: ='DÍA 8'!G4 -> 0 | I11: ='DÍA 8'!H4 -> 178 | J11: ='DÍA 8'!I4 -> 0 | K11: ='DÍA 8'!J4 -> 92560 | L11: ='DÍA 8'!K4 -> 178
B12: 9 | D12: ='DÍA 9'!C4 -> 0 | E12: ='DÍA 9'!D4 -> 0 | F12: ='DÍA 9'!E4 -> 0 | G12: ='DÍA 9'!F4 -> 0 | H12: ='DÍA 9'!G4 -> 0 | I12: ='DÍA 9'!H4 -> 103 | J12: ='DÍA 9'!I4 -> 0 | K12: ='DÍA 9'!J4 -> 53560 | L12: ='DÍA 9'!K4 -> 103
B13: 10 | D13: ='DÍA 10'!C4 -> 0 | E13: ='DÍA 10'!D4 -> 0 | F13: ='DÍA 10'!E4 -> 0 | G13: ='DÍA 10'!F4 -> 0 | H13: ='DÍA 10'!G4 -> 0 | I13: ='DÍA 10'!H4 -> 160 | J13: ='DÍA 10'!I4 -> 0 | K13: ='DÍA 10'!J4 -> 83200 | L13: ='DÍA 10'!K4 -> 160
B14: 11 | D14: ='DÍA 11'!C4 -> 0 | E14: ='DÍA 11'!D4 -> 78450 | F14: ='DÍA 11'!E4 -> 30334 | G14: ='DÍA 11'!F4 -> 0 | H14: ='DÍA 11'!G4 -> 0 | I14: ='DÍA 11'!H4 -> 35 | J14: ='DÍA 11'!I4 -> 26150 | K14: ='DÍA 11'!J4 -> 153239 | L14: ='DÍA 11'!K4 -> 293
B15: 12 | D15: ='DÍA 12'!C4 -> 0 | E15: ='DÍA 12'!D4 -> 0 | F15: ='DÍA 12'!E4 -> 0 | G15: ='DÍA 12'!F4 -> 0 | H15: ='DÍA 12'!G4 -> 0 | I15: ='DÍA 12'!H4 -> 477 | J15: ='DÍA 12'!I4 -> 0 | K15: ='DÍA 12'!J4 -> 249471 | L15: ='DÍA 12'!K4 -> 477
B16: 13 | D16: ='DÍA 13'!C4 -> 0 | E16: ='DÍA 13'!D4 -> 0 | F16: ='DÍA 13'!E4 -> 0 | G16: ='DÍA 13'!F4 -> 0 | H16: ='DÍA 13'!G4 -> 0 | I16: ='DÍA 13'!H4 -> 235.8 | J16: ='DÍA 13'!I4 -> 0 | K16: ='DÍA 13'!J4 -> 123323.4 | L16: ='DÍA 13'!K4 -> 235.8
B17: 14 | D17: ='DÍA 14'!C4 -> 0 | E17: ='DÍA 14'!D4 -> 0 | F17: ='DÍA 14'!E4 -> 0 | G17: ='DÍA 14'!F4 -> 0 | H17: ='DÍA 14'!G4 -> 0 | I17: ='DÍA 14'!H4 -> 85 | J17: ='DÍA 14'!I4 -> 26250 | K17: ='DÍA 14'!J4 -> 70875 | L17: ='DÍA 14'!K4 -> 135
B18: 15 | D18: ='DÍA 15'!C4 -> 10500 | E18: ='DÍA 15'!D4 -> 0 | F18: ='DÍA 15'!E4 -> 0 | G18: ='DÍA 15'!F4 -> 0 | H18: ='DÍA 15'!G4 -> 0 | I18: ='DÍA 15'!H4 -> 193 | J18: ='DÍA 15'!I4 -> 36850 | K18: ='DÍA 15'!J4 -> 148675 | L18: ='DÍA 15'!K4 -> 283.19048
B19: 16 | D19: ='DÍA 16'!C4 -> 0 | E19: ='DÍA 16'!D4 -> 0 | F19: ='DÍA 16'!E4 -> 21100 | G19: ='DÍA 16'!F4 -> 0 | H19: ='DÍA 16'!G4 -> 150 | I19: ='DÍA 16'!H4 -> 21 | J19: ='DÍA 16'!I4 -> 26250 | K19: ='DÍA 16'!J4 -> 137125 | L19: ='DÍA 16'!K4 -> 261.19048
B20: 17 | D20: ='DÍA 17'!C4 -> 0 | E20: ='DÍA 17'!D4 -> 0 | F20: ='DÍA 17'!E4 -> 0 | G20: ='DÍA 17'!F4 -> 0 | H20: ='DÍA 17'!G4 -> 70 | I20: ='DÍA 17'!H4 -> 169 | J20: ='DÍA 17'!I4 -> 116350 | K20: ='DÍA 17'!J4 -> 241825 | L20: ='DÍA 17'!K4 -> 460.61905
B21: 18 | D21: ='DÍA 18'!C4 -> 0 | E21: ='DÍA 18'!D4 -> 0 | F21: ='DÍA 18'!E4 -> 0 | G21: ='DÍA 18'!F4 -> 0 | H21: ='DÍA 18'!G4 -> 10 | I21: ='DÍA 18'!H4 -> 504 | J21: ='DÍA 18'!I4 -> 163645 | K21: ='DÍA 18'!J4 -> 433495 | L21: ='DÍA 18'!K4 -> 825.70476
B22: 19 | D22: ='DÍA 19'!C4 -> 0 | E22: ='DÍA 19'!D4 -> 0 | F22: ='DÍA 19'!E4 -> 0 | G22: ='DÍA 19'!F4 -> 0 | H22: ='DÍA 19'!G4 -> 0 | I22: ='DÍA 19'!H4 -> 221 | J22: ='DÍA 19'!I4 -> 18500 | K22: ='DÍA 19'!J4 -> 134525 | L22: ='DÍA 19'!K4 -> 256.2381
B23: 20 | D23: ='DÍA 20'!C4 -> 0 | E23: ='DÍA 20'!D4 -> 0 | F23: ='DÍA 20'!E4 -> 0 | G23: ='DÍA 20'!F4 -> 0 | H23: ='DÍA 20'!G4 -> 40 | I23: ='DÍA 20'!H4 -> 43 | J23: ='DÍA 20'!I4 -> 0 | K23: ='DÍA 20'!J4 -> 43575 | L23: ='DÍA 20'!K4 -> 83
B24: 21 | D24: ='DÍA 21'!C4 -> 0 | E24: ='DÍA 21'!D4 -> 0 | F24: ='DÍA 21'!E4 -> 0 | G24: ='DÍA 21'!F4 -> 0 | H24: ='DÍA 21'!G4 -> 0 | I24: ='DÍA 21'!H4 -> 119 | J24: ='DÍA 21'!I4 -> 0 | K24: ='DÍA 21'!J4 -> 62475 | L24: ='DÍA 21'!K4 -> 119
B25: 22 | D25: ='DÍA 22'!C4 -> 0 | E25: ='DÍA 22'!D4 -> 0 | F25: ='DÍA 22'!E4 -> 0 | G25: ='DÍA 22'!F4 -> 0 | H25: ='DÍA 22'!G4 -> 0 | I25: ='DÍA 22'!H4 -> 131.54 | J25: ='DÍA 22'!I4 -> 0 | K25: ='DÍA 22'!J4 -> 69716.2 | L25: ='DÍA 22'!K4 -> 131.54
B26: 23 | D26: ='DÍA 23'!C4 -> 0 | E26: ='DÍA 23'!D4 -> 0 | F26: ='DÍA 23'!E4 -> 0 | G26: ='DÍA 23'!F4 -> 0 | H26: ='DÍA 23'!G4 -> 0 | I26: ='DÍA 23'!H4 -> 113 | J26: ='DÍA 23'!I4 -> 17550 | K26: ='DÍA 23'!J4 -> 77440 | L26: ='DÍA 23'!K4 -> 146.11321
B27: 24 | D27: ='DÍA 24'!C4 -> 0 | E27: ='DÍA 24'!D4 -> 0 | F27: ='DÍA 24'!E4 -> 0 | G27: ='DÍA 24'!F4 -> 0 | H27: ='DÍA 24'!G4 -> 0 | I27: ='DÍA 24'!H4 -> 86 | J27: ='DÍA 24'!I4 -> 33127 | K27: ='DÍA 24'!J4 -> 78707 | L27: ='DÍA 24'!K4 -> 148.50377
B28: 25 | D28: ='DÍA 25'!C4 -> 0 | E28: ='DÍA 25'!D4 -> 0 | F28: ='DÍA 25'!E4 -> 0 | G28: ='DÍA 25'!F4 -> 0 | H28: ='DÍA 25'!G4 -> 200 | I28: ='DÍA 25'!H4 -> 90 | J28: ='DÍA 25'!I4 -> 184800 | K28: ='DÍA 25'!J4 -> 338500 | L28: ='DÍA 25'!K4 -> 638.67925
B29: 26 | D29: ='DÍA 26'!C4 -> 0 | E29: ='DÍA 26'!D4 -> 0 | F29: ='DÍA 26'!E4 -> 0 | G29: ='DÍA 26'!F4 -> 0 | H29: ='DÍA 26'!G4 -> 0 | I29: ='DÍA 26'!H4 -> 25 | J29: ='DÍA 26'!I4 -> 0 | K29: ='DÍA 26'!J4 -> 13250 | L29: ='DÍA 26'!K4 -> 25
B30: 27 | D30: ='DÍA 27'!C4 -> 0 | E30: ='DÍA 27'!D4 -> 0 | F30: ='DÍA 27'!E4 -> 0 | G30: ='DÍA 27'!F4 -> 0 | H30: ='DÍA 27'!G4 -> 0 | I30: ='DÍA 27'!H4 -> 674 | J30: ='DÍA 27'!I4 -> 540 | K30: ='DÍA 27'!J4 -> 357760 | L30: ='DÍA 27'!K4 -> 675.01887
B31: 28 | D31: ='DÍA 28'!C4 -> 0 | E31: ='DÍA 28'!D4 -> 0 | F31: ='DÍA 28'!E4 -> 0 | G31: ='DÍA 28'!F4 -> 0 | H31: ='DÍA 28'!G4 -> 100 | I31: ='DÍA 28'!H4 -> 582 | J31: ='DÍA 28'!I4 -> 17000 | K31: ='DÍA 28'!J4 -> 378460 | L31: ='DÍA 28'!K4 -> 714.07547
B32: 29 | D32: ='DÍA 29'!C4 -> 0 | E32: ='DÍA 29'!D4 -> 0 | F32: ='DÍA 29'!E4 -> 0 | G32: ='DÍA 29'!F4 -> 0 | H32: ='DÍA 29'!G4 -> 0 | I32: ='DÍA 29'!H4 -> 161 | J32: ='DÍA 29'!I4 -> 0 | K32: ='DÍA 29'!J4 -> 85330 | L32: ='DÍA 29'!K4 -> 161
B33: 30 | D33: ='DÍA 30'!C4 -> 149808 | E33: ='DÍA 30'!D4 -> 0 | F33: ='DÍA 30'!E4 -> 0 | G33: ='DÍA 30'!F4 -> 0 | H33: ='DÍA 30'!G4 -> 0 | I33: ='DÍA 30'!H4 -> 0 | J33: ='DÍA 30'!I4 -> 0 | K33: ='DÍA 30'!J4 -> 149808 | L33: ='DÍA 30'!K4 -> 281.06567
B34: TOTAL | D34: =+SUM(D4:D33) -> 184233 | E34: =+SUM(E4:E33) -> 103450 | F34: =+SUM(F4:F33) -> 51434 | G34: =+SUM(G4:G33) -> 0 | H34: =+SUM(H4:H33) -> 575 | I34: =+SUM(I4:I33) -> 7087.34 | J34: =+SUM(J4:J33) -> 683562 | K34: =+SUM(K4:K33) -> 5029942.6 | L34: =+SUM(L4:L33) -> 9604.7391
C36: Promedio diario | D36: =+D34/30 -> 6141.1 | E36: =+E34/30 -> 3448.3333 | F36: =+F34/30 -> 1714.4667 | G36: =+G34/30 -> 0 | H36: =+H34/30 -> 19.166667 | I36: =+I34/30 -> 236.24467 | J36: =+J34/30 -> 22785.4 | K36: =+K34/30 -> 167664.75 | L36: =+L34/30 -> 320.15797
D37: 2236 | E37: 4910 | F37: 4660 | G37: TRANSFERENCIAS ZELLE | H37: EURO | I37: USD | J37: CUP | K37: TOTAL | L37: TOTAL USD

Sheet Salario
C5: Dia1 | D5: Día 2 | E5: Dia3 | F5: Dia4 | G5: Dia5 | H5: Dia6 | I5: Dia7 | J5: Dia8 | K5: Dia9 | L5: Dia10 | M5: Dia11 | N5: Dia12 | O5: Dia13 | P5: Dia14 | Q5: Dia15 | R5: Dia16 | S5: Dia17 | T5: Dia18 | U5: Dia19 | V5: Dia20 | W5: Dia21 | X5: Dia22 | Y5: Dia23 | Z5: Dia24 | AA5: Dia25 | AB5: Dia26 | AC5: Dia27 | AD5: Dia28 | AE5: Dia29 | AF5: Dia30 | AG5: Dia31 | AH5: TOTAL MES
B6: Jacqueline | C6: ='DÍA 1'!C34 -> 0 | D6: ='DÍA 2'!C34 -> 0 | E6: ='DÍA 3'!C34 -> 2000 | F6: ='DÍA 4'!C34 -> 0 | G6: ='DÍA 5'!C34 -> 0 | H6: ='DÍA 6'!C34 -> 6000 | I6: ='DÍA 7'!C34 -> 2000 | J6: ='DÍA 8'!C34 -> 0 | K6: ='DÍA 9'!C34 -> 0 | L6: ='DÍA 10'!C34 -> 0 | M6: ='DÍA 11'!C34 -> 2000 | N6: ='DÍA 12'!C34 -> 0 | O6: ='DÍA 13'!C34 -> 0 | P6: ='DÍA 14'!C34 -> 2000 | Q6: ='DÍA 15'!C34 -> 2000 | R6: ='DÍA 16'!C34 -> 0 | S6: ='DÍA 17'!C34 -> 0 | T6: ='DÍA 18'!C34 -> 2000 | U6: ='DÍA 19'!C34 -> 2000 | V6: ='DÍA 20'!C34 -> 0 | W6: ='DÍA 21'!C34 -> 2000 | X6: ='DÍA 22'!C34 -> 2000 | Y6: ='DÍA 23'!C34 -> 2000 | Z6: ='DÍA 24'!C34 -> 0 | AA6: ='DÍA 25'!C34 -> 0 | AB6: ='DÍA 26'!C34 -> 0 | AC6: ='DÍA 27'!C34 -> 2000 | AD6: ='DÍA 28'!C34 -> 2000 | AE6: ='DÍA 29'!C34 -> 2000 | AF6: ='DÍA 30'!C34 -> 0 | AG6: ='DÍA 30'!C34 -> 0 | AH6: =SUM(C6:AG6) -> 32000
B7: Yeni | C7: ='DÍA 1'!C35 -> 2000 | D7: ='DÍA 2'!C35 -> 2000 | E7: ='DÍA 3'!C35 -> 0 | F7: ='DÍA 4'!C35 -> 0 | G7: ='DÍA 5'!C35 -> 0 | H7: ='DÍA 6'!C35 -> 2000 | I7: ='DÍA 7'!C35 -> 0 | J7: ='DÍA 8'!C35 -> 2000 | K7: ='DÍA 9'!C35 -> 0 | L7: ='DÍA 10'!C35 -> 0 | M7: ='DÍA 11'!C35 -> 1000 | N7: ='DÍA 12'!C35 -> 1000 | O7: ='DÍA 13'!C35 -> 0 | P7: ='DÍA 14'!C35 -> 0 | Q7: ='DÍA 15'!C35 -> 0 | R7: ='DÍA 16'!C35 -> 0 | S7: ='DÍA 17'!C35 -> 0 | T7: ='DÍA 18'!C35 -> 0 | U7: ='DÍA 19'!C35 -> 0 | V7: ='DÍA 20'!C35 -> 2000 | W7: ='DÍA 21'!C35 -> 0 | X7: ='DÍA 22'!C35 -> 0 | Y7: ='DÍA 23'!C35 -> 0 | Z7: ='DÍA 24'!C35 -> 2000 | AA7: ='DÍA 25'!C35 -> 0 | AB7: ='DÍA 26'!C35 -> 2000 | AC7: ='DÍA 27'!C35 -> 0 | AD7: ='DÍA 28'!C35 -> 0 | AE7: ='DÍA 29'!C35 -> 0 | AF7: ='DÍA 30'!C35 -> 0 | AG7: ='DÍA 30'!C35 -> 0 | AH7: =SUM(C7:AG7) -> 16000
B8: Daniela | C8: ='DÍA 1'!C36 -> 0 | D8: ='DÍA 2'!C36 -> 0 | E8: ='DÍA 3'!C36 -> 0 | F8: ='DÍA 4'!C36 -> 0 | G8: ='DÍA 5'!C36 -> 0 | H8: ='DÍA 6'!C36 -> 0 | I8: ='DÍA 7'!C36 -> 0 | J8: ='DÍA 8'!C36 -> 0 | K8: ='DÍA 9'!C36 -> 0 | L8: ='DÍA 10'!C36 -> 0 | M8: ='DÍA 11'!C36 -> 0 | N8: ='DÍA 12'!C36 -> 0 | O8: ='DÍA 13'!C36 -> 0 | P8: ='DÍA 14'!C36 -> 0 | Q8: ='DÍA 15'!C36 -> 0 | R8: ='DÍA 16'!C36 -> 0 | S8: ='DÍA 17'!C36 -> 0 | T8: ='DÍA 18'!C36 -> 0 | U8: ='DÍA 19'!C36 -> 0 | V8: ='DÍA 20'!C36 -> 0 | W8: ='DÍA 21'!C36 -> 0 | X8: ='DÍA 22'!C36 -> 0 | Y8: ='DÍA 23'!C36 -> 0 | Z8: ='DÍA 24'!C36 -> 0 | AA8: ='DÍA 25'!C36 -> 0 | AB8: ='DÍA 26'!C36 -> 0 | AC8: ='DÍA 27'!C36 -> 0 | AD8: ='DÍA 28'!C36 -> 0 | AE8: ='DÍA 29'!C36 -> 0 | AF8: ='DÍA 30'!C36 -> 0 | AG8: ='DÍA 30'!C36 -> 0 | AH8: =SUM(C8:AG8) -> 0
B9: Lisandra | C9: ='DÍA 1'!C37 -> 0 | D9: ='DÍA 2'!C37 -> 0 | E9: ='DÍA 3'!C37 -> 0 | F9: ='DÍA 4'!C37 -> 0 | G9: ='DÍA 5'!C37 -> 0 | H9: ='DÍA 6'!C37 -> 0 | I9: ='DÍA 7'!C37 -> 0 | J9: ='DÍA 8'!C37 -> 0 | K9: ='DÍA 9'!C37 -> 0 | L9: ='DÍA 10'!C37 -> 0 | M9: ='DÍA 11'!C37 -> 0 | N9: ='DÍA 12'!C37 -> 0 | O9: ='DÍA 13'!C37 -> 0 | P9: ='DÍA 14'!C37 -> 0 | Q9: ='DÍA 15'!C37 -> 0 | R9: ='DÍA 16'!C37 -> 0 | S9: ='DÍA 17'!C37 -> 0 | T9: ='DÍA 18'!C37 -> 0 | U9: ='DÍA 19'!C37 -> 0 | V9: ='DÍA 20'!C37 -> 0 | W9: ='DÍA 21'!C37 -> 0 | X9: ='DÍA 22'!C37 -> 0 | Y9: ='DÍA 23'!C37 -> 0 | Z9: ='DÍA 24'!C37 -> 0 | AA9: ='DÍA 25'!C37 -> 0 | AB9: ='DÍA 26'!C37 -> 0 | AC9: ='DÍA 27'!C37 -> 0 | AD9: ='DÍA 28'!C37 -> 0 | AE9: ='DÍA 29'!C37 -> 0 | AF9: ='DÍA 30'!C37 -> 0 | AG9: ='DÍA 30'!C37 -> 0 | AH9: =SUM(C9:AG9) -> 0
B10: Aileen | C10: ='DÍA 1'!C38 -> 0 | D10: ='DÍA 2'!C38 -> 2000 | E10: ='DÍA 3'!C38 -> 2000 | F10: ='DÍA 4'!C38 -> 2000 | G10: ='DÍA 5'!C38 -> 0 | H10: ='DÍA 6'!C38 -> 0 | I10: ='DÍA 7'!C38 -> 0 | J10: ='DÍA 8'!C38 -> 4000 | K10: ='DÍA 9'!C38 -> 2000 | L10: ='DÍA 10'!C38 -> 2000 | M10: ='DÍA 11'!C38 -> 2000 | N10: ='DÍA 12'!C38 -> 0 | O10: ='DÍA 13'!C38 -> 2000 | P10: ='DÍA 14'!C38 -> 2000 | Q10: ='DÍA 15'!C38 -> 2000 | R10: ='DÍA 16'!C38 -> 2000 | S10: ='DÍA 17'!C38 -> 2000 | T10: ='DÍA 18'!C38 -> 0 | U10: ='DÍA 19'!C38 -> 2000 | V10: ='DÍA 20'!C38 -> 0 | W10: ='DÍA 21'!C38 -> 2000 | X10: ='DÍA 22'!C38 -> 2000 | Y10: ='DÍA 23'!C38 -> 2000 | Z10: ='DÍA 24'!C38 -> 0 | AA10: ='DÍA 25'!C38 -> 2000 | AB10: ='DÍA 26'!C38 -> 2000 | AC10: ='DÍA 27'!C38 -> 0 | AD10: ='DÍA 28'!C38 -> 2000 | AE10: ='DÍA 29'!C38 -> 2000 | AF10: ='DÍA 30'!C38 -> 2000 | AG10: ='DÍA 30'!C38 -> 2000 | AH10: =SUM(C10:AG10) -> 46000
B11: Laura | C11: ='DÍA 1'!C39 -> 0 | D11: ='DÍA 2'!C39 -> 0 | E11: ='DÍA 3'!C39 -> 0 | F11: ='DÍA 4'!C39 -> 0 | G11: ='DÍA 5'!C39 -> 0 | H11: ='DÍA 6'!C39 -> 0 | I11: ='DÍA 7'!C39 -> 0 | J11: ='DÍA 8'!C39 -> 0 | K11: ='DÍA 9'!C39 -> 0 | L11: ='DÍA 10'!C39 -> 0 | M11: ='DÍA 11'!C39 -> 0 | N11: ='DÍA 12'!C39 -> 0 | O11: ='DÍA 13'!C39 -> 0 | P11: ='DÍA 14'!C39 -> 0 | Q11: ='DÍA 15'!C39 -> 0 | R11: ='DÍA 16'!C39 -> 0 | S11: ='DÍA 17'!C39 -> 5250 | T11: ='DÍA 18'!C39 -> 0 | U11: ='DÍA 19'!C39 -> 0 | V11: ='DÍA 20'!C39 -> 0 | W11: ='DÍA 21'!C39 -> 0 | X11: ='DÍA 22'!C39 -> 0 | Y11: ='DÍA 23'!C39 -> 0 | Z11: ='DÍA 24'!C39 -> 0 | AA11: ='DÍA 25'!C39 -> 0 | AB11: ='DÍA 26'!C39 -> 0 | AC11: ='DÍA 27'!C39 -> 0 | AD11: ='DÍA 28'!C39 -> 0 | AE11: ='DÍA 29'!C39 -> 0 | AF11: ='DÍA 30'!C39 -> 0 | AG11: ='DÍA 30'!C39 -> 0 | AH11: =SUM(C11:AG11) -> 5250
B12: Vanessa | C12: ='DÍA 1'!C40 -> 0 | D12: ='DÍA 2'!C40 -> 0 | E12: ='DÍA 3'!C40 -> 0 | F12: ='DÍA 4'!C40 -> 0 | G12: ='DÍA 5'!C40 -> 0 | H12: ='DÍA 6'!C40 -> 0 | I12: ='DÍA 7'!C40 -> 0 | J12: ='DÍA 8'!C40 -> 0 | K12: ='DÍA 9'!C40 -> 0 | L12: ='DÍA 10'!C40 -> 0 | M12: ='DÍA 11'!C40 -> 0 | N12: ='DÍA 12'!C40 -> 0 | O12: ='DÍA 13'!C40 -> 0 | P12: ='DÍA 14'!C40 -> 0 | Q12: ='DÍA 15'!C40 -> 0 | R12: ='DÍA 16'!C40 -> 0 | S12: ='DÍA 17'!C40 -> 0 | T12: ='DÍA 18'!C40 -> 0 | U12: ='DÍA 19'!C40 -> 0 | V12: ='DÍA 20'!C40 -> 0 | W12: ='DÍA 21'!C40 -> 0 | X12: ='DÍA 22'!C40 -> 0 | Y12: ='DÍA 23'!C40 -> 0 | Z12: ='DÍA 24'!C40 -> 0 | AA12: ='DÍA 25'!C40 -> 0 | AB12: ='DÍA 26'!C40 -> 0 | AC12: ='DÍA 27'!C40 -> 0 | AD12: ='DÍA 28'!C40 -> 0 | AE12: ='DÍA 29'!C40 -> 0 | AF12: ='DÍA 30'!C40 -> 0 | AG12: ='DÍA 30'!C40 -> 0 | AH12: =SUM(C12:AG12) -> 0
B13: Magaly | C13: ='DÍA 1'!C41 -> 0 | D13: ='DÍA 2'!C41 -> 0 | E13: ='DÍA 3'!C41 -> 0 | F13: ='DÍA 4'!C41 -> 0 | G13: ='DÍA 5'!C41 -> 0 | H13: ='DÍA 6'!C41 -> 0 | I13: ='DÍA 7'!C41 -> 0 | J13: ='DÍA 8'!C41 -> 0 | K13: ='DÍA 9'!C41 -> 0 | L13: ='DÍA 10'!C41 -> 0 | M13: ='DÍA 11'!C41 -> 0 | N13: ='DÍA 12'!C41 -> 0 | O13: ='DÍA 13'!C41 -> 0 | P13: ='DÍA 14'!C41 -> 0 | Q13: ='DÍA 15'!C41 -> 0 | R13: ='DÍA 16'!C41 -> 0 | S13: ='DÍA 17'!C41 -> 0 | T13: ='DÍA 18'!C41 -> 0 | U13: ='DÍA 19'!C41 -> 0 | V13: ='DÍA 20'!C41 -> 0 | W13: ='DÍA 21'!C41 -> 0 | X13: ='DÍA 22'!C41 -> 0 | Y13: ='DÍA 23'!C41 -> 0 | Z13: ='DÍA 24'!C41 -> 0 | AA13: ='DÍA 25'!C41 -> 0 | AB13: ='DÍA 26'!C41 -> 0 | AC13: ='DÍA 27'!C41 -> 0 | AD13: ='DÍA 28'!C41 -> 0 | AE13: ='DÍA 29'!C41 -> 0 | AF13: ='DÍA 30'!C41 -> 0 | AG13: ='DÍA 30'!C41 -> 0 | AH13: =SUM(C13:AG13) -> 0
C14: ='DÍA 1'!C42 -> 0 | D14: ='DÍA 2'!C42 -> 0 | E14: ='DÍA 3'!C42 -> 0 | F14: ='DÍA 4'!C42 -> 0 | G14: ='DÍA 5'!C42 -> 0 | H14: ='DÍA 6'!C42 -> 0 | I14: ='DÍA 7'!C42 -> 0 | J14: ='DÍA 8'!C42 -> 0 | K14: ='DÍA 9'!C42 -> 0 | L14: ='DÍA 10'!C42 -> 0 | M14: ='DÍA 11'!C42 -> 0 | N14: ='DÍA 12'!C42 -> 0 | O14: ='DÍA 13'!C42 -> 0 | P14: ='DÍA 14'!C42 -> 0 | Q14: ='DÍA 15'!C42 -> 0 | R14: ='DÍA 16'!C42 -> 0 | S14: ='DÍA 17'!C42 -> 0 | T14: ='DÍA 18'!C42 -> 0 | U14: ='DÍA 19'!C42 -> 0 | V14: ='DÍA 20'!C42 -> 0 | W14: ='DÍA 21'!C42 -> 0 | X14: ='DÍA 22'!C42 -> 0 | Y14: ='DÍA 23'!C42 -> 0 | Z14: ='DÍA 24'!C42 -> 0 | AA14: ='DÍA 25'!C42 -> 0 | AB14: ='DÍA 26'!C42 -> 0 | AC14: ='DÍA 27'!C42 -> 0 | AD14: ='DÍA 28'!C42 -> 0 | AE14: ='DÍA 29'!C42 -> 0 | AF14: ='DÍA 30'!C42 -> 0 | AG14: ='DÍA 30'!C42 -> 0 | AH14: =SUM(C14:AG14) -> 0
C15: =SUM(C6:C14) -> 2000 | D15: =SUM(D6:D14) -> 4000 | E15: =SUM(E6:E14) -> 4000 | F15: =SUM(F6:F14) -> 2000 | G15: =SUM(G6:G14) -> 0 | H15: =SUM(H6:H14) -> 8000 | I15: =SUM(I6:I14) -> 2000 | J15: =SUM(J6:J14) -> 6000 | ... AG15: =SUM(AG6:AG14) -> 2000 | AH15: =SUM(C15:AG15) -> 99250
B17: 0.02 | C17: ='DÍA 1'!F43 -> 15 | D17: ='DÍA 2'!F43 -> 8 | E17: ='DÍA 3'!F43 -> 15 | F17: ='DÍA 4'!F43 -> 5 | G17: ='DÍA 5'!F43 -> 12 | H17: ='DÍA 6'!F43 -> 2 | I17: ='DÍA 7'!F43 -> 1 | J17: ='DÍA 8'!F43 -> 4 | K17: ='DÍA 9'!F43 -> 3 | L17: ='DÍA 10'!F43 -> 4 | M17: ='DÍA 11'!F43 -> 6 | N17: ='DÍA 12'!F43 -> 10 | O17: ='DÍA 13'!F43 -> 5 | P17: ='DÍA 14'!F43 -> 3 | Q17: ='DÍA 15'!E43 -> 6 | R17: ='DÍA 16'!E43 -> 6 | S17: ='DÍA 17'!E43 -> 10 | T17: ='DÍA 18'!E43 -> 17 | U17: ='DÍA 19'!E43 -> 6 | V17: ='DÍA 20'!E43 -> 2 | W17: ='DÍA 21'!E42 -> 0 | X17: ='DÍA 22'!E43 -> 3 | Y17: ='DÍA 23'!E43 -> 3 | Z17: ='DÍA 24'!E43 -> 3 | AA17: ='DÍA 25'!E43 -> 13 | AB17: ='DÍA 26'!E43 -> 1 | AC17: ='DÍA 27'!E43 -> 14 | AD17: ='DÍA 28'!E43 -> 15 | AE17: ='DÍA 29'!E43 -> 4 | AF17: ='DÍA 30'!E43 -> 6 | AG17: ='DÍA 30'!E43 -> 6 | AH17: =SUM(C17:AG17) -> 208

Sheet DÍA 1
C2: TRANSFERENCIAS | G2: 515 | H2: 515 | I2: 515
B3: VENTAS | C3: 2236 | D3: 4910 | E3: 4660 | F3: TRANSFERENCIAS ZELLE | G3: EURO | H3: USD | I3: EFECTIVO | J3: TOTAL | K3: TOTAL USD | L3: DIFERENCIA
C4: 0 | F4: 0 | G4: 0 | H4: 768 | I4: 0 | J4: =+C4+D4+E4+F5+G5+H5+I4 -> 395520 | K4: =+J4/$H$2 -> 768 | L4: =K4-C8 -> 0
F5: =+F4*F2 -> 0 | G5: =+G4*G2 -> 0 | H5: =+H4*H2 -> 395520
B7: Ventas
B8: Ventas Brutas | C8: 768
B9: Gastos | C9: CUP | F9: USD
B10: Salario | C10: =+C47 -> 2000 | F10: =+F47 -> 18.883495
B11: Renta
B12: Compras
B13: Perfumes Juank
B14: H&M
B15: Otros
B16: Electricidad
B17: Gas
B18: Pantry
B19: Comunicaciones
B20: Publicidad
B21: Pago de colaboración modelos
B22: Comunity manager
... B29: Otros servicios comprados
B30: Total de Gastos | C30: =SUM(C10:C29) -> 2000 | F30: =SUM(F10:F20)+F24+F25+F26+F27+F28+F29 -> 18.883495
B33: Salario | C33: CUP | F33: USD
B34: Jacqueline | F34: =C34/$H$2 -> 0
B35: Yeni | C35: 2000 | F35: =C35/$H$2 -> 3.8834951
B36: Daniela | F36: =C36/$H$2 -> 0
B37: Lisandra | F37: =C37/$H$2 -> 0
B38: Aileen | F38: =C38/$H$2 -> 0
B39: Laura
B40: Vanessa
B41: Magaly
B43: 0.02 | F43: =ROUND(K4*0.02,0) -> 15
B47: Total | C47: =SUM(C34:C46) -> 2000 | F47: =SUM(F34:F46) -> 18.883495
B51: FONDO
B52: CUP | C52: USD | D52: EURO
A53: INICIAL | B53: 6110 | C53: 472 | D53: 40
A54: FINAL | B54: =B53-4000 -> 2110 | C54: 472 | D54: 40

Sheet DÍA 2
C2: TRANSFERENCIAS | G2: 515 | H2: 515 | I2: 515
B3: VENTAS | C3: 2236 | D3: 4910 | E3: 4660 | F3: TRANSFERENCIAS ZELLE | G3: EURO | H3: USD | I3: EFECTIVO | J3: TOTAL | K3: TOTAL USD | L3: DIFERENCIA
C4: 23925 | D4: 25000 | F4: 0 | G4: 5 | H4: =275+8 -> 283 | I4: 0 | J4: =+C4+D4+E4+F5+G5+H5+I4 -> 197245 | K4: =+J4/$H$2 -> 383 | L4: =K4-C8 -> 0
F5: =+F4*F2 -> 0 | G5: =+G4*G2 -> 2575 | H5: =+H4*H2 -> 145745
B7: Ventas
B8: Ventas Brutas | C8: 383
B9: Gastos | C9: CUP | F9: USD
B10: Salario | C10: =+C47 -> 4000 | F10: =+F47 -> 15.76699
B11: Renta
B12: Compras
B13: Perfumes Juank
B14: H&M
B15: Otros
B16: Electricidad
B17: Gas
B18: Pantry
B19: Comunicaciones
B20: Publicidad
B21: Pago de colaboración modelos
B22: Comunity manager
... B29: Otros servicios comprados
B30: Total de Gastos | C30: =SUM(C10:C29) -> 4000 | F30: =SUM(F10:F20)+F24+F25+F26+F27+F28+F29 -> 15.76699
B33: Salario | C33: CUP | F33: USD
B34: Jacqueline | F34: =C34/$H$2 -> 0
B35: Yeni | C35: 2000 | F35: =C35/$H$2 -> 3.8834951
B36: Daniela | F36: =C36/$H$2 -> 0
B37: Lisandra | F37: =C37/$H$2 -> 0
B38: Aileen | C38: 2000 | F38: =C38/$H$2 -> 3.8834951
B39: Laura
B40: Vanessa
B41: Magaly
B43: 0.02 | F43: =ROUND(K4*0.02,0) -> 8
B47: Total | C47: =SUM(C34:C46) -> 4000 | F47: =SUM(F34:F46) -> 15.76699
B51: FONDO
B52: CUP | C52: USD | D52: EURO
A53: INICIAL | B53: 6110 | C53: 472 | D53: 40
A54: FINAL | B54: =B53-4000 -> 2110 | C54: 472 | D54: 40

Sheet DÍA 3
C2: TRANSFERENCIAS | G2: 517 | H2: 517 | I2: 517
B3: VENTAS | C3: 2236 | D3: 4910 | E3: 4660 | F3: TRANSFERENCIAS ZELLE | G3: EURO | H3: USD | I3: EFECTIVO | J3: TOTAL | K3: TOTAL USD | L3: DIFERENCIA
C4: 0 | F4: 0 | G4: 0 | H4: =682+15 -> 697 | I4: 15510 | J4: =+C4+D4+E4+F5+G5+H5+I4 -> 375859 | K4: =+J4/$H$2 -> 727 | L4: =K4-C8 -> 0
F5: =+F4*F2 -> 0 | G5: =+G4*G2 -> 0 | H5: =+H4*H2 -> 360349
B7: Ventas
B8: Ventas Brutas | C8: 727
B9: Gastos | C9: CUP | F9: USD
B10: Salario | C10: =+C47 -> 4000 | F10: =+F47 -> 22.736944
B11: Renta
B12: Compras
B13: Perfumes Juank
B14: H&M
B15: Otros
B16: Electricidad
B17: Gas
B18: Pantry
B19: Comunicaciones
B20: Publicidad
B21: Pago de colaboración modelos
B22: Comunity manager
... B29: Otros servicios comprados
B30: Total de Gastos | C30: =SUM(C10:C29) -> 4000 | F30: =SUM(F10:F20)+F24+F25+F26+F27+F28+F29 -> 22.736944
B33: Salario | C33: CUP | F33: USD
B34: Jacqueline | C34: 2000 | F34: =C34/$H$2 -> 3.868472
B35: Yeni | F35: =C35/$H$2 -> 0
B36: Daniela | F36: =C36/$H$2 -> 0
B37: Lisandra | F37: =C37/$H$2 -> 0
B38: Aileen | C38: 2000 | F38: =C38/$H$2 -> 3.868472
B39: Laura
B40: Vanessa
B41: Magaly
B43: 0.02 | F43: =ROUNDUP(K4*0.02,0) -> 15
B47: Total | C47: =SUM(C34:C46) -> 4000 | F47: =SUM(F34:F46) -> 22.736944
B51: FONDO
B52: CUP | C52: USD | D52: EURO
A53: INICIAL | B53: 6110 | C53: 472 | D53: 40
A54: FINAL | B54: =B53-4000 -> 2110 | C54: 472 | D54: 40

Sheet DÍA 4
C2: TRANSFERENCIAS | G2: 518 | H2: 518 | I2: 518
B3: VENTAS | C3: 2236 | D3: 4910 | E3: 4660 | F3: TRANSFERENCIAS ZELLE | G3: EURO | H3: USD | I3: EFECTIVO | J3: TOTAL | K3: TOTAL USD | L3: DIFERENCIA
C4: 0 | F4: 0 | G4: 0 | H4: =201+4 -> 205 | J4: =+C4+D4+E4+F5+G5+H5+I4 -> 106190 | K4: =+J4/H2 -> 205 | L4: =K4-C8 -> 0
F5: =+F4*F2 -> 0 | G5: =+G4*G2 -> 0 | H5: =+H4*H2 -> 106190
B7: Ventas
B8: Ventas Brutas | C8: 205
B9: Gastos | C9: CUP | F9: USD
B10: Salario | C10: =+C47 -> 2000 | F10: =+F47 -> 8.8610039
B11: Renta
B12: Compras
B13: Perfumes Juank
B14: H&M
B15: Otros
B16: Electricidad
B17: Gas
B18: Pantry
B19: Comunicaciones
B20: Publicidad
B21: Pago de colaboración modelos
B22: Comunity manager
... B29: Otros servicios comprados
B30: Total de Gastos | C30: =SUM(C10:C29) -> 2000 | F30: =SUM(F10:F20)+F24+F25+F26+F27+F28+F29 -> 8.8610039
B33: Salario | C33: CUP | F33: USD
B34: Jacqueline | F34: =C34/$H$2 -> 0
B35: Yeni | F35: =C35/$H$2 -> 0
B36: Daniela | F36: =C36/$H$2 -> 0
B37: Lisandra | F37: =C37/$H$2 -> 0
B38: Aileen | C38: 2000 | F38: =C38/$H$2 -> 3.8610039
B39: Laura
B40: Vanessa
B41: Magaly
B43: 0.02 | F43: =ROUNDUP(K4*0.02,0) -> 5
B47: Total | C47: =SUM(C34:C46) -> 2000 | F47: =SUM(F34:F46) -> 8.8610039
B51: FONDO | F51: OBSERVACIONES
B52: CUP | C52: USD | D52: EURO | F52: El 2% de las ventas es 5 pero cobró 4 USD solamente.
A53: Inicial | B53: 2110 | C53: 472 | D53: 40
A54: final | B54: =B53-2000 -> 110 | C54: 472 | D54: 40

Sheet DÍA 5
C2: TRANSFERENCIAS | G2: 518 | H2: 518 | I2: 518
B3: VENTAS | C3: 2236 | D3: 4910 | E3: 4660 | F3: TRANSFERENCIAS ZELLE | G3: EURO | H3: USD | I3: EFECTIVO | J3: TOTAL | K3: TOTAL USD | L3: DIFERENCIA
C4: 0 | F4: 0 | G4: 0 | H4: =581+12 -> 593 | J4: =+C4+D4+E4+F5+G5+H5+I4 -> 307174 | K4: =+J4/H2 -> 593 | L4: =K4-C8 -> 0
F5: =+F4*F2 -> 0 | G5: =+G4*G2 -> 0 | H5: =+H4*H2 -> 307174
B7: Ventas
B8: Ventas Brutas | C8: 593
B9: Gastos | C9: CUP | F9: USD
B10: Salario | C10: =+C47 -> 0 | F10: =+F47 -> 12
B11: Renta
B12: Compras
B13: Perfumes Juank
B14: H&M
B15: Otros
B16: Electricidad
B17: Gas
B18: Pantry
B19: Comunicaciones
B20: Publicidad
B21: Pago de colaboración modelos
B22: Comunity manager
... B29: Otros servicios comprados
B30: Total de Gastos | C30: =SUM(C10:C29) -> 0 | F30: =SUM(F10:F20)+F24+F25+F26+F27+F28+F29 -> 12
B33: Salario | C33: CUP | F33: USD
B34: Jacqueline | F34: =C34/G2 -> 0
B35: Yeni
B36: Daniela
B37: Lisandra
B38: Aileen
B39: Laura
B40: Vanessa
B41: Magaly
B43: 0.02 | F43: =ROUNDUP(K4*0.02,0) -> 12
B47: Total | C47: =SUM(C34:C46) -> 0 | F47: =SUM(F34:F46) -> 12
B51: FONDO | F51: OBSERVACIONES
B52: CUP | C52: USD | D52: EURO | F52: Ninguna de las vendedoras (Aileén y Yaquelín) cobraron su salario pq no alcanzaba el dinero del fondo.
A53: Inicial | B53: 110 | C53: 472 | D53: 40
A54: final | B54: 110 | C54: 472 | D54: 40

Sheet DÍA 6
C2: TRANSFERENCIAS | G2: 518 | H2: 518 | I2: 518
B3: VENTAS | C3: 2236 | D3: 4910 | E3: 4660 | F3: TRANSFERENCIAS ZELLE | G3: EURO | H3: USD | I3: EFECTIVO | J3: TOTAL | K3: TOTAL USD | L3: DIFERENCIA
C4: 0 | F4: 0 | G4: 0 | H4: =88+2 -> 90 | J4: =+C4+D4+E4+F5+G5+H5+I4 -> 46620 | K4: =+J4/H2 -> 90 | L4: =K4-C8 -> 0
F5: =+F4*F2 -> 0 | G5: =+G4*G2 -> 0 | H5: =+H4*H2 -> 46620
B7: Ventas
B8: Ventas Brutas | C8: 90
B9: Gastos | C9: CUP | F9: USD
B10: Salario | C10: =+C47 -> 8000 | F10: =+F47 -> 17.444015
B11: Renta
B12: Compras
B13: Perfumes Juank
B14: H&M
B15: Otros
B16: Electricidad
B17: Gas
B18: Pantry
B19: Comunicaciones
B20: Publicidad
B21: Pago de colaboración modelos
B22: Comunity manager
... B29: Otros servicios comprados
B30: Total de Gastos | C30: =SUM(C10:C29) -> 8000 | F30: =SUM(F10:F20)+F24+F25+F26+F27+F28+F29 -> 17.444015
B33: Salario | C33: CUP | F33: USD
B34: Jacqueline | C34: 6000 | F34: =C34/$H$2 -> 11.583012
B35: Yeni | C35: 2000 | F35: =C35/$H$2 -> 3.8610039
B36: Daniela | F36: =C36/$H$2 -> 0
B37: Lisandra | F37: =C37/$H$2 -> 0
B38: Aileen | F38: =C38/$H$2 -> 0
B39: Laura
B40: Vanessa
B41: Magaly
B43: 0.02 | F43: =ROUNDUP(K4*0.02,0) -> 2
B47: Total | C47: =SUM(C34:C46) -> 8000 | F47: =SUM(F34:F46) -> 17.444015
B51: FONDO | F51: OBSERVACIONES
B52: CUP | C52: USD | D52: EURO | F52: En el día de hoy se incrementó el dinero del fondo con 20000 CUP Yaquelín cobro el salario de hoy, el de ayer y al parecer de otro día que dejó de cobrar.
A53: Inicial | B53: =110 +20000 -> 20110 | C53: 472 | D53: 40
A54: Final | B54: =B53-8000 -> 12110 | C54: 472 | D54: 40

Sheet DÍA 7
C2: TRANSFERENCIAS | G2: 520 | H2: 520 | I2: 520
B3: VENTAS | C3: 2236 | D3: 4910 | E3: 4660 | F3: TRANSFERENCIAS ZELLE | G3: EURO | H3: USD | I3: EFECTIVO | J3: TOTAL | K3: TOTAL USD | L3: DIFERENCIA
C4: 0 | F4: 0 | G4: 0 | H4: =44+1 -> 45 | I4: =40+1000 -> 1040 | J4: =+C4+D4+E4+F5+G5+H5+I4 -> 24440 | K4: =+J4/H2 -> 47 | L4: =K4-C8 -> 0
F5: =+F4*F2 -> 0 | G5: =+G4*G2 -> 0 | H5: =+H4*H2 -> 23400
B7: Ventas
B8: Ventas Brutas | C8: 47
B9: Gastos | C9: CUP | F9: USD
B10: Salario | C10: =+C47 -> 2000 | F10: =+F47 -> 4.8461538
B11: Renta
B12: Compras
B13: Perfumes Juank
B14: H&M
B15: Otros
B16: Electricidad
B17: Gas
B18: Pantry
B19: Comunicaciones
B20: Publicidad
B21: Pago de colaboración modelos
B22: Comunity manager
... B29: Otros servicios comprados
B30: Total de Gastos | C30: =SUM(C10:C29) -> 2000 | F30: =SUM(F10:F20)+F24+F25+F26+F27+F28+F29 -> 4.8461538
B33: Salario | C33: CUP | F33: USD
B34: Jacqueline | C34: 2000 | F34: =C34/$G$2 -> 3.8461538
B35: Yeni | F35: =C35/$G$2 -> 0
B36: Daniela | F36: =C36/$G$2 -> 0
B37: Lisandra | F37: =C37/$G$2 -> 0
B38: Aileen | F38: =C38/$G$2 -> 0
B39: Laura
B40: Vanessa
B41: Magaly
B43: 0.02 | F43: =ROUNDUP(K4*0.02,0) -> 1
B47: Total | C47: =SUM(C34:C46) -> 2000 | F47: =SUM(F34:F46) -> 4.8461538
B51: FONDO | F51: OBSERVACIONES
B52: CUP | C52: USD | D52: EURO | F52: La vendedora cobro del fondo 1000 y al parecer los otros 1000 pesos los cobró de la venta, no se sabe porque pues había fondo para haberlo cobrado de este.
B53: 12110 | C53: 472 | D53: 40
B54: =B53-1000 -> 11110 | C54: 472 | D54: 40

Sheet DÍA 8
C2: TRANSFERENCIAS | G2: 520 | H2: 520 | I2: 520
B3: VENTAS | C3: 2236 | D3: 4910 | E3: 4660 | F3: TRANSFERENCIAS ZELLE | G3: EURO | H3: USD | I3: EFECTIVO | J3: TOTAL | K3: TOTAL USD | L3: DIFERENCIA
C4: 0 | F4: 0 | G4: 0 | H4: =74+100+4 -> 178 | J4: =+C4+D4+E4+F5+G5+H5+I4 -> 92560 | K4: =+J4/H2 -> 178 | L4: =K4-C8 -> 0
F5: =+F4*F2 -> 0 | G5: =+G4*G2 -> 0 | H5: =+H4*H2 -> 92560
B7: Ventas
B8: Ventas Brutas | C8: 178
B9: Gastos | C9: CUP | F9: USD
B10: Salario | C10: =+C47 -> 6000 | F10: =+F47 -> 115.53846
B11: Renta
B12: Compras
B13: Perfumes Juank
B14: H&M
B15: Otros
B16: Electricidad
B17: Gas | C17: 75 | F17: =C17/G2 -> 0.14423077
B18: Pantry
B19: Comunicaciones
B20: Publicidad
B21: Pago de colaboración modelos
B22: Comunity manager
B23: Creador de contenido
B24: Insumos de Limpieza
B25: Mantenimiento
B26: Insumos para la tienda
B27: Transporte
B28: Servicios contables
B29: Otros servicios comprados
B30: Total de Gastos | C30: =SUM(C10:C29) -> 6075 | F30: =SUM(F10:F20)+F24+F25+F26+F27+F28+F29 -> 115.68269
B33: Salario | C33: CUP | F33: USD
B34: Jacqueline | F34: =C34/$G$2 -> 0
B35: Yeni | C35: 2000 | F35: =C35/$G$2 -> 3.8461538
B36: Daniela | F36: =C36/$G$2 -> 0
B37: Lisandra | F37: =C37/$G$2 -> 0
B38: Aileen | C38: 4000 | F38: =C38/$G$2 -> 7.6923077
B39: Laura | F39: 100
B40: Vanessa
B41: Magaly
B43: 0.02 | F43: =ROUNDUP(K4*0.02,0) -> 4
B47: Total | C47: =SUM(C34:C46) -> 6000 | F47: =SUM(F34:F46) -> 115.53846
B51: FONDO | F51: OBSERVACIONES
...

Sheet DÍA 9
C2: TRANSFERENCIAS | G2: 520 | H2: 520 | I2: 520
B3: VENTAS | C3: 2236 | D3: 4910 | E3: 4660 | F3: TRANSFERENCIAS ZELLE | G3: EURO | H3: USD | I3: EFECTIVO | J3: TOTAL | K3: TOTAL USD | L3: DIFERENCIA
C4: 0 | F4: 0 | G4: 0 | H4: =103 -> 103 | J4: =+C4+D4+E4+F5+G5+H5+I4 -> 53560 | K4: =+J4/H2 -> 103 | L4: =K4-C8 -> -2
F5: =+F4*F2 -> 0 | G5: =+G4*G2 -> 0 | H5: =+H4*H2 -> 53560
B7: Ventas
B8: Ventas Brutas | C8: 105
B9: Gastos | C9: CUP | F9: USD
B10: Salario | C10: =+C47 -> 2000 | F10: =+F47 -> 6.8461538
B11: Renta
B12: Compras
B13: Perfumes Juank
B14: H&M
B15: Otros
B16: Electricidad
B17: Gas
B18: Pantry
B19: Comunicaciones
B20: Publicidad
B21: Pago de colaboración modelos
B22: Comunity manager
... B29: Otros servicios comprados
B30: Total de Gastos | C30: =SUM(C10:C29) -> 2000 | F30: =SUM(F10:F20)+F24+F25+F26+F27+F28+F29 -> 6.8461538
B33: Salario | C33: CUP | F33: USD
B34: Jacqueline | F34: =C34/$G$2 -> 0
B35: Yeni | F35: =C35/$G$2 -> 0
B36: Daniela | F36: =C36/$G$2 -> 0
B37: Lisandra | F37: =C37/$G$2 -> 0
B38: Aileen | C38: 2000 | F38: =C38/$G$2 -> 3.8461538
B39: Laura
B40: Vanessa
B41: Magaly
B43: 0.02 | F43: =ROUNDUP(K4*0.02,0) -> 3
B47: Total | C47: =SUM(C34:C46) -> 2000 | F47: =SUM(F34:F46) -> 6.8461538
B51: FONDO | F51: OBSERVACIONES
B52: CUP | C52: USD | D52: EURO | F52: El fondo d este día está mal calculado pues el día 8 cuyo fondo inicial en MN era de 11110 hubo que restarle los 6000 de salario más los 75 pesos de la factura del gas. Por tanto el Fondo inicial este día 9 es 5035 MN y ellas reflejaron 5040.
B53: 5040 | C53: 472 | D53: 40
B54: =B53-2000 -> 3040 | C54: =C53+2 -> 474 | D54: 40
F56: El 2 % que es igual a 2.1 USD por exceso serían 3 dolares, pero Aileen lo asume como dos. Declara que liquida 103 USD por lo que no coincide la venta del día con lo liquidado. Sin embargo esos 2 USD se los sumó al fondo de USD. Quedó pendiente de cobrar 1 USD.

Sheet DÍA 10
C2: TRANSFERENCIAS | G2: 520 | H2: 520 | I2: 520
B3: VENTAS | C3: 2236 | D3: 4910 | E3: 4660 | F3: TRANSFERENCIAS ZELLE | G3: EURO | H3: USD | I3: EFECTIVO | J3: TOTAL | K3: TOTAL USD | L3: DIFERENCIA
C4: 0 | F4: 0 | G4: 0 | H4: =110+47+3 -> 160 | J4: =+C4+D4+E4+F5+G5+H5+I4 -> 83200 | K4: =+J4/H2 -> 160 | L4: =K4-C8 -> 0
F5: =+F4*F2 -> 0 | G5: =+G4*G2 -> 0 | H5: =+H4*H2 -> 83200
B7: Ventas
B8: Ventas Brutas | C8: 160
B9: Gastos | C9: CUP | F9: USD
B10: Salario | C10: =+C47 -> 2000 | F10: =+F47 -> 7.8461538
B11: Renta | F11: 300
B12: Compras
B13: Perfumes Juank | F13: 47
B14: H&M
B15: Otros
B16: Electricidad
B17: Gas
B18: Pantry
B19: Comunicaciones
B20: Publicidad
B21: Pago de colaboración modelos
B22: Comunity manager
B23: Creador de contenido
B24: Insumos de Limpieza
B25: Mantenimiento
... B29: Otros servicios comprados
B30: Total de Gastos | C30: =SUM(C10:C29) -> 2000 | F30: =SUM(F10:F20)+F24+F25+F26+F27+F28+F29 -> 354.84615
B33: Salario | C33: CUP | F33: USD
B34: Jacqueline | F34: =C34/$H$2 -> 0
B35: Yeni | F35: =C35/$H$2 -> 0
B36: Daniela | F36: =C36/$H$2 -> 0
B37: Lisandra | F37: =C37/$H$2 -> 0
B38: Aileen | C38: 2000 | F38: =C38/$H$2 -> 3.8461538
B39: Laura
B40: Vanessa
B41: Magaly
B43: 0.02 | F43: =ROUNDUP(K4*0.02,0) -> 4
B47: Total | C47: =SUM(C34:C46) -> 2000 | F47: =SUM(F34:F46) -> 7.8461538
B51: FONDO | F51: OBSERVACIONES
B52: CUP | C52: USD | D52: EURO | F52: Se sigue arrastrando el error en el fondo en MN
A53: INICIAL | B53: 3040 | C53: 474 | D53: 40
A54: FINAL | B54: =B53-2000 -> 1040 | C54: 474 | D54: 40
...

Sheet DÍA 11
C2: TRANSFERENCIAS | G2: 523 | H2: 523 | I2: 523
B3: VENTAS | C3: 2236 | D3: 4910 | E3: 4660 | F3: TRANSFERENCIAS ZELLE | G3: EURO | H3: USD | I3: EFECTIVO | J3: TOTAL | K3: TOTAL USD | L3: DIFERENCIA
C4: 0 | D4: 78450 | E4: 30334 | F4: 0 | G4: 0 | H4: =29+6 -> 35 | I4: =23150+4000-1000 -> 26150 | J4: =+C4+D4+E4+F5+G5+H5+I4 -> 153239 | K4: =+J4/H2 -> 293 | L4: =K4-C8 -> 0
F5: =+F4*F2 -> 0 | G5: =+G4*G2 -> 0 | H5: =+H4*H2 -> 18305
B7: Ventas
B8: Ventas Brutas | C8: 293
B9: Gastos | C9: CUP | F9: USD
B10: Salario | C10: =+C47 -> 5000 | F10: =+F47 -> 15.560229
B11: Renta
B12: Compras
B13: Perfumes Juank
B14: H&M
B15: Otros
B16: Electricidad
B17: Gas
B18: Pantry
B19: Comunicaciones
B20: Publicidad
B21: Pago de colaboración modelos
B22: Comunity manager
... B29: Otros servicios comprados
B30: Total de Gastos | C30: =SUM(C10:C29) -> 5000 | F30: =SUM(F10:F20)+F24+F25+F26+F27+F28+F29 -> 15.560229
B33: Salario | C33: CUP | F33: USD
B34: Jacqueline | C34: 2000 | F34: =C34/$H$2 -> 3.8240918
B35: Yeni | C35: 1000 | F35: =C35/$H$2 -> 1.9120459
B36: Daniela | F36: =C36/$H$2 -> 0
B37: Lisandra | F37: =C37/$H$2 -> 0
B38: Aileen | C38: 2000 | F38: =C38/$H$2 -> 3.8240918
B39: Laura
B40: Vanessa
B41: Magaly
B43: 0.02 | F43: =ROUNDUP(K4*0.02,0) -> 6
B47: Total | C47: =SUM(C34:C46) -> 5000 | F47: =SUM(F34:F46) -> 15.560229
B50: FONDO
B51: CUP | C51: USD | D51: EURO | F51: OBSERVACIONES
A52: INICIAL | B52: 1040 | C52: 474 | D52: 40 | F52: Se sigue arrastrando el error en el fondo en MN
A53: FINAL | B53: 1040 | C53: 474 | D53: 40
F54: Como no había suficiente fondo en MN suponemos que su salario lo hayan cobrado del efectivo de la venta de este día pero al sumar los 4000 pesos al efectivo, el ingreso total sobrepasa la venta en 1,92 USD.
F58: Al parecer este día no se liquidó y el dinero quedó en caja, por lo que Yeni, que trabajó el día 12 cobro mil CUP de su salario del efectivo del día 11. Coincidentemente al restarle los 1000 pesos del efectivo se cuadra la venta del día 11.

Sheet DÍA 12
C2: TRANSFERENCIAS | G2: 523 | H2: 523 | I2: 523
B3: VENTAS | C3: 2236 | D3: 4910 | E3: 4660 | F3: TRANSFERENCIAS ZELLE | G3: EURO | H3: USD | I3: EFECTIVO | J3: TOTAL | K3: TOTAL USD | L3: DIFERENCIA
C4: 0 | F4: 0 | G4: 0 | H4: =467+10 -> 477 | J4: =+C4+D4+E4+F5+G5+H5+I4 -> 249471 | K4: =+J4/$H$2 -> 477 | L4: =K4-C8 -> 0
F5: =+F4*F2 -> 0 | G5: =+G4*G2 -> 0 | H5: =+H4*H2 -> 249471
B7: Ventas
B8: Ventas Brutas | C8: 477
B9: Gastos | C9: CUP | F9: USD
B10: Salario | C10: =+C47 -> 1000 | F10: =+F47 -> 11.912046
B11: Renta
B12: Compras
B13: Perfumes Juank
B14: H&M
B15: Otros
B16: Electricidad
B17: Gas
B18: Pantry
B19: Comunicaciones
B20: Publicidad
B21: Pago de colaboración modelos
B22: Comunity manager
... B29: Otros servicios comprados
B30: Total de Gastos | C30: =SUM(C10:C29) -> 1000 | F30: =SUM(F10:F20)+F24+F25+F26+F27+F28+F29 -> 11.912046
B33: Salario | C33: CUP | F33: USD
B34: Jacqueline | F34: =C34/$H$2 -> 0
B35: Yeni | C35: 1000 | F35: =C35/$H$2 -> 1.9120459
B36: Daniela | F36: =C36/$H$2 -> 0
B37: Lisandra | F37: =C37/$H$2 -> 0
B38: Aileen | F38: =C38/$H$2 -> 0
B39: Laura
B40: Vanessa
B41: Magaly
B43: 0.02 | F43: =ROUNDUP(K4*0.02,0) -> 10
B47: Total | C47: =SUM(C34:C46) -> 1000 | F47: =SUM(F34:F46) -> 11.912046
B50: FONDO
B51: CUP | C51: USD | D51: EURO | F51: OBSERVACIONES
A52: INICIAL | B52: 1040 | C52: 474 | D52: 40 | F52: Se sigue arrastrando el error en el fondo en MN. El fondo final del día debe ser realmente 35 CUP.
A53: FINAL | B53: =B52-1000 -> 40 | C53: 474 | D53: 40
F54: Yeni declara que para cobrar su salario completo cogió 1000 del fondo y los otros mil CUP los tomó del efectivo del día 11.

Sheet DÍA 13
C2: TRANSFERENCIAS | G2: 523 | H2: 523 | I2: 523
B3: VENTAS | C3: 2236 | D3: 4910 | E3: 4660 | F3: TRANSFERENCIAS ZELLE | G3: EURO | H3: USD | I3: EFECTIVO | J3: TOTAL | K3: TOTAL USD | L3: DIFERENCIA
C4: 0 | F4: 0 | G4: 0 | H4: =227+3.8+5 -> 235.8 | J4: =+C4+D4+E4+F5+G5+H5+I4 -> 123323.4 | K4: =J4/H2 -> 235.8 | L4: =K4-C8 -> -14.2
F5: =+F4*F2 -> 0 | G5: =+G4*G2 -> 0 | H5: =+H4*H2 -> 123323.4
B7: Ventas | H7: =H4+100 -> 335.8 | K7: =K4+100 -> 335.8 | L7: =K7-C8 -> 85.8
B8: Ventas Brutas | C8: 250 | H8: =H4-100 -> 135.8 | K8: 135.8 | L8: =K8-C8 -> -114.2
B9: Gastos | C9: CUP | F9: USD
B10: Salario | C10: =+C47 -> 2000 | F10: =+F47 -> 108.82409
B11: Renta
B12: Compras
B13: Perfumes Juank
B14: H&M
B15: Otros
B16: Electricidad
B17: Gas
B18: Pantry
B19: Comunicaciones
B20: Publicidad | F20: 100
B21: Pago de colaboración modelos
B22: Comunity manager
B23: Creador de contenido
B24: Insumos de Limpieza
B25: Mantenimiento
B26: Insumos para la tienda
B27: Transporte
B28: Servicios contables
B29: Otros servicios comprados
B30: Total de Gastos | C30: =SUM(C10:C29) -> 2000 | F30: =SUM(F10:F20)+F24+F25+F26+F27+F28+F29 -> 208.82409
B33: Salario | C33: CUP | F33: USD
B34: Jacqueline | F34: =C34/$H$2 -> 0
B35: Yeni | F35: =C35/$H$2 -> 0
B36: Daniela | F36: 100
B37: Lisandra | F37: =C37/$H$2 -> 0
B38: Aileen | C38: 2000 | F38: =C38/$H$2 -> 3.8240918
B39: Laura
B40: Vanessa
B41: Magaly
B43: 0.02 | F43: =ROUNDUP(K4*0.02,0) -> 5
B47: Total | C47: =SUM(C34:C46) -> 2000 | F47: =SUM(F34:F46) -> 108.82409
B50: FONDO
...

Sheet DÍA 14
C2: TRANSFERENCIAS | G2: 525 | H2: 525 | I2: 525
B3: VENTAS | C3: 2236 | D3: 4910 | E3: 4660 | F3: TRANSFERENCIAS ZELLE | G3: EURO | H3: USD | I3: EFECTIVO | J3: TOTAL | K3: TOTAL USD | L3: DIFERENCIA
C4: 0 | F4: 0 | G4: 0 | H4: =82+3 -> 85 | I4: =22250 + 4000 -> 26250 | J4: =+C4+D4+E4+F5+G5+H5+I4 -> 70875 | K4: =+J4/H2 -> 135 | L4: =K4-C8 -> 0
F5: =+F4*F2 -> 0 | G5: =+G4*G2 -> 0 | H5: =+H4*H2 -> 44625
B7: Ventas
B8: Ventas Brutas | C8: 135
B9: Gastos | C9: CUP | F9: USD
B10: Salario | C10: =+C47 -> 4000 | F10: =+F47 -> 10.619048
B11: Renta
B12: Compras
B13: Perfumes Juank
B14: H&M
B15: Otros
B16: Electricidad
B17: Gas
B18: Pantry
B19: Comunicaciones
B20: Publicidad
B21: Pago de colaboración modelos
B22: Comunity manager
... B29: Otros servicios comprados
B30: Total de Gastos | C30: =SUM(C10:C29) -> 4000 | F30: =SUM(F10:F20)+F24+F25+F26+F27+F28+F29 -> 10.619048
B33: Salario | C33: CUP | F33: USD
B34: Jacqueline | C34: 2000 | F34: =C34/$H$2 -> 3.8095238
B35: Yeni | F35: =C35/$H$2 -> 0
B36: Daniela | F36: 0
B37: Lisandra | F37: =C37/$H$2 -> 0
B38: Aileen | C38: 2000 | F38: =C38/$H$2 -> 3.8095238
B39: Laura
B40: Vanessa
B41: Magaly
B43: 0.02 | F43: =ROUNDUP(K4*0.02,0) -> 3
B47: Total | C47: =SUM(C34:C46) -> 4000 | F47: =SUM(F34:F46) -> 10.619048
B50: FONDO
B51: CUP | C51: USD | D51: EURO | F51: OBSERVACIONES
A52: INICIAL | B52: 3060 | C52: 474 | D52: 40 | F52: Se sigue arrastrando el error en el fondo en MN. El fondo final del día anterior debe ser realmente 3055 CUP. Como no había suficiente fondo para el cobro del salario de las dos vendedoras, al parecer lo cobraron de la MN de la venta del día, aunque no lo expresan en la planilla.
A53: FINAL | B53: =3490-430 -> 3060 | C53: 474 | D53: 40
C58: CUP | D58: USD
B59: Impuestos pagados | C59: =SUM(C60:C65) -> 30044.91 | D59: =C59/$G$2 -> 57.2284
B60: Impuesto sobre ventas | C60: 16945.03 | D60: =C60/$G$2 -> 32.276248
...

Sheet DÍA 15
G2: 525 | H2: 525 | I2: 525
B3: VENTAS | C3: 2236 | D3: 4910 | E3: 4660 | F3: TRANSFERENCIAS ZELLE | G3: EURO | H3: USD | I3: EFECTIVO | J3: TOTAL | K3: TOTAL USD | L3: DIFERENCIA
C4: 10500 | F4: 0 | G4: 0 | H4: =187+6 -> 193 | I4: =30650+500+1700+4000 -> 36850 | J4: =C4+D4+E4+F5+G5+H5+I4 -> 148675 | K4: =J4/H2 -> 283.19048 | L4: =K4-C8 -> 0.19047619
F5: =+F4*F2 -> 0 | G5: =+G4*G2 -> 0 | H5: =+H4*H2 -> 101325
B7: Ventas
B8: Ventas Brutas | C8: 283
B9: Gastos | C9: CUP | E9: USD
B10: Salario | C10: =+C47 -> 4000 | E10: =+E47 -> 113.61905
B11: Renta
B12: Compras
B13: Perfumes Juank
B14: H&M
B15: Otros
B16: Electricidad
B17: Gas
B18: Pantry
B19: Comunicaciones
B20: Publicidad
B21: Pago de colaboración modelos
B22: Comunity manager
... B27: Transporte
B28: Servicios contables (Mensajería) | C28: 500 | E28: =C28/G2 -> 0.95238095
B29: Otros servicios comprados | C29: 1700 | E29: =C29/G2 -> 3.2380952
B30: Total de Gastos | D30: =SUM(D10:D29) -> 0 | E30: =SUM(G10:G20)+G24+G25+G26+G27+E28+E29 -> 4.1904762
B33: Salario | C33: CUP | E33: USD
B34: Jacqueline | C34: 2000 | E34: =C34/$H$2 -> 3.8095238
B35: Yeni | E35: =C35/$H$2 -> 0
B36: Daniela | E36: 100
B37: Lisandra | E37: =C37/$H$2 -> 0
B38: Aileen | C38: 2000 | E38: =C38/$H$2 -> 3.8095238
B39: Laura
B40: Vanessa
B41: Magaly
B43: 0.02 | E43: =ROUNDUP(K4*0.02,0) -> 6
B47: Total | C47: =SUM(C34:C46) -> 4000 | E47: =SUM(E34:E46) -> 113.61905
B50: FONDO
B51: CUP | C51: USD | D51: EURO
A52: INICIAL | B52: 3060 | C52: 474 | D52: 40
A53: FINAL | B53: =3490-430 -> 3060 | C53: 474 | D53: 40

Sheet DÍA 16
C2: TRANSFERENCIAS | G2: 525 | H2: 525 | I2: 525 | J2: 525
B3: VENTAS | C3: 2236 | D3: 4910 | E3: 4660 | F3: TRANSFERENCIAS ZELLE | G3: EURO | H3: USD | I3: EFECTIVO | J3: TOTAL | K3: TOTAL USD | L3: DIFERENCIA
E4: 21100 | F4: 0 | G4: 150 | H4: =15+6 -> 21 | I4: =24250+2000 -> 26250 | J4: =+C4+D4+E4+F5+G5+H5+I4 -> 137125 | K4: =J4/I2 -> 261.19048 | L4: =K4-C8 -> 1.1904762
F5: =+F4*G2 -> 0 | G5: =+G4*H2 -> 78750 | H5: =+H4*I2 -> 11025
B7: Ventas
B8: Ventas Brutas | C8: 260
B9: Gastos | C9: CUP | E9: USD
B10: Salario | C10: =+C47 -> 2000 | E10: =+E47 -> 109.80952
B11: Renta
B12: Compras
B13: Perfumes Juank
B14: H&M
B15: Otros
B16: Electricidad
B17: Gas
B18: Pantry
B19: Comunicaciones
B20: Publicidad
B21: Pago de colaboración modelos
B22: Comunity manager
... B29: Otros servicios comprados
B30: Total de Gastos | D30: =SUM(D10:D29) -> 0 | E30: =SUM(G10:G20)+G24+G25+G26+G27+E28+E29 -> 0
B33: Salario | C33: CUP | E33: USD
B34: Jacqueline | E34: =C34/$I$2 -> 0
B35: Yeni | E35: =C35/$I$2 -> 0
B36: Daniela | E36: 100
B37: Lisandra | E37: =C37/$I$2 -> 0
B38: Aileen | C38: 2000 | E38: =C38/$I$2 -> 3.8095238
B39: Laura
B40: Vanessa
B41: Magaly
B43: 0.02 | E43: =ROUNDUP(K4*0.02,0) -> 6
B47: Total | C47: =SUM(C34:C46) -> 2000 | E47: =SUM(E34:E46) -> 109.80952
B50: FONDO
B51: CUP | C51: USD | D51: EURO | G51: OBSERVACIONES
A52: INICIAL | B52: =2540+7400 -> 9940 | C52: =474+4 -> 478 | D52: 40 | G52: Fondo inicial es 9940 MN, 478 USD y 40 EUROS, este mismo fondo se mantiene el día 17, lo cual significa que el salario Aileén lo cobró del efectivo del día, además refleja que 2% es 5,20, lo cual hace pensar que cobró 5 USD en lugar de 6.sI considero que cobró los 6 da una diferencia de 1,19 que puede ser una propina. Con estas consideraciones se cuadra el día.
A53: FINAL | B53: =2540+7400 -> 9940 | C53: =474+4 -> 478 | D53: 40

Sheet DÍA 17
G2: 525 | H2: 525 | I2: 525
B3: VENTAS | C3: 2236 | D3: 4910 | E3: 4660 | F3: TRANSFERENCIAS ZELLE | G3: EURO | H3: USD | I3: EFECTIVO | J3: TOTAL | K3: TOTAL USD | L3: DIFERENCIA
F4: 0 | G4: 70 | H4: =159+10 -> 169 | I4: =114350 + 2000 -> 116350 | J4: =C4+D4+E4+F5+G5+H5+I4 -> 241825 | K4: =J4/H2 -> 460.61905 | L4: =K4-C8 -> 2.6190476
F5: =+F4*F2 -> 0 | G5: =+G4*G2 -> 36750 | H5: =+H4*H2 -> 88725
B7: Ventas
B8: Ventas Brutas | C8: 458
B9: Gastos | C9: CUP | E9: USD
B10: Salario | C10: =+C47 -> 7250 | E10: =+E47 -> 133.80952
B11: Renta
B12: Compras
B13: Perfumes Juank
B14: H&M
B15: Otros
B16: Electricidad
B17: Gas
B18: Pantry
B19: Comunicaciones
B20: Publicidad
B21: Pago de colaboración modelos
B22: Comunity manager
... B29: Otros servicios comprados
B30: Total de Gastos | D30: =SUM(D10:D29) -> 0 | E30: =SUM(G10:G20)+G24+G25+G26+G27+E28+E29 -> 0
B33: Salario | C33: CUP | E33: USD
B34: Jacqueline | E34: =C34/$H$2 -> 0
B35: Yeni | E35: =C35/$H$2 -> 0
B36: Daniela | E36: 100
B37: Lisandra | E37: =C37/$H$2 -> 0
B38: Aileen | C38: 2000 | E38: =C38/$H$2 -> 3.8095238
B39: Laura | C39: 5250 | E39: =C39/$H$2+10 -> 20
B40: Vanessa
B41: Magaly
B43: 0.02 | E43: =ROUNDUP(K4*0.02,0) -> 10
B47: Total | C47: =SUM(C34:C46) -> 7250 | E47: =SUM(E34:E46) -> 133.80952
B50: FONDO
B51: CUP | C51: USD | D51: EURO | G51: OBSERVACIONES
A52: INICIAL | B52: =2540+7400 -> 9940 | C52: =474+4 -> 478 | D52: 40 | G52: Fondo inicial es 9940 MN, 478 USD y 40 EUROS, este mismo fondo se mantiene al final del día 17, lo cual significa que el salario Aileén lo cobró del efectivo del día, Con estas consideraciones se cuadra el día con un sobrante de 2.62 USD. Este día reflejan el salario de Laura, el cual fue de 20 USD divididos en 10 USD y los otros 10 en MN que al cambio son 5250. Asumí que este gasto ya se tuvo en cuenta en lo que se debía liquidar pq de lo contrario se descuadra el día.
A53: FINAL | B53: =2540+7400 -> 9940 | C53: =474+4 -> 478 | D53: 40

Sheet DÍA 18
G2: 525 | H2: 525 | I2: 525
B3: VENTAS | C3: 2236 | D3: 4910 | E3: 4660 | F3: TRANSFERENCIAS ZELLE | G3: EURO | H3: USD | I3: EFECTIVO | J3: TOTAL | K3: TOTAL USD | L3: DIFERENCIA
F4: 0 | G4: 10 | H4: =487+17 -> 504 | I4: =161645+2000 -> 163645 | J4: =C4+D4+E4+F5+G5+H5+I4 -> 433495 | K4: =J4/H2 -> 825.70476 | L4: =K4-C8 -> 1.1047619
F5: =+F4*F2 -> 0 | G5: =+G4*G2 -> 5250 | H5: =+H4*H2 -> 264600
B7: Ventas
B8: Ventas Brutas | C8: 824.6
B9: Gastos | C9: CUP | E9: USD
B10: Salario | C10: =+C47 -> 2000 | E10: =+E47 -> 20.809524
B11: Renta
B12: Compras
B13: Perfumes Juank
B14: H&M
B15: Otros
B16: Electricidad
B17: Gas
B18: Pantry
B19: Comunicaciones
B20: Publicidad
B21: Pago de colaboración modelos
B22: Comunity manager
... B29: Otros servicios comprados
B30: Total de Gastos | D30: =SUM(D10:D29) -> 0 | E30: =SUM(G10:G20)+G24+G25+G26+G27+E28+E29 -> 0
B33: Salario | C33: CUP | E33: USD
B34: Jacqueline | C34: 2000 | E34: =C34/$H$2 -> 3.8095238
B35: Yeni | E35: =C35/$H$2 -> 0
B36: Daniela | E36: =C36/$H$2 -> 0
B37: Lisandra | E37: =C37/$H$2 -> 0
B38: Aileen | E38: =C38/$H$2 -> 0
B39: Laura | E39: =C39/$H$2 -> 0
B40: Vanessa
B41: Magaly
B43: 0.02 | E43: =ROUNDUP(K4*0.02,0) -> 17
B47: Total | C47: =SUM(C34:C46) -> 2000 | E47: =SUM(E34:E46) -> 20.809524
B50: FONDO
B51: CUP | C51: USD | D51: EURO | G51: OBSERVACIONES
A52: INICIAL | B52: =2540+7400 -> 9940 | C52: =474+4 -> 478 | D52: 40 | G52: Fondo inicial es 9940 MN, 478 USD y 40 EUROS, este mismo fondo se mantiene el día 19, lo cual significa que el salario Yaquelín lo cobró del efectivo del día. Con estas consideraciones se cuadra el día.
A53: FINAL | B53: =2540+7400 -> 9940 | C53: =474+4 -> 478 | D53: 40

Sheet DÍA 19
G2: 525 | H2: 525 | I2: 525
B3: VENTAS | C3: 2236 | D3: 4910 | E3: 4660 | F3: TRANSFERENCIAS ZELLE | G3: EURO | H3: USD | I3: EFECTIVO | J3: TOTAL | K3: TOTAL USD | L3: DIFERENCIA
F4: 0 | H4: =215+6 -> 221 | I4: =14500+4000 -> 18500 | J4: =C4+D4+E4+F5+G5+H5+I4 -> 134525 | K4: =J4/H2 -> 256.2381 | L4: =K4-C8 -> 1.2380952
F5: =+F4*F2 -> 0 | G5: =+G4*G2 -> 0 | H5: =+H4*H2 -> 116025
B7: Ventas
B8: Ventas Brutas | C8: 255
B9: Gastos | C9: CUP | E9: USD
B10: Salario | C10: =+C47 -> 4000 | E10: =C10/H2 -> 7.6190476
B11: Renta
B12: Compras
B13: Perfumes Juank
B14: H&M
B15: Otros
B16: Electricidad
B17: Gas
B18: Pantry
B19: Comunicaciones
B20: Publicidad
B21: Pago de colaboración modelos
B22: Comunity manager
... B29: Otros servicios comprados
B30: Total de Gastos | D30: =SUM(D10:D29) -> 0 | E30: =SUM(G10:G20)+G24+G25+G26+G27+E28+E29 -> 0
B33: Salario | C33: CUP | E33: USD
B34: Jacqueline | C34: 2000 | E34: =C34/$H$2 -> 3.8095238
B35: Yeni | E35: =C35/$H$2 -> 0
B36: Daniela | E36: =C36/$H$2 -> 0
B37: Lisandra | E37: =C37/$H$2 -> 0
B38: Aileen | C38: 2000 | E38: =C38/$H$2 -> 3.8095238
B39: Laura | E39: =C39/$H$2 -> 0
B40: Vanessa
B41: Magaly
B43: 0.02 | E43: =ROUNDUP(K4*0.02,0) -> 6
B47: Total | C47: =SUM(C34:C46) -> 4000 | E47: =SUM(E34:E46) -> 13.619048
B50: FONDO
B51: CUP | C51: USD | D51: EURO | G51: OBSERVACIONES
A52: INICIAL | B52: =2540+7400 -> 9940 | C52: =474+4 -> 478 | D52: 40 | G52: Fondo inicial es 9940 MN, 478 USD y 40 EUROS, este mismo fondo se mantiene el día 20, lo cual significa que el salario Yaquelín y Aileén lo cobraron del efectivo del día. Con estas consideraciones se cuadra el día.
A53: FINAL | B53: =2540+7400 -> 9940 | C53: =474+4 -> 478 | D53: 40

Sheet DÍA 20
G2: 525 | H2: 525 | I2: 525
B3: VENTAS | C3: 2236 | D3: 4910 | E3: 4660 | F3: TRANSFERENCIAS ZELLE | G3: EURO | H3: USD | I3: EFECTIVO | J3: TOTAL | K3: TOTAL USD | L3: DIFERENCIA
F4: 0 | G4: 40 | H4: =21+2+20 -> 43 | J4: =C4+D4+E4+F5+G5+H5+I4 -> 43575 | K4: =J4/H2 -> 83 | L4: =K4-C8 -> 0
F5: =+F4*F2 -> 0 | G5: =+G4*G2 -> 21000 | H5: =+H4*H2 -> 22575
B7: Ventas
B8: Ventas Brutas | C8: 83
B9: Gastos | C9: CUP | E9: USD
B10: Salario | C10: =+C47 -> 2000 | E10: =+E47 -> 25.809524
B11: Renta
B12: Compras
B13: Perfumes Juank
B14: H&M
B15: Otros
B16: Electricidad
B17: Gas
B18: Pantry
B19: Comunicaciones
B20: Publicidad
B21: Pago de colaboración modelos
B22: Comunity manager
... B29: Otros servicios comprados
B30: Total de Gastos | D30: =SUM(D10:D29) -> 0 | E30: =SUM(G10:G20)+G24+G25+G26+G27+E28+E29 -> 0
B33: Salario | C33: CUP | E33: USD
B34: Jacqueline | E34: =C34/$H$2 -> 0
B35: Yeni | C35: 2000 | E35: =C35/$H$2 -> 3.8095238
B36: Daniela | E36: =C36/$H$2 -> 0
B37: Lisandra | E37: =C37/$H$2 -> 0
B38: Aileen | E38: =C38/$H$2 -> 0
B39: Laura | E39: 20
B40: Vanessa
B41: Magaly
B43: 0.02 | E43: =ROUNDUP(K4*0.02,0) -> 2
B47: Total | C47: =SUM(C34:C46) -> 2000 | E47: =SUM(E34:E46) -> 25.809524
B50: FONDO
B51: CUP | C51: USD | D51: EURO | G51: OBSERVACIONES
A52: INICIAL | B52: =2540+7400 -> 9940 | C52: =474+4 -> 478 | D52: 40 | G52: El salario Yeni lo cobró del fondo , por tanto el fondo final es el que se expresa en la Tabla.
A53: FINAL | B53: =B52-2000 -> 7940 | C53: =474+4 -> 478 | D53: 40

Sheet DÍA 21
G2: 525 | H2: 525 | I2: 525
B3: VENTAS | C3: 2236 | D3: 4910 | E3: 4660 | F3: TRANSFERENCIAS ZELLE | G3: EURO | H3: USD | I3: EFECTIVO | J3: TOTAL | K3: TOTAL USD | L3: DIFERENCIA
F4: 0 | H4: =115+4 -> 119 | J4: =C4+D4+E4+F5+G5+H5+I4 -> 62475 | K4: =J4/H2 -> 119 | L4: =K4-C8 -> -39.5
F5: =+F4*F2 -> 0 | G5: =+G4*G2 -> 0 | H5: =+H4*H2 -> 62475
B7: Ventas
B8: Ventas Brutas | C8: 158.5
B9: Gastos | C9: CUP | E9: USD
B10: Salario | C10: =+C47 -> 4000 | E10: =+E47 -> 10.619048
B11: Renta
B12: Compras
B13: Perfumes Juank
B14: H&M
B15: Otros
B16: Electricidad | E16: =C16/G2 -> 0
B17: Gas
B18: Pantry
B19: Comunicaciones
B20: Publicidad
B21: Pago de colaboración modelos
B22: Comunity manager
B23: Creador de contenido
B24: Insumos de Limpieza
B25: Mantenimiento
B26: Insumos para la tienda (Bolsas del día 22) | C26: 51 | E26: =C26/G2 -> 0.097142857
B27: Transporte
B28: Servicios contables (Mensajería)
B29: Otros servicios comprados
B30: Total de Gastos | D30: =SUM(D10:D29) -> 0 | E30: =SUM(G10:G20)+G24+G25+G26+G27+E28+E29 -> 0
B33: Salario | C33: CUP | E33: USD
B34: Jacqueline | C34: 2000 | E34: =C34/$H$2 -> 3.8095238
B35: Yeni | E35: =C35/$H$2 -> 0
B36: Daniela | E36: =C36/$H$2 -> 0
B37: Lisandra | E37: =C37/$H$2 -> 0
B38: Aileen | C38: 2000 | E38: =C38/$H$2 -> 3.8095238
B39: Laura
B40: Vanessa
B41: Magaly
B43: 0.02 | E43: =ROUNDUP(K4*0.02,0) -> 3
B47: Total | C47: =SUM(C34:C46) -> 4000 | E47: =SUM(E34:E46) -> 10.619048
B50: FONDO
...

Sheet DÍA 22
G2: 530 | H2: 530 | I2: 530
B3: VENTAS | C3: 2236 | D3: 4910 | E3: 4660 | F3: TRANSFERENCIAS ZELLE | G3: EURO | H3: USD | I3: EFECTIVO | J3: TOTAL | K3: TOTAL USD | L3: EXCEDENTE
F4: 0 | H4: =121+3+7.54 -> 131.54 | J4: =+C4+D4+E4+F5+G5+H5+I4 -> 69716.2 | K4: =J4/H2 -> 131.54 | L4: =K4-C8 -> 1.54
F5: =+F4*F2 -> 0 | G5: =+G4*G2 -> 0 | H5: =+H4*H2 -> 69716.2
B7: Ventas
B8: Ventas Brutas | C8: 130
B9: Gastos | C9: CUP | E9: USD
B10: Salario | C10: =+C47 -> 4000 | E10: =+E47 -> 10.54717
B11: Renta
B12: Compras
B13: Perfumes Juank
B14: H&M
B15: Otros
B16: Electricidad | C16: 940 | E16: =C16/G2 -> 1.7735849
B17: Gas
B18: Pantry
B19: Comunicaciones
B20: Publicidad
B21: Pago de colaboración modelos
B22: Comunity manager
B23: Creador de contenido
B24: Insumos de Limpieza
B25: Mantenimiento
B26: Insumos para la tienda (BOLSAS) | C26: 900 | E26: =C26/G2 -> 1.6981132
B27: Transporte
B28: Servicios contables (Mensajería) | C28: 1000 | E28: =C28/G2 -> 1.8867925
B29: Otros servicios comprados
B30: Total de Gastos | D30: =SUM(D10:D29) -> 0 | E30: =SUM(G10:G20)+G24+G25+G26+G27+E28+E29 -> 1.8867925
B33: Salario | C33: CUP | E33: USD
B34: Jacqueline | C34: 2000 | E34: =C34/$H$2 -> 3.7735849
B35: Yeni | E35: =C35/$H$2 -> 0
B36: Daniela | E36: =C36/$H$2 -> 0
B37: Lisandra | E37: =C37/$H$2 -> 0
B38: Aileen | C38: 2000 | E38: =C38/$H$2 -> 3.7735849
B39: Laura
B40: Vanessa
B41: Magaly
B43: 0.02 | E43: =ROUNDUP(K4*0.02,0) -> 3
B47: Total | C47: =SUM(C34:C46) -> 4000 | E47: =SUM(E34:E46) -> 10.54717
B50: FONDO | G50: OBSERVACIONES
...

Sheet DÍA 23
G2: 530 | H2: 530 | I2: 530
B3: VENTAS | C3: 2236 | D3: 4910 | E3: 4660 | F3: TRANSFERENCIAS ZELLE | G3: EURO | H3: USD | I3: EFECTIVO | J3: TOTAL | K3: TOTAL USD | L3: EXCEDENTE
F4: 0 | H4: =110+3 -> 113 | I4: =13550+4000 -> 17550 | J4: =+C4+D4+E4+F5+G5+H5+I4 -> 77440 | K4: =J4/H2 -> 146.11321 | L4: =K4-C8 -> -1.8867925
F5: =+F4*F2 -> 0 | G5: =+G4*G2 -> 0 | H5: =+H4*H2 -> 59890
B7: Ventas
B8: Ventas Brutas | C8: 148
B9: Gastos | C9: CUP | E9: USD
B10: Salario | C10: =+C47 -> 4000 | E10: =+E47 -> 10.54717
B11: Renta
B12: Compras
B13: Perfumes Juank
B14: H&M
B15: Otros
B16: Electricidad
B17: Gas
B18: Pantry
B19: Comunicaciones
B20: Publicidad
B21: Pago de colaboración modelos
B22: Comunity manager
... B29: Otros servicios comprados
B30: Total de Gastos | D30: =SUM(D10:D29) -> 0 | E30: =SUM(G10:G20)+G24+G25+G26+G27+E28+E29 -> 0
B33: Salario | C33: CUP | E33: USD
B34: Jacqueline | C34: 2000 | E34: =C34/$H$2 -> 3.7735849
B35: Yeni | E35: =C35/$H$2 -> 0
B36: Daniela | E36: =C36/$H$2 -> 0
B37: Lisandra | E37: =C37/$H$2 -> 0
B38: Aileen | C38: 2000 | E38: =C38/$H$2 -> 3.7735849
B39: Laura
B40: Vanessa
B41: Magaly
B43: 0.02 | E43: =ROUNDUP(K4*0.02,0) -> 3
B47: Total | C47: =SUM(C34:C46) -> 4000 | E47: =SUM(E34:E46) -> 10.54717
B50: FONDO | G50: OBSERVACIONES
B51: CUP | C51: USD | D51: EURO | G51: Al parecer los 3 USD corespondiente al 2 % de la venta se los pagaron directamente por tanto los 3 USD los incorporaron al fondo.
B52: 12300 | C52: =474+4 -> 478 | D52: 40
B53: =B52 -> 12300 | C53: =C52+3 -> 481 | D53: =D52 -> 40

Sheet DÍA 24
G2: 530 | H2: 530 | I2: 530
B3: VENTAS | C3: 2236 | D3: 4910 | E3: 4660 | F3: TRANSFERENCIAS ZELLE | G3: EURO | H3: USD | I3: EFECTIVO | J3: TOTAL | K3: TOTAL USD | L3: EXCEDENTE
F4: 0 | H4: =83+3 -> 86 | I4: =31127+2000 -> 33127 | J4: =C4+D4+E4+F5+G5+H5+I4 -> 78707 | K4: =J4/H2 -> 148.50377 | L4: =K4-C8 -> 0.0037735849
F5: =+F4*F2 -> 0 | G5: =+G4*G2 -> 0 | H5: =+H4*H2 -> 45580 | I5: .
B7: Ventas
B8: Ventas Brutas | C8: 148.5
B9: Gastos | E9: USD
B10: Salario | C10: =+C47 -> 2000 | E10: =+E47 -> 6.7735849
B11: Renta
B12: Compras
B13: Perfumes Juank
B14: H&M
B15: Otros
B16: Electricidad
B17: Gas
B18: Pantry
B19: Comunicaciones
B20: Publicidad
B21: Pago de colaboración modelos
B22: Comunity manager
... B29: Otros servicios comprados
B30: Total de Gastos | D30: =SUM(D10:D29) -> 0 | E30: =SUM(G10:G20)+G24+G25+G26+G27+E28+E29 -> 0
B33: Salario | C33: CUP | E33: USD
B34: Jacqueline | E34: =C34/$H$2 -> 0
B35: Yeni | C35: 2000 | E35: =C35/$H$2 -> 3.7735849
B36: Daniela | E36: =C36/$H$2 -> 0
B37: Lisandra | E37: =C37/$H$2 -> 0
B38: Aileen | E38: =C38/$H$2 -> 0
B39: Laura
B40: Vanessa
B41: Magaly
B43: 0.02 | E43: =ROUNDUP(K4*0.02,0) -> 3
B47: Total | C47: =SUM(C34:C46) -> 2000 | E47: =SUM(E34:E46) -> 6.7735849
B50: FONDO | G50: OBSERVACIONES
B51: CUP | C51: USD | D51: EURO | G51: El día cuadra perfecto. El salario lo tomó de la venta del díaaunque no lo declaró.
B52: 12300 | C52: 481 | D52: 40
B53: =B52 -> 12300 | C53: =C52 -> 481 | D53: =D52 -> 40

Sheet DÍA 25
G2: 530 | H2: 530 | I2: 530
B3: VENTAS | C3: 2236 | D3: 4910 | E3: 4660 | F3: TRANSFERENCIAS ZELLE | G3: EURO | H3: USD | I3: EFECTIVO | J3: TOTAL | K3: TOTAL USD | L3: EXCEDENTE
F4: 0 | G4: 200 | H4: =77+13 -> 90 | I4: =182800+2000 -> 184800 | J4: =C4+D4+E4+F5+G5+H5+I4 -> 338500 | K4: =J4/H2 -> 638.67925 | L4: =K4-C8 -> 0.67924528
F5: =+F4*F2 -> 0 | G5: =+G4*G2 -> 106000 | H5: =+H4*H2 -> 47700
B7: Ventas
B8: Ventas Brutas | C8: 638
B9: Gastos | E9: USD
B10: Salario | C10: =+C47 -> 2000 | E10: =+E47 -> 16.773585
B11: Renta
B12: Compras
B13: Perfumes Juank
B14: H&M
B15: Otros
B16: Electricidad
B17: Gas
B18: Pantry
B19: Comunicaciones
B20: Publicidad
B21: Pago de colaboración modelos
B22: Comunity manager
... B29: Otros servicios comprados
B30: Total de Gastos | D30: =SUM(D10:D29) -> 0 | E30: =SUM(G10:G20)+G24+G25+G26+G27+E28+E29 -> 0
B33: Salario | C33: CUP | E33: USD
B34: Jacqueline | E34: =C34/$H$2 -> 0
B35: Yeni | E35: =C35/$H$2 -> 0
B36: Daniela | E36: =C36/$H$2 -> 0
B37: Lisandra | E37: =C37/$H$2 -> 0
B38: Aileen | C38: 2000 | E38: =C38/$H$2 -> 3.7735849
B39: Laura
B40: Vanessa
B41: Magaly
B43: 0.02 | E43: =ROUNDUP(K4*0.02,0) -> 13
B47: Total | C47: =SUM(C34:C46) -> 2000 | E47: =SUM(E34:E46) -> 16.773585
B50: FONDO | G50: OBSERVACIONES
B51: CUP | C51: USD | D51: EURO | G51: Todo OK
B52: 12300 | C52: 481 | D52: 40
B53: =B52 -> 12300 | C53: 481 | D53: 40

Sheet DÍA 26
G2: 530 | H2: 530 | I2: 530
B3: VENTAS | C3: 2236 | D3: 4910 | E3: 4660 | F3: TRANSFERENCIAS ZELLE | G3: EURO | H3: USD | I3: EFECTIVO | J3: TOTAL | K3: TOTAL USD | L3: EXCEDENTE
F4: 0 | H4: =25 -> 25 | J4: =C4+D4+E4+F5+G5+H5+I4 -> 13250 | K4: =J4/H2 -> 25 | L4: =K4-C8 -> 0
F5: =+F4*F2 -> 0 | G5: =+G4*G2 -> 0 | H5: =+H4*H2 -> 13250
B7: Ventas
B8: Ventas Brutas | C8: 25
B9: Gastos | E9: USD
B10: Salario | C10: =+C47 -> 4000 | E10: =+E47 -> 8.5471698
B11: Renta
B12: Compras
B13: Perfumes Juank
B14: H&M
B15: Otros
B16: Electricidad
B17: Gas
B18: Pantry
B19: Comunicaciones
B20: Publicidad
B21: Pago de colaboración modelos
B22: Comunity manager
... B29: Otros servicios comprados
B30: Total de Gastos | D30: =SUM(D10:D29) -> 0 | E30: =SUM(G10:G20)+G24+G25+G26+G27+E28+E29 -> 0
B33: Salario | C33: CUP | E33: USD
B34: Jacqueline | E34: =C34/$H$2 -> 0
B35: Yeni | C35: 2000 | E35: =C35/$H$2 -> 3.7735849
B36: Daniela | E36: =C36/$H$2 -> 0 | H36: =478-14 -> 464
B37: Lisandra | E37: =C37/$H$2 -> 0
B38: Aileen | C38: 2000 | E38: =C38/$H$2 -> 3.7735849
B39: Laura
B40: Vanessa
B41: Magaly
B43: 0.02 | E43: =ROUNDUP(K4*0.02,0) -> 1
B47: Total | C47: =SUM(C34:C46) -> 4000 | E47: =SUM(E34:E46) -> 8.5471698
B50: FONDO | G50: OBSERVACIONES
B51: CUP | C51: USD | D51: EURO | G51: Este día el fondo inicial en USD es 478 sin explicación alguna faltan 3 USD. El salario de hoy lo cobraron del fondo y asumo que el dólar correspondiente al 2% lo hayan tomado tbién del fondo.
A52: inicial | B52: 12300 | C52: 478 | D52: 40
A53: final | B53: =B52-4000 -> 8300 | C53: =C52-1 -> 477 | D53: 40

Sheet DÍA 27
G2: 530 | H2: 530 | I2: 530
B3: VENTAS | C3: 2236 | D3: 4910 | E3: 4660 | F3: TRANSFERENCIAS ZELLE | G3: EURO | H3: USD | I3: EFECTIVO | J3: TOTAL | K3: TOTAL USD | L3: EXCEDENTE
F4: 0 | H4: =502+14+22+136 -> 674 | I4: 540 | J4: =C4+D4+E4+F5+G5+H5+I4 -> 357760 | K4: =J4/H2 -> 675.01887 | L4: =K4-C8 -> 2.0188679
F5: =+F4*F2 -> 0 | G5: =+G4*G2 -> 0 | H5: =+H4*H2 -> 357220
B7: Ventas
B8: Ventas Brutas | C8: 673
B9: Gastos | E9: USD
B10: Salario | C10: =+C47 -> 2000 | E10: =+E47 -> 39.773585
B11: Renta
B12: Compras
B13: Perfumes Juank
B14: H&M
B15: Otros
B16: Electricidad
B17: Gas
B18: Pantry
B19: Comunicaciones
B20: Publicidad
B21: Pago de colaboración modelos
B22: Comunity manager
... B28: Servicios contables (Mensajería)
B29: Otros servicios comprados (Rhandy) | E29: 136
B30: Total de Gastos | D30: =SUM(D10:D29) -> 0 | E30: =SUM(G10:G20)+G24+G25+G26+G27+E28+E29 -> 136
B33: Salario | C33: CUP | E33: USD
B34: Jacqueline | C34: 2000 | E34: =C34/$H$2 -> 3.7735849
B35: Yeni | E35: =C35/$H$2 -> 0
B36: Daniela | E36: =C36/$H$2 -> 0
B37: Lisandra | E37: =C37/$H$2 -> 0
